/*
 *** MADE BY MITHION'S .SCHEMATIC TO JAVA CONVERTING TOOL v1.6 ***
 */

package net.divinerpg.dimension.gen.iceika;
import java.util.Random;

import net.divinerpg.helper.blocks.IceikaBlocks;
import net.minecraft.block.Block;
import net.minecraft.init.Blocks;
import net.minecraft.item.ItemStack;
import net.minecraft.world.World;
import net.minecraft.world.gen.feature.WorldGenerator;

public class WorldGenIceikaDungeon extends WorldGenerator
{

    protected Block[] GetValidSpawnBlocks() {
        return new Block[] {
                IceikaBlocks.frozenStone
        };
    }

    public boolean LocationIsValidSpawn(World world, int i, int j, int k){
        int distanceToAir = 0;
        Block checkID = world.getBlock(i, j, k);

        while (checkID != Blocks.air){
            distanceToAir++;
            checkID = world.getBlock(i, j + distanceToAir, k);
        }

        if (distanceToAir > 3)
            return false;
        j += distanceToAir - 1;

        Block blockID = world.getBlock(i, j, k);
        Block blockIDAbove = world.getBlock(i, j+1, k);
        Block blockIDBelow = world.getBlock(i, j-1, k);
        for (Block x : GetValidSpawnBlocks()){
            if (blockIDAbove != Blocks.air)
                return false;
            if (blockID == x)
                return true;
            else if (blockID == Blocks.snow && blockIDBelow == x)
                return true;
        }
        return false;
    }

    public WorldGenIceikaDungeon() { }

    @Override
    public boolean generate(World world, Random rand, int i, int j, int k) {
        //check that each corner is one of the valid spawn blocks

        world.setBlock(i + 0, j + 0, k + 11, IceikaBlocks.snowBricks);
        world.setBlock(i + 0, j + 0, k + 12, IceikaBlocks.snowBricks);
        world.setBlock(i + 0, j + 0, k + 13, IceikaBlocks.snowBricks);
        world.setBlock(i + 0, j + 0, k + 14, IceikaBlocks.snowBricks);
        world.setBlock(i + 0, j + 0, k + 15, IceikaBlocks.snowBricks);
        world.setBlock(i + 0, j + 0, k + 16, IceikaBlocks.snowBricks);
        world.setBlock(i + 0, j + 0, k + 17, IceikaBlocks.snowBricks);
        world.setBlock(i + 0, j + 0, k + 18, IceikaBlocks.snowBricks);
        world.setBlock(i + 0, j + 0, k + 19, IceikaBlocks.snowBricks);
        world.setBlock(i + 0, j + 0, k + 20, IceikaBlocks.snowBricks);
        world.setBlock(i + 0, j + 0, k + 21, IceikaBlocks.snowBricks);
        world.setBlock(i + 0, j + 0, k + 22, IceikaBlocks.snowBricks);
        world.setBlock(i + 0, j + 1, k + 11, IceikaBlocks.snowBricks);
        world.setBlock(i + 0, j + 1, k + 12, IceikaBlocks.snowBricks);
        world.setBlock(i + 0, j + 1, k + 13, IceikaBlocks.snowBricks);
        world.setBlock(i + 0, j + 1, k + 14, IceikaBlocks.snowBricks);
        world.setBlock(i + 0, j + 1, k + 15, IceikaBlocks.snowBricks);
        world.setBlock(i + 0, j + 1, k + 16, IceikaBlocks.snowBricks);
        world.setBlock(i + 0, j + 1, k + 17, IceikaBlocks.snowBricks);
        world.setBlock(i + 0, j + 1, k + 18, IceikaBlocks.snowBricks);
        world.setBlock(i + 0, j + 1, k + 19, IceikaBlocks.snowBricks);
        world.setBlock(i + 0, j + 1, k + 20, IceikaBlocks.snowBricks);
        world.setBlock(i + 0, j + 1, k + 21, IceikaBlocks.snowBricks);
        world.setBlock(i + 0, j + 1, k + 22, IceikaBlocks.snowBricks);
        world.setBlock(i + 0, j + 2, k + 11, IceikaBlocks.snowBricks);
        world.setBlock(i + 0, j + 2, k + 12, IceikaBlocks.snowBricks);
        world.setBlock(i + 0, j + 2, k + 13, IceikaBlocks.snowBricks);
        world.setBlock(i + 0, j + 2, k + 14, IceikaBlocks.snowBricks);
        world.setBlock(i + 0, j + 2, k + 15, IceikaBlocks.snowBricks);
        world.setBlock(i + 0, j + 2, k + 16, IceikaBlocks.snowBricks);
        world.setBlock(i + 0, j + 2, k + 17, IceikaBlocks.snowBricks);
        world.setBlock(i + 0, j + 2, k + 18, IceikaBlocks.snowBricks);
        world.setBlock(i + 0, j + 2, k + 19, IceikaBlocks.snowBricks);
        world.setBlock(i + 0, j + 2, k + 20, IceikaBlocks.snowBricks);
        world.setBlock(i + 0, j + 2, k + 21, IceikaBlocks.snowBricks);
        world.setBlock(i + 0, j + 2, k + 22, IceikaBlocks.snowBricks);
        world.setBlock(i + 0, j + 3, k + 11, IceikaBlocks.snowBricks);
        world.setBlock(i + 0, j + 3, k + 12, IceikaBlocks.snowBricks);
        world.setBlock(i + 0, j + 3, k + 13, IceikaBlocks.snowBricks);
        world.setBlock(i + 0, j + 3, k + 14, IceikaBlocks.snowBricks);
        world.setBlock(i + 0, j + 3, k + 15, IceikaBlocks.snowBricks);
        world.setBlock(i + 0, j + 3, k + 16, IceikaBlocks.snowBricks);
        world.setBlock(i + 0, j + 3, k + 17, IceikaBlocks.snowBricks);
        world.setBlock(i + 0, j + 3, k + 18, IceikaBlocks.snowBricks);
        world.setBlock(i + 0, j + 3, k + 19, IceikaBlocks.snowBricks);
        world.setBlock(i + 0, j + 3, k + 20, IceikaBlocks.snowBricks);
        world.setBlock(i + 0, j + 3, k + 21, IceikaBlocks.snowBricks);
        world.setBlock(i + 0, j + 3, k + 22, IceikaBlocks.snowBricks);
        world.setBlock(i + 1, j + 0, k + 11, IceikaBlocks.snowBricks);
        world.setBlock(i + 1, j + 0, k + 12, IceikaBlocks.icyStone);
        world.setBlock(i + 1, j + 0, k + 13, IceikaBlocks.icyStone);
        world.setBlock(i + 1, j + 0, k + 14, IceikaBlocks.icyStone);
        world.setBlock(i + 1, j + 0, k + 15, IceikaBlocks.icyStone);
        world.setBlock(i + 1, j + 0, k + 16, IceikaBlocks.icyStone);
        world.setBlock(i + 1, j + 0, k + 17, IceikaBlocks.icyStone);
        world.setBlock(i + 1, j + 0, k + 18, IceikaBlocks.icyStone);
        world.setBlock(i + 1, j + 0, k + 19, IceikaBlocks.icyStone);
        world.setBlock(i + 1, j + 0, k + 20, IceikaBlocks.icyStone);
        world.setBlock(i + 1, j + 0, k + 21, IceikaBlocks.icyStone);
        world.setBlock(i + 1, j + 0, k + 22, IceikaBlocks.snowBricks);
        world.setBlock(i + 1, j + 1, k + 11, IceikaBlocks.snowBricks);
        world.setBlock(i + 1, j + 1, k + 12, Blocks.air);
        world.setBlock(i + 1, j + 1, k + 13, Blocks.air);
        world.setBlock(i + 1, j + 1, k + 14, Blocks.air);
        world.setBlock(i + 1, j + 1, k + 15, Blocks.air);
        world.setBlock(i + 1, j + 1, k + 16, Blocks.air);
        world.setBlock(i + 1, j + 1, k + 17, Blocks.air);
        world.setBlock(i + 1, j + 1, k + 18, Blocks.air);
        world.setBlock(i + 1, j + 1, k + 19, Blocks.air);
        world.setBlock(i + 1, j + 1, k + 20, Blocks.air);
        world.setBlock(i + 1, j + 1, k + 21, Blocks.air);
        world.setBlock(i + 1, j + 1, k + 22, IceikaBlocks.snowBricks);
        world.setBlock(i + 1, j + 2, k + 11, IceikaBlocks.snowBricks);
        world.setBlock(i + 1, j + 2, k + 12, Blocks.air);
        world.setBlock(i + 1, j + 2, k + 13, Blocks.air);
        world.setBlock(i + 1, j + 2, k + 14, Blocks.air);
        world.setBlock(i + 1, j + 2, k + 15, Blocks.air);
        world.setBlock(i + 1, j + 2, k + 16, Blocks.air);
        world.setBlock(i + 1, j + 2, k + 17, Blocks.air);
        world.setBlock(i + 1, j + 2, k + 18, Blocks.air);
        world.setBlock(i + 1, j + 2, k + 19, Blocks.air);
        world.setBlock(i + 1, j + 2, k + 20, Blocks.air);
        world.setBlock(i + 1, j + 2, k + 21, Blocks.air);
        world.setBlock(i + 1, j + 2, k + 22, IceikaBlocks.snowBricks);
        world.setBlock(i + 1, j + 3, k + 11, IceikaBlocks.snowBricks);
        world.setBlock(i + 1, j + 3, k + 12, Blocks.air);
        world.setBlock(i + 1, j + 3, k + 13, Blocks.air);
        world.setBlock(i + 1, j + 3, k + 14, Blocks.air);
        world.setBlock(i + 1, j + 3, k + 15, Blocks.air);
        world.setBlock(i + 1, j + 3, k + 16, Blocks.air);
        world.setBlock(i + 1, j + 3, k + 17, Blocks.air);
        world.setBlock(i + 1, j + 3, k + 18, Blocks.air);
        world.setBlock(i + 1, j + 3, k + 19, Blocks.air);
        world.setBlock(i + 1, j + 3, k + 20, Blocks.air);
        world.setBlock(i + 1, j + 3, k + 21, Blocks.air);
        world.setBlock(i + 1, j + 3, k + 22, IceikaBlocks.snowBricks);
        world.setBlock(i + 1, j + 4, k + 12, IceikaBlocks.snowBricks);
        world.setBlock(i + 1, j + 4, k + 13, IceikaBlocks.snowBricks);
        world.setBlock(i + 1, j + 4, k + 14, IceikaBlocks.snowBricks);
        world.setBlock(i + 1, j + 4, k + 15, IceikaBlocks.snowBricks);
        world.setBlock(i + 1, j + 4, k + 16, IceikaBlocks.snowBricks);
        world.setBlock(i + 1, j + 4, k + 17, IceikaBlocks.snowBricks);
        world.setBlock(i + 1, j + 4, k + 18, IceikaBlocks.snowBricks);
        world.setBlock(i + 1, j + 4, k + 19, IceikaBlocks.snowBricks);
        world.setBlock(i + 1, j + 4, k + 20, IceikaBlocks.snowBricks);
        world.setBlock(i + 1, j + 4, k + 21, IceikaBlocks.snowBricks);
        world.setBlock(i + 2, j + 0, k + 11, IceikaBlocks.snowBricks);
        world.setBlock(i + 2, j + 0, k + 12, IceikaBlocks.icyStone);
        world.setBlock(i + 2, j + 0, k + 13, IceikaBlocks.icyStone);
        world.setBlock(i + 2, j + 0, k + 14, IceikaBlocks.icyStone);
        world.setBlock(i + 2, j + 0, k + 15, IceikaBlocks.icyStone);
        world.setBlock(i + 2, j + 0, k + 16, IceikaBlocks.icyStone);
        world.setBlock(i + 2, j + 0, k + 17, IceikaBlocks.icyStone);
        world.setBlock(i + 2, j + 0, k + 18, IceikaBlocks.icyStone);
        world.setBlock(i + 2, j + 0, k + 19, IceikaBlocks.icyStone);
        world.setBlock(i + 2, j + 0, k + 20, IceikaBlocks.icyStone);
        world.setBlock(i + 2, j + 0, k + 21, IceikaBlocks.icyStone);
        world.setBlock(i + 2, j + 0, k + 22, IceikaBlocks.snowBricks);
        world.setBlock(i + 2, j + 1, k + 11, IceikaBlocks.snowBricks);
        world.setBlock(i + 2, j + 1, k + 12, Blocks.air);
        world.setBlock(i + 2, j + 1, k + 13, Blocks.air);
        world.setBlock(i + 2, j + 1, k + 14, Blocks.air);
        world.setBlock(i + 2, j + 1, k + 15, Blocks.air);
        world.setBlock(i + 2, j + 1, k + 16, Blocks.air);
        world.setBlock(i + 2, j + 1, k + 17, Blocks.air);
        world.setBlock(i + 2, j + 1, k + 18, Blocks.air);
        world.setBlock(i + 2, j + 1, k + 19, Blocks.air);
        world.setBlock(i + 2, j + 1, k + 20, Blocks.air);
        world.setBlock(i + 2, j + 1, k + 21, Blocks.air);
        world.setBlock(i + 2, j + 1, k + 22, IceikaBlocks.snowBricks);
        world.setBlock(i + 2, j + 2, k + 11, IceikaBlocks.snowBricks);
        world.setBlock(i + 2, j + 2, k + 12, Blocks.air);
        world.setBlock(i + 2, j + 2, k + 13, Blocks.air);
        world.setBlock(i + 2, j + 2, k + 14, Blocks.air);
        world.setBlock(i + 2, j + 2, k + 15, Blocks.air);
        world.setBlock(i + 2, j + 2, k + 16, Blocks.air);
        world.setBlock(i + 2, j + 2, k + 17, Blocks.air);
        world.setBlock(i + 2, j + 2, k + 18, Blocks.air);
        world.setBlock(i + 2, j + 2, k + 19, Blocks.air);
        world.setBlock(i + 2, j + 2, k + 20, Blocks.air);
        world.setBlock(i + 2, j + 2, k + 21, Blocks.air);
        world.setBlock(i + 2, j + 2, k + 22, IceikaBlocks.snowBricks);
        world.setBlock(i + 2, j + 3, k + 11, IceikaBlocks.snowBricks);
        world.setBlock(i + 2, j + 3, k + 12, Blocks.air);
        world.setBlock(i + 2, j + 3, k + 13, Blocks.air);
        world.setBlock(i + 2, j + 3, k + 14, Blocks.air);
        world.setBlock(i + 2, j + 3, k + 15, Blocks.air);
        world.setBlock(i + 2, j + 3, k + 16, Blocks.air);
        world.setBlock(i + 2, j + 3, k + 17, Blocks.air);
        world.setBlock(i + 2, j + 3, k + 18, Blocks.air);
        world.setBlock(i + 2, j + 3, k + 19, Blocks.air);
        world.setBlock(i + 2, j + 3, k + 20, Blocks.air);
        world.setBlock(i + 2, j + 3, k + 21, Blocks.air);
        world.setBlock(i + 2, j + 3, k + 22, IceikaBlocks.snowBricks);
        world.setBlock(i + 2, j + 4, k + 12, IceikaBlocks.snowBricks);
        world.setBlock(i + 2, j + 4, k + 13, IceikaBlocks.snowBricks);
        world.setBlock(i + 2, j + 4, k + 14, IceikaBlocks.snowBricks);
        world.setBlock(i + 2, j + 4, k + 15, IceikaBlocks.snowBricks);
        world.setBlock(i + 2, j + 4, k + 16, IceikaBlocks.snowBricks);
        world.setBlock(i + 2, j + 4, k + 17, IceikaBlocks.snowBricks);
        world.setBlock(i + 2, j + 4, k + 18, IceikaBlocks.snowBricks);
        world.setBlock(i + 2, j + 4, k + 19, IceikaBlocks.snowBricks);
        world.setBlock(i + 2, j + 4, k + 20, IceikaBlocks.snowBricks);
        world.setBlock(i + 2, j + 4, k + 21, IceikaBlocks.snowBricks);
        world.setBlock(i + 3, j + 0, k + 11, IceikaBlocks.snowBricks);
        world.setBlock(i + 3, j + 0, k + 12, IceikaBlocks.icyStone);
        world.setBlock(i + 3, j + 0, k + 13, IceikaBlocks.icyStone);
        world.setBlock(i + 3, j + 0, k + 14, IceikaBlocks.icyStone);
        world.setBlock(i + 3, j + 0, k + 15, IceikaBlocks.icyStone);
        world.setBlock(i + 3, j + 0, k + 16, IceikaBlocks.icyStone);
        world.setBlock(i + 3, j + 0, k + 17, IceikaBlocks.icyStone);
        world.setBlock(i + 3, j + 0, k + 18, IceikaBlocks.snowBricks);
        world.setBlock(i + 3, j + 0, k + 19, IceikaBlocks.snowBricks);
        world.setBlock(i + 3, j + 0, k + 20, IceikaBlocks.icyStone);
        world.setBlock(i + 3, j + 0, k + 21, IceikaBlocks.icyStone);
        world.setBlock(i + 3, j + 0, k + 22, IceikaBlocks.snowBricks);
        world.setBlock(i + 3, j + 1, k + 11, IceikaBlocks.snowBricks);
        world.setBlock(i + 3, j + 1, k + 12, Blocks.air);
        world.setBlock(i + 3, j + 1, k + 13, Blocks.air);
        world.setBlock(i + 3, j + 1, k + 14, Blocks.air);
        world.setBlock(i + 3, j + 1, k + 15, Blocks.air);
        world.setBlock(i + 3, j + 1, k + 16, Blocks.air);
        world.setBlock(i + 3, j + 1, k + 17, Blocks.air);
        world.setBlock(i + 3, j + 1, k + 18, IceikaBlocks.snowBricks);
        world.setBlock(i + 3, j + 1, k + 19, IceikaBlocks.snowBricks);
        world.setBlock(i + 3, j + 1, k + 20, Blocks.air);
        world.setBlock(i + 3, j + 1, k + 21, Blocks.air);
        world.setBlock(i + 3, j + 1, k + 22, IceikaBlocks.snowBricks);
        world.setBlock(i + 3, j + 2, k + 11, IceikaBlocks.snowBricks);
        world.setBlock(i + 3, j + 2, k + 12, Blocks.air);
        world.setBlock(i + 3, j + 2, k + 13, Blocks.air);
        world.setBlock(i + 3, j + 2, k + 14, Blocks.air);
        world.setBlock(i + 3, j + 2, k + 15, Blocks.air);
        world.setBlock(i + 3, j + 2, k + 16, Blocks.air);
        world.setBlock(i + 3, j + 2, k + 17, Blocks.air);
        world.setBlock(i + 3, j + 2, k + 18, IceikaBlocks.snowBricks);
        world.setBlock(i + 3, j + 2, k + 19, IceikaBlocks.snowBricks);
        world.setBlock(i + 3, j + 2, k + 20, Blocks.air);
        world.setBlock(i + 3, j + 2, k + 21, Blocks.air);
        world.setBlock(i + 3, j + 2, k + 22, IceikaBlocks.snowBricks);
        world.setBlock(i + 3, j + 3, k + 11, IceikaBlocks.snowBricks);
        world.setBlock(i + 3, j + 3, k + 12, Blocks.air);
        world.setBlock(i + 3, j + 3, k + 13, Blocks.air);
        world.setBlock(i + 3, j + 3, k + 14, Blocks.air);
        world.setBlock(i + 3, j + 3, k + 15, Blocks.air);
        world.setBlock(i + 3, j + 3, k + 16, Blocks.air);
        world.setBlock(i + 3, j + 3, k + 17, Blocks.air);
        world.setBlock(i + 3, j + 3, k + 18, IceikaBlocks.snowBricks);
        world.setBlock(i + 3, j + 3, k + 19, IceikaBlocks.snowBricks);
        world.setBlock(i + 3, j + 3, k + 20, Blocks.air);
        world.setBlock(i + 3, j + 3, k + 21, Blocks.air);
        world.setBlock(i + 3, j + 3, k + 22, IceikaBlocks.snowBricks);
        world.setBlock(i + 3, j + 4, k + 12, IceikaBlocks.snowBricks);
        world.setBlock(i + 3, j + 4, k + 13, IceikaBlocks.snowBricks);
        world.setBlock(i + 3, j + 4, k + 14, IceikaBlocks.snowBricks);
        world.setBlock(i + 3, j + 4, k + 15, IceikaBlocks.snowBricks);
        world.setBlock(i + 3, j + 4, k + 16, IceikaBlocks.snowBricks);
        world.setBlock(i + 3, j + 4, k + 17, IceikaBlocks.snowBricks);
        world.setBlock(i + 3, j + 4, k + 20, IceikaBlocks.snowBricks);
        world.setBlock(i + 3, j + 4, k + 21, IceikaBlocks.snowBricks);
        world.setBlock(i + 4, j + 0, k + 11, IceikaBlocks.snowBricks);
        world.setBlock(i + 4, j + 0, k + 12, IceikaBlocks.icyStone);
        world.setBlock(i + 4, j + 0, k + 13, IceikaBlocks.icyStone);
        world.setBlock(i + 4, j + 0, k + 14, IceikaBlocks.icyStone);
        world.setBlock(i + 4, j + 0, k + 15, IceikaBlocks.icyStone);
        world.setBlock(i + 4, j + 0, k + 16, IceikaBlocks.icyStone);
        world.setBlock(i + 4, j + 0, k + 17, IceikaBlocks.icyStone);
        world.setBlock(i + 4, j + 0, k + 18, IceikaBlocks.snowBricks);
        world.setBlock(i + 4, j + 0, k + 19, IceikaBlocks.snowBricks);
        world.setBlock(i + 4, j + 0, k + 20, IceikaBlocks.icyStone);
        world.setBlock(i + 4, j + 0, k + 21, IceikaBlocks.icyStone);
        world.setBlock(i + 4, j + 0, k + 22, IceikaBlocks.snowBricks);
        world.setBlock(i + 4, j + 0, k + 23, IceikaBlocks.snowBricks);
        world.setBlock(i + 4, j + 0, k + 24, IceikaBlocks.snowBricks);
        world.setBlock(i + 4, j + 0, k + 25, IceikaBlocks.snowBricks);
        world.setBlock(i + 4, j + 1, k + 11, IceikaBlocks.snowBricks);
        world.setBlock(i + 4, j + 1, k + 12, Blocks.air);
        world.setBlock(i + 4, j + 1, k + 13, Blocks.air);
        world.setBlock(i + 4, j + 1, k + 14, IceikaBlocks.glacideSpawner);
        world.setBlock(i + 4, j + 1, k + 15, Blocks.air);
        world.setBlock(i + 4, j + 1, k + 16, Blocks.air);
        world.setBlock(i + 4, j + 1, k + 17, Blocks.air);
        world.setBlock(i + 4, j + 1, k + 18, IceikaBlocks.snowBricks);
        world.setBlock(i + 4, j + 1, k + 19, IceikaBlocks.snowBricks);
        world.setBlock(i + 4, j + 1, k + 20, Blocks.air);
        world.setBlock(i + 4, j + 1, k + 21, Blocks.air);
        world.setBlock(i + 4, j + 1, k + 22, IceikaBlocks.snowBricks);
        world.setBlock(i + 4, j + 1, k + 23, IceikaBlocks.snowBricks);
        world.setBlock(i + 4, j + 1, k + 24, IceikaBlocks.snowBricks);
        world.setBlock(i + 4, j + 1, k + 25, IceikaBlocks.snowBricks);
        world.setBlock(i + 4, j + 2, k + 11, IceikaBlocks.snowBricks);
        world.setBlock(i + 4, j + 2, k + 12, Blocks.air);
        world.setBlock(i + 4, j + 2, k + 13, Blocks.air);
        world.setBlock(i + 4, j + 2, k + 14, Blocks.air);
        world.setBlock(i + 4, j + 2, k + 15, Blocks.air);
        world.setBlock(i + 4, j + 2, k + 16, Blocks.air);
        world.setBlock(i + 4, j + 2, k + 17, Blocks.air);
        world.setBlock(i + 4, j + 2, k + 18, IceikaBlocks.snowBricks);
        world.setBlock(i + 4, j + 2, k + 19, IceikaBlocks.snowBricks);
        world.setBlock(i + 4, j + 2, k + 20, Blocks.air);
        world.setBlock(i + 4, j + 2, k + 21, Blocks.air);
        world.setBlock(i + 4, j + 2, k + 22, IceikaBlocks.snowBricks);
        world.setBlock(i + 4, j + 2, k + 23, IceikaBlocks.snowBricks);
        world.setBlock(i + 4, j + 2, k + 24, IceikaBlocks.snowBricks);
        world.setBlock(i + 4, j + 2, k + 25, IceikaBlocks.snowBricks);
        world.setBlock(i + 4, j + 3, k + 11, IceikaBlocks.snowBricks);
        world.setBlock(i + 4, j + 3, k + 12, Blocks.air);
        world.setBlock(i + 4, j + 3, k + 13, Blocks.air);
        world.setBlock(i + 4, j + 3, k + 14, Blocks.air);
        world.setBlock(i + 4, j + 3, k + 15, Blocks.air);
        world.setBlock(i + 4, j + 3, k + 16, Blocks.air);
        world.setBlock(i + 4, j + 3, k + 17, Blocks.air);
        world.setBlock(i + 4, j + 3, k + 18, IceikaBlocks.snowBricks);
        world.setBlock(i + 4, j + 3, k + 19, IceikaBlocks.snowBricks);
        world.setBlock(i + 4, j + 3, k + 20, Blocks.air);
        world.setBlock(i + 4, j + 3, k + 21, Blocks.air);
        world.setBlock(i + 4, j + 3, k + 22, IceikaBlocks.snowBricks);
        world.setBlock(i + 4, j + 3, k + 23, IceikaBlocks.snowBricks);
        world.setBlock(i + 4, j + 3, k + 24, IceikaBlocks.snowBricks);
        world.setBlock(i + 4, j + 3, k + 25, IceikaBlocks.snowBricks);
        world.setBlock(i + 4, j + 4, k + 12, IceikaBlocks.snowBricks);
        world.setBlock(i + 4, j + 4, k + 13, IceikaBlocks.snowBricks);
        world.setBlock(i + 4, j + 4, k + 14, IceikaBlocks.snowBricks);
        world.setBlock(i + 4, j + 4, k + 15, IceikaBlocks.snowBricks);
        world.setBlock(i + 4, j + 4, k + 16, IceikaBlocks.snowBricks);
        world.setBlock(i + 4, j + 4, k + 17, IceikaBlocks.snowBricks);
        world.setBlock(i + 4, j + 4, k + 20, IceikaBlocks.snowBricks);
        world.setBlock(i + 4, j + 4, k + 21, IceikaBlocks.snowBricks);
        world.setBlock(i + 5, j + 0, k + 11, IceikaBlocks.snowBricks);
        world.setBlock(i + 5, j + 0, k + 12, IceikaBlocks.icyStone);
        world.setBlock(i + 5, j + 0, k + 13, IceikaBlocks.icyStone);
        world.setBlock(i + 5, j + 0, k + 14, IceikaBlocks.icyStone);
        world.setBlock(i + 5, j + 0, k + 15, IceikaBlocks.icyStone);
        world.setBlock(i + 5, j + 0, k + 16, IceikaBlocks.icyStone);
        world.setBlock(i + 5, j + 0, k + 17, IceikaBlocks.icyStone);
        world.setBlock(i + 5, j + 0, k + 18, IceikaBlocks.snowBricks);
        world.setBlock(i + 5, j + 0, k + 19, IceikaBlocks.snowBricks);
        world.setBlock(i + 5, j + 0, k + 20, IceikaBlocks.icyStone);
        world.setBlock(i + 5, j + 0, k + 21, IceikaBlocks.icyStone);
        world.setBlock(i + 5, j + 0, k + 22, IceikaBlocks.icyStone);
        world.setBlock(i + 5, j + 0, k + 23, IceikaBlocks.icyStone);
        world.setBlock(i + 5, j + 0, k + 24, IceikaBlocks.icyStone);
        world.setBlock(i + 5, j + 0, k + 25, IceikaBlocks.icyStone);
        world.setBlock(i + 5, j + 1, k + 11, IceikaBlocks.snowBricks);
        world.setBlock(i + 5, j + 1, k + 12, Blocks.air);
        world.setBlock(i + 5, j + 1, k + 13, Blocks.air);
        world.setBlock(i + 5, j + 1, k + 14, Blocks.air);
        world.setBlock(i + 5, j + 1, k + 15, Blocks.air);
        world.setBlock(i + 5, j + 1, k + 16, Blocks.air);
        world.setBlock(i + 5, j + 1, k + 17, Blocks.air);
        world.setBlock(i + 5, j + 1, k + 18, IceikaBlocks.snowBricks);
        world.setBlock(i + 5, j + 1, k + 19, IceikaBlocks.snowBricks);
        world.setBlock(i + 5, j + 1, k + 20, Blocks.air);
        world.setBlock(i + 5, j + 1, k + 21, Blocks.air);
        world.setBlock(i + 5, j + 1, k + 22, Blocks.air);
        world.setBlock(i + 5, j + 1, k + 23, Blocks.air);
        world.setBlock(i + 5, j + 1, k + 24, Blocks.air);
        world.setBlock(i + 5, j + 2, k + 11, IceikaBlocks.snowBricks);
        world.setBlock(i + 5, j + 2, k + 12, Blocks.air);
        world.setBlock(i + 5, j + 2, k + 13, Blocks.air);
        world.setBlock(i + 5, j + 2, k + 14, Blocks.air);
        world.setBlock(i + 5, j + 2, k + 15, Blocks.air);
        world.setBlock(i + 5, j + 2, k + 16, Blocks.air);
        world.setBlock(i + 5, j + 2, k + 17, Blocks.air);
        world.setBlock(i + 5, j + 2, k + 18, IceikaBlocks.snowBricks);
        world.setBlock(i + 5, j + 2, k + 19, IceikaBlocks.snowBricks);
        world.setBlock(i + 5, j + 2, k + 20, Blocks.air);
        world.setBlock(i + 5, j + 2, k + 21, Blocks.air);
        world.setBlock(i + 5, j + 2, k + 22, Blocks.air);
        world.setBlock(i + 5, j + 2, k + 23, Blocks.air);
        world.setBlock(i + 5, j + 2, k + 24, Blocks.air);
        world.setBlock(i + 5, j + 3, k + 11, IceikaBlocks.snowBricks);
        world.setBlock(i + 5, j + 3, k + 12, Blocks.air);
        world.setBlock(i + 5, j + 3, k + 13, Blocks.air);
        world.setBlock(i + 5, j + 3, k + 14, Blocks.air);
        world.setBlock(i + 5, j + 3, k + 15, Blocks.air);
        world.setBlock(i + 5, j + 3, k + 16, Blocks.air);
        world.setBlock(i + 5, j + 3, k + 17, Blocks.air);
        world.setBlock(i + 5, j + 3, k + 18, IceikaBlocks.snowBricks);
        world.setBlock(i + 5, j + 3, k + 19, IceikaBlocks.snowBricks);
        world.setBlock(i + 5, j + 3, k + 20, Blocks.air);
        world.setBlock(i + 5, j + 3, k + 21, Blocks.air);
        world.setBlock(i + 5, j + 3, k + 22, Blocks.air);
        world.setBlock(i + 5, j + 3, k + 23, Blocks.air);
        world.setBlock(i + 5, j + 3, k + 24, Blocks.air);
        world.setBlock(i + 5, j + 4, k + 12, IceikaBlocks.snowBricks);
        world.setBlock(i + 5, j + 4, k + 13, IceikaBlocks.snowBricks);
        world.setBlock(i + 5, j + 4, k + 14, IceikaBlocks.snowBricks);
        world.setBlock(i + 5, j + 4, k + 15, IceikaBlocks.snowBricks);
        world.setBlock(i + 5, j + 4, k + 16, IceikaBlocks.snowBricks);
        world.setBlock(i + 5, j + 4, k + 17, IceikaBlocks.snowBricks);
        world.setBlock(i + 5, j + 4, k + 20, IceikaBlocks.snowBricks);
        world.setBlock(i + 5, j + 4, k + 21, IceikaBlocks.snowBricks);
        world.setBlock(i + 5, j + 4, k + 22, IceikaBlocks.snowBricks);
        world.setBlock(i + 5, j + 4, k + 23, IceikaBlocks.snowBricks);
        world.setBlock(i + 5, j + 4, k + 24, IceikaBlocks.snowBricks);
        world.setBlock(i + 5, j + 4, k + 25, IceikaBlocks.snowBricks);
        world.setBlock(i + 6, j + 0, k + 11, IceikaBlocks.snowBricks);
        world.setBlock(i + 6, j + 0, k + 12, IceikaBlocks.icyStone);
        world.setBlock(i + 6, j + 0, k + 13, IceikaBlocks.icyStone);
        world.setBlock(i + 6, j + 0, k + 14, IceikaBlocks.icyStone);
        world.setBlock(i + 6, j + 0, k + 15, IceikaBlocks.icyStone);
        world.setBlock(i + 6, j + 0, k + 16, IceikaBlocks.icyStone);
        world.setBlock(i + 6, j + 0, k + 17, IceikaBlocks.icyStone);
        world.setBlock(i + 6, j + 0, k + 18, IceikaBlocks.snowBricks);
        world.setBlock(i + 6, j + 0, k + 19, IceikaBlocks.snowBricks);
        world.setBlock(i + 6, j + 0, k + 20, IceikaBlocks.icyStone);
        world.setBlock(i + 6, j + 0, k + 21, IceikaBlocks.icyStone);
        world.setBlock(i + 6, j + 0, k + 22, IceikaBlocks.icyStone);
        world.setBlock(i + 6, j + 0, k + 23, IceikaBlocks.icyStone);
        world.setBlock(i + 6, j + 0, k + 24, IceikaBlocks.icyStone);
        world.setBlock(i + 6, j + 0, k + 25, IceikaBlocks.icyStone);
        world.setBlock(i + 6, j + 1, k + 11, IceikaBlocks.snowBricks);
        world.setBlock(i + 6, j + 1, k + 12, Blocks.air);
        world.setBlock(i + 6, j + 1, k + 13, Blocks.air);
        world.setBlock(i + 6, j + 1, k + 14, Blocks.air);
        world.setBlock(i + 6, j + 1, k + 15, Blocks.air);
        world.setBlock(i + 6, j + 1, k + 16, Blocks.air);
        world.setBlock(i + 6, j + 1, k + 17, Blocks.air);
        world.setBlock(i + 6, j + 1, k + 18, IceikaBlocks.snowBricks);
        world.setBlock(i + 6, j + 1, k + 19, IceikaBlocks.snowBricks);
        world.setBlock(i + 6, j + 1, k + 20, Blocks.air);
        world.setBlock(i + 6, j + 1, k + 21, Blocks.air);
        world.setBlock(i + 6, j + 1, k + 22, Blocks.air);
        world.setBlock(i + 6, j + 1, k + 23, Blocks.air);
        world.setBlock(i + 6, j + 1, k + 24, Blocks.air);
        world.setBlock(i + 6, j + 2, k + 11, IceikaBlocks.snowBricks);
        world.setBlock(i + 6, j + 2, k + 12, Blocks.air);
        world.setBlock(i + 6, j + 2, k + 13, Blocks.air);
        world.setBlock(i + 6, j + 2, k + 14, Blocks.air);
        world.setBlock(i + 6, j + 2, k + 15, Blocks.air);
        world.setBlock(i + 6, j + 2, k + 16, Blocks.air);
        world.setBlock(i + 6, j + 2, k + 17, Blocks.air);
        world.setBlock(i + 6, j + 2, k + 18, IceikaBlocks.snowBricks);
        world.setBlock(i + 6, j + 2, k + 19, IceikaBlocks.snowBricks);
        world.setBlock(i + 6, j + 2, k + 20, Blocks.air);
        world.setBlock(i + 6, j + 2, k + 21, Blocks.air);
        world.setBlock(i + 6, j + 2, k + 22, Blocks.air);
        world.setBlock(i + 6, j + 2, k + 23, Blocks.air);
        world.setBlock(i + 6, j + 2, k + 24, Blocks.air);
        world.setBlock(i + 6, j + 3, k + 11, IceikaBlocks.snowBricks);
        world.setBlock(i + 6, j + 3, k + 12, Blocks.air);
        world.setBlock(i + 6, j + 3, k + 13, Blocks.air);
        world.setBlock(i + 6, j + 3, k + 14, Blocks.air);
        world.setBlock(i + 6, j + 3, k + 15, Blocks.air);
        world.setBlock(i + 6, j + 3, k + 16, Blocks.air);
        world.setBlock(i + 6, j + 3, k + 17, Blocks.air);
        world.setBlock(i + 6, j + 3, k + 18, IceikaBlocks.snowBricks);
        world.setBlock(i + 6, j + 3, k + 19, IceikaBlocks.snowBricks);
        world.setBlock(i + 6, j + 3, k + 20, Blocks.air);
        world.setBlock(i + 6, j + 3, k + 21, Blocks.air);
        world.setBlock(i + 6, j + 3, k + 22, Blocks.air);
        world.setBlock(i + 6, j + 3, k + 23, Blocks.air);
        world.setBlock(i + 6, j + 3, k + 24, Blocks.air);
        world.setBlock(i + 6, j + 4, k + 12, IceikaBlocks.snowBricks);
        world.setBlock(i + 6, j + 4, k + 13, IceikaBlocks.snowBricks);
        world.setBlock(i + 6, j + 4, k + 14, IceikaBlocks.snowBricks);
        world.setBlock(i + 6, j + 4, k + 15, IceikaBlocks.snowBricks);
        world.setBlock(i + 6, j + 4, k + 16, IceikaBlocks.snowBricks);
        world.setBlock(i + 6, j + 4, k + 17, IceikaBlocks.snowBricks);
        world.setBlock(i + 6, j + 4, k + 20, IceikaBlocks.snowBricks);
        world.setBlock(i + 6, j + 4, k + 21, IceikaBlocks.snowBricks);
        world.setBlock(i + 6, j + 4, k + 22, IceikaBlocks.snowBricks);
        world.setBlock(i + 6, j + 4, k + 23, IceikaBlocks.snowBricks);
        world.setBlock(i + 6, j + 4, k + 24, IceikaBlocks.snowBricks);
        world.setBlock(i + 6, j + 4, k + 25, IceikaBlocks.snowBricks);
        world.setBlock(i + 7, j + 0, k + 0, IceikaBlocks.snowBricks);
        world.setBlock(i + 7, j + 0, k + 1, IceikaBlocks.snowBricks);
        world.setBlock(i + 7, j + 0, k + 2, IceikaBlocks.snowBricks);
        world.setBlock(i + 7, j + 0, k + 3, IceikaBlocks.snowBricks);
        world.setBlock(i + 7, j + 0, k + 4, IceikaBlocks.snowBricks);
        world.setBlock(i + 7, j + 0, k + 5, IceikaBlocks.snowBricks);
        world.setBlock(i + 7, j + 0, k + 6, IceikaBlocks.snowBricks);
        world.setBlock(i + 7, j + 0, k + 7, IceikaBlocks.snowBricks);
        world.setBlock(i + 7, j + 0, k + 8, IceikaBlocks.snowBricks);
        world.setBlock(i + 7, j + 0, k + 11, IceikaBlocks.snowBricks);
        world.setBlock(i + 7, j + 0, k + 12, IceikaBlocks.snowBricks);
        world.setBlock(i + 7, j + 0, k + 13, IceikaBlocks.snowBricks);
        world.setBlock(i + 7, j + 0, k + 14, IceikaBlocks.icyStone);
        world.setBlock(i + 7, j + 0, k + 15, IceikaBlocks.icyStone);
        world.setBlock(i + 7, j + 0, k + 16, IceikaBlocks.snowBricks);
        world.setBlock(i + 7, j + 0, k + 17, IceikaBlocks.snowBricks);
        world.setBlock(i + 7, j + 0, k + 18, IceikaBlocks.snowBricks);
        world.setBlock(i + 7, j + 0, k + 19, IceikaBlocks.snowBricks);
        world.setBlock(i + 7, j + 0, k + 20, IceikaBlocks.snowBricks);
        world.setBlock(i + 7, j + 0, k + 21, IceikaBlocks.snowBricks);
        world.setBlock(i + 7, j + 0, k + 22, IceikaBlocks.snowBricks);
        world.setBlock(i + 7, j + 0, k + 23, IceikaBlocks.snowBricks);
        world.setBlock(i + 7, j + 0, k + 24, IceikaBlocks.snowBricks);
        world.setBlock(i + 7, j + 0, k + 25, IceikaBlocks.snowBricks);
        world.setBlock(i + 7, j + 1, k + 0, IceikaBlocks.snowBricks);
        world.setBlock(i + 7, j + 1, k + 1, IceikaBlocks.snowBricks);
        world.setBlock(i + 7, j + 1, k + 2, IceikaBlocks.snowBricks);
        world.setBlock(i + 7, j + 1, k + 3, IceikaBlocks.snowBricks);
        world.setBlock(i + 7, j + 1, k + 4, IceikaBlocks.snowBricks);
        world.setBlock(i + 7, j + 1, k + 5, IceikaBlocks.snowBricks);
        world.setBlock(i + 7, j + 1, k + 6, IceikaBlocks.snowBricks);
        world.setBlock(i + 7, j + 1, k + 7, IceikaBlocks.snowBricks);
        world.setBlock(i + 7, j + 1, k + 8, IceikaBlocks.snowBricks);
        world.setBlock(i + 7, j + 1, k + 11, IceikaBlocks.snowBricks);
        world.setBlock(i + 7, j + 1, k + 12, IceikaBlocks.snowBricks);
        world.setBlock(i + 7, j + 1, k + 13, IceikaBlocks.snowBricks);
        world.setBlock(i + 7, j + 1, k + 14, Blocks.air);
        world.setBlock(i + 7, j + 1, k + 15, Blocks.air);
        world.setBlock(i + 7, j + 1, k + 16, IceikaBlocks.snowBricks);
        world.setBlock(i + 7, j + 1, k + 17, IceikaBlocks.snowBricks);
        world.setBlock(i + 7, j + 1, k + 18, IceikaBlocks.snowBricks);
        world.setBlock(i + 7, j + 1, k + 19, IceikaBlocks.snowBricks);
        world.setBlock(i + 7, j + 1, k + 20, IceikaBlocks.snowBricks);
        world.setBlock(i + 7, j + 1, k + 21, IceikaBlocks.snowBricks);
        world.setBlock(i + 7, j + 1, k + 22, IceikaBlocks.snowBricks);
        world.setBlock(i + 7, j + 1, k + 23, IceikaBlocks.snowBricks);
        world.setBlock(i + 7, j + 1, k + 24, IceikaBlocks.snowBricks);
        world.setBlock(i + 7, j + 1, k + 25, IceikaBlocks.snowBricks);
        world.setBlock(i + 7, j + 2, k + 0, IceikaBlocks.snowBricks);
        world.setBlock(i + 7, j + 2, k + 1, IceikaBlocks.snowBricks);
        world.setBlock(i + 7, j + 2, k + 2, IceikaBlocks.snowBricks);
        world.setBlock(i + 7, j + 2, k + 3, IceikaBlocks.snowBricks);
        world.setBlock(i + 7, j + 2, k + 4, IceikaBlocks.snowBricks);
        world.setBlock(i + 7, j + 2, k + 5, IceikaBlocks.snowBricks);
        world.setBlock(i + 7, j + 2, k + 6, IceikaBlocks.snowBricks);
        world.setBlock(i + 7, j + 2, k + 7, IceikaBlocks.snowBricks);
        world.setBlock(i + 7, j + 2, k + 8, IceikaBlocks.snowBricks);
        world.setBlock(i + 7, j + 2, k + 11, IceikaBlocks.snowBricks);
        world.setBlock(i + 7, j + 2, k + 12, IceikaBlocks.snowBricks);
        world.setBlock(i + 7, j + 2, k + 13, IceikaBlocks.snowBricks);
        world.setBlock(i + 7, j + 2, k + 14, Blocks.air);
        world.setBlock(i + 7, j + 2, k + 15, Blocks.air);
        world.setBlock(i + 7, j + 2, k + 16, IceikaBlocks.snowBricks);
        world.setBlock(i + 7, j + 2, k + 17, IceikaBlocks.snowBricks);
        world.setBlock(i + 7, j + 2, k + 18, IceikaBlocks.snowBricks);
        world.setBlock(i + 7, j + 2, k + 19, IceikaBlocks.snowBricks);
        world.setBlock(i + 7, j + 2, k + 20, IceikaBlocks.snowBricks);
        world.setBlock(i + 7, j + 2, k + 21, IceikaBlocks.snowBricks);
        world.setBlock(i + 7, j + 2, k + 22, IceikaBlocks.snowBricks);
        world.setBlock(i + 7, j + 2, k + 23, IceikaBlocks.snowBricks);
        world.setBlock(i + 7, j + 2, k + 24, IceikaBlocks.snowBricks);
        world.setBlock(i + 7, j + 2, k + 25, IceikaBlocks.snowBricks);
        world.setBlock(i + 7, j + 3, k + 0, IceikaBlocks.snowBricks);
        world.setBlock(i + 7, j + 3, k + 1, IceikaBlocks.snowBricks);
        world.setBlock(i + 7, j + 3, k + 2, IceikaBlocks.snowBricks);
        world.setBlock(i + 7, j + 3, k + 3, IceikaBlocks.snowBricks);
        world.setBlock(i + 7, j + 3, k + 4, IceikaBlocks.snowBricks);
        world.setBlock(i + 7, j + 3, k + 5, IceikaBlocks.snowBricks);
        world.setBlock(i + 7, j + 3, k + 6, IceikaBlocks.snowBricks);
        world.setBlock(i + 7, j + 3, k + 7, IceikaBlocks.snowBricks);
        world.setBlock(i + 7, j + 3, k + 8, IceikaBlocks.snowBricks);
        world.setBlock(i + 7, j + 3, k + 11, IceikaBlocks.snowBricks);
        world.setBlock(i + 7, j + 3, k + 12, IceikaBlocks.snowBricks);
        world.setBlock(i + 7, j + 3, k + 13, IceikaBlocks.snowBricks);
        world.setBlock(i + 7, j + 3, k + 14, Blocks.air);
        world.setBlock(i + 7, j + 3, k + 15, Blocks.air);
        world.setBlock(i + 7, j + 3, k + 16, IceikaBlocks.snowBricks);
        world.setBlock(i + 7, j + 3, k + 17, IceikaBlocks.snowBricks);
        world.setBlock(i + 7, j + 3, k + 18, IceikaBlocks.snowBricks);
        world.setBlock(i + 7, j + 3, k + 19, IceikaBlocks.snowBricks);
        world.setBlock(i + 7, j + 3, k + 20, IceikaBlocks.snowBricks);
        world.setBlock(i + 7, j + 3, k + 21, IceikaBlocks.snowBricks);
        world.setBlock(i + 7, j + 3, k + 22, IceikaBlocks.snowBricks);
        world.setBlock(i + 7, j + 3, k + 23, IceikaBlocks.snowBricks);
        world.setBlock(i + 7, j + 3, k + 24, IceikaBlocks.snowBricks);
        world.setBlock(i + 7, j + 3, k + 25, IceikaBlocks.snowBricks);
        world.setBlock(i + 7, j + 4, k + 14, IceikaBlocks.snowBricks);
        world.setBlock(i + 7, j + 4, k + 15, IceikaBlocks.snowBricks);
        world.setBlock(i + 8, j + 0, k + 0, IceikaBlocks.snowBricks);
        world.setBlock(i + 8, j + 0, k + 1, IceikaBlocks.icyStone);
        world.setBlock(i + 8, j + 0, k + 2, IceikaBlocks.icyStone);
        world.setBlock(i + 8, j + 0, k + 3, IceikaBlocks.icyStone);
        world.setBlock(i + 8, j + 0, k + 4, IceikaBlocks.icyStone);
        world.setBlock(i + 8, j + 0, k + 5, IceikaBlocks.icyStone);
        world.setBlock(i + 8, j + 0, k + 6, IceikaBlocks.icyStone);
        world.setBlock(i + 8, j + 0, k + 7, IceikaBlocks.icyStone);
        world.setBlock(i + 8, j + 0, k + 8, IceikaBlocks.snowBricks);
        world.setBlock(i + 8, j + 0, k + 13, IceikaBlocks.snowBricks);
        world.setBlock(i + 8, j + 0, k + 14, IceikaBlocks.icyStone);
        world.setBlock(i + 8, j + 0, k + 15, IceikaBlocks.icyStone);
        world.setBlock(i + 8, j + 0, k + 16, IceikaBlocks.snowBricks);
        world.setBlock(i + 8, j + 1, k + 0, IceikaBlocks.snowBricks);
        world.setBlock(i + 8, j + 1, k + 1, IceikaBlocks.frostedChest);
        world.setBlock(i + 8, j + 1, k + 2, Blocks.air);
        world.setBlock(i + 8, j + 1, k + 3, Blocks.air);
        world.setBlock(i + 8, j + 1, k + 4, Blocks.air);
        world.setBlock(i + 8, j + 1, k + 5, Blocks.air);
        world.setBlock(i + 8, j + 1, k + 6, Blocks.air);
        world.setBlock(i + 8, j + 1, k + 7, Blocks.air);
        world.setBlock(i + 8, j + 1, k + 8, IceikaBlocks.snowBricks);
        world.setBlock(i + 8, j + 1, k + 13, IceikaBlocks.snowBricks);
        world.setBlock(i + 8, j + 1, k + 14, Blocks.air);
        world.setBlock(i + 8, j + 1, k + 15, Blocks.air);
        world.setBlock(i + 8, j + 1, k + 16, IceikaBlocks.snowBricks);
        world.setBlock(i + 8, j + 2, k + 0, IceikaBlocks.snowBricks);
        world.setBlock(i + 8, j + 2, k + 1, Blocks.air);
        world.setBlock(i + 8, j + 2, k + 2, Blocks.air);
        world.setBlock(i + 8, j + 2, k + 3, Blocks.air);
        world.setBlock(i + 8, j + 2, k + 4, Blocks.air);
        world.setBlock(i + 8, j + 2, k + 5, Blocks.air);
        world.setBlock(i + 8, j + 2, k + 6, Blocks.air);
        world.setBlock(i + 8, j + 2, k + 7, Blocks.air);
        world.setBlock(i + 8, j + 2, k + 8, IceikaBlocks.snowBricks);
        world.setBlock(i + 8, j + 2, k + 13, IceikaBlocks.snowBricks);
        world.setBlock(i + 8, j + 2, k + 14, Blocks.air);
        world.setBlock(i + 8, j + 2, k + 15, Blocks.air);
        world.setBlock(i + 8, j + 2, k + 16, IceikaBlocks.snowBricks);
        world.setBlock(i + 8, j + 3, k + 0, IceikaBlocks.snowBricks);
        world.setBlock(i + 8, j + 3, k + 1, Blocks.air);
        world.setBlock(i + 8, j + 3, k + 2, Blocks.air);
        world.setBlock(i + 8, j + 3, k + 3, Blocks.air);
        world.setBlock(i + 8, j + 3, k + 4, Blocks.air);
        world.setBlock(i + 8, j + 3, k + 5, Blocks.air);
        world.setBlock(i + 8, j + 3, k + 6, Blocks.air);
        world.setBlock(i + 8, j + 3, k + 7, Blocks.air);
        world.setBlock(i + 8, j + 3, k + 8, IceikaBlocks.snowBricks);
        world.setBlock(i + 8, j + 3, k + 13, IceikaBlocks.snowBricks);
        world.setBlock(i + 8, j + 3, k + 14, Blocks.air);
        world.setBlock(i + 8, j + 3, k + 15, Blocks.air);
        world.setBlock(i + 8, j + 3, k + 16, IceikaBlocks.snowBricks);
        world.setBlock(i + 8, j + 4, k + 1, IceikaBlocks.snowBricks);
        world.setBlock(i + 8, j + 4, k + 2, IceikaBlocks.snowBricks);
        world.setBlock(i + 8, j + 4, k + 3, IceikaBlocks.snowBricks);
        world.setBlock(i + 8, j + 4, k + 4, IceikaBlocks.snowBricks);
        world.setBlock(i + 8, j + 4, k + 5, IceikaBlocks.snowBricks);
        world.setBlock(i + 8, j + 4, k + 6, IceikaBlocks.snowBricks);
        world.setBlock(i + 8, j + 4, k + 7, IceikaBlocks.snowBricks);
        world.setBlock(i + 8, j + 4, k + 14, IceikaBlocks.snowBricks);
        world.setBlock(i + 8, j + 4, k + 15, IceikaBlocks.snowBricks);
        world.setBlock(i + 9, j + 0, k + 0, IceikaBlocks.snowBricks);
        world.setBlock(i + 9, j + 0, k + 1, IceikaBlocks.icyStone);
        world.setBlock(i + 9, j + 0, k + 2, IceikaBlocks.icyStone);
        world.setBlock(i + 9, j + 0, k + 3, IceikaBlocks.icyStone);
        world.setBlock(i + 9, j + 0, k + 4, IceikaBlocks.icyStone);
        world.setBlock(i + 9, j + 0, k + 5, IceikaBlocks.icyStone);
        world.setBlock(i + 9, j + 0, k + 6, IceikaBlocks.icyStone);
        world.setBlock(i + 9, j + 0, k + 7, IceikaBlocks.icyStone);
        world.setBlock(i + 9, j + 0, k + 8, IceikaBlocks.snowBricks);
        world.setBlock(i + 9, j + 0, k + 9, IceikaBlocks.snowBricks);
        world.setBlock(i + 9, j + 0, k + 10, IceikaBlocks.snowBricks);
        world.setBlock(i + 9, j + 0, k + 11, IceikaBlocks.snowBricks);
        world.setBlock(i + 9, j + 0, k + 12, IceikaBlocks.snowBricks);
        world.setBlock(i + 9, j + 0, k + 13, IceikaBlocks.snowBricks);
        world.setBlock(i + 9, j + 0, k + 14, IceikaBlocks.icyStone);
        world.setBlock(i + 9, j + 0, k + 15, IceikaBlocks.icyStone);
        world.setBlock(i + 9, j + 0, k + 16, IceikaBlocks.snowBricks);
        world.setBlock(i + 9, j + 1, k + 0, IceikaBlocks.snowBricks);
        world.setBlock(i + 9, j + 1, k + 1, Blocks.air);
        world.setBlock(i + 9, j + 1, k + 2, Blocks.air);
        world.setBlock(i + 9, j + 1, k + 3, Blocks.air);
        world.setBlock(i + 9, j + 1, k + 4, IceikaBlocks.glacideSpawner);
        world.setBlock(i + 9, j + 1, k + 5, Blocks.air);
        world.setBlock(i + 9, j + 1, k + 6, Blocks.air);
        world.setBlock(i + 9, j + 1, k + 7, Blocks.air);
        world.setBlock(i + 9, j + 1, k + 8, IceikaBlocks.snowBricks);
        world.setBlock(i + 9, j + 1, k + 9, IceikaBlocks.snowBricks);
        world.setBlock(i + 9, j + 1, k + 10, IceikaBlocks.snowBricks);
        world.setBlock(i + 9, j + 1, k + 11, IceikaBlocks.snowBricks);
        world.setBlock(i + 9, j + 1, k + 12, IceikaBlocks.snowBricks);
        world.setBlock(i + 9, j + 1, k + 13, IceikaBlocks.snowBricks);
        world.setBlock(i + 9, j + 1, k + 14, Blocks.air);
        world.setBlock(i + 9, j + 1, k + 15, Blocks.air);
        world.setBlock(i + 9, j + 1, k + 16, IceikaBlocks.snowBricks);
        world.setBlock(i + 9, j + 2, k + 0, IceikaBlocks.snowBricks);
        world.setBlock(i + 9, j + 2, k + 1, Blocks.air);
        world.setBlock(i + 9, j + 2, k + 2, Blocks.air);
        world.setBlock(i + 9, j + 2, k + 3, Blocks.air);
        world.setBlock(i + 9, j + 2, k + 4, Blocks.air);
        world.setBlock(i + 9, j + 2, k + 5, Blocks.air);
        world.setBlock(i + 9, j + 2, k + 6, Blocks.air);
        world.setBlock(i + 9, j + 2, k + 7, Blocks.air);
        world.setBlock(i + 9, j + 2, k + 8, IceikaBlocks.snowBricks);
        world.setBlock(i + 9, j + 2, k + 9, IceikaBlocks.snowBricks);
        world.setBlock(i + 9, j + 2, k + 10, IceikaBlocks.snowBricks);
        world.setBlock(i + 9, j + 2, k + 11, IceikaBlocks.snowBricks);
        world.setBlock(i + 9, j + 2, k + 12, IceikaBlocks.snowBricks);
        world.setBlock(i + 9, j + 2, k + 13, IceikaBlocks.snowBricks);
        world.setBlock(i + 9, j + 2, k + 14, Blocks.air);
        world.setBlock(i + 9, j + 2, k + 15, Blocks.air);
        world.setBlock(i + 9, j + 2, k + 16, IceikaBlocks.snowBricks);
        world.setBlock(i + 9, j + 3, k + 0, IceikaBlocks.snowBricks);
        world.setBlock(i + 9, j + 3, k + 1, Blocks.air);
        world.setBlock(i + 9, j + 3, k + 2, Blocks.air);
        world.setBlock(i + 9, j + 3, k + 3, Blocks.air);
        world.setBlock(i + 9, j + 3, k + 4, Blocks.air);
        world.setBlock(i + 9, j + 3, k + 5, Blocks.air);
        world.setBlock(i + 9, j + 3, k + 6, Blocks.air);
        world.setBlock(i + 9, j + 3, k + 7, Blocks.air);
        world.setBlock(i + 9, j + 3, k + 8, IceikaBlocks.snowBricks);
        world.setBlock(i + 9, j + 3, k + 9, IceikaBlocks.snowBricks);
        world.setBlock(i + 9, j + 3, k + 10, IceikaBlocks.snowBricks);
        world.setBlock(i + 9, j + 3, k + 11, IceikaBlocks.snowBricks);
        world.setBlock(i + 9, j + 3, k + 12, IceikaBlocks.snowBricks);
        world.setBlock(i + 9, j + 3, k + 13, IceikaBlocks.snowBricks);
        world.setBlock(i + 9, j + 3, k + 14, Blocks.air);
        world.setBlock(i + 9, j + 3, k + 15, Blocks.air);
        world.setBlock(i + 9, j + 3, k + 16, IceikaBlocks.snowBricks);
        world.setBlock(i + 9, j + 4, k + 1, IceikaBlocks.snowBricks);
        world.setBlock(i + 9, j + 4, k + 2, IceikaBlocks.snowBricks);
        world.setBlock(i + 9, j + 4, k + 3, IceikaBlocks.snowBricks);
        world.setBlock(i + 9, j + 4, k + 4, IceikaBlocks.snowBricks);
        world.setBlock(i + 9, j + 4, k + 5, IceikaBlocks.snowBricks);
        world.setBlock(i + 9, j + 4, k + 6, IceikaBlocks.snowBricks);
        world.setBlock(i + 9, j + 4, k + 7, IceikaBlocks.snowBricks);
        world.setBlock(i + 9, j + 4, k + 14, IceikaBlocks.snowBricks);
        world.setBlock(i + 9, j + 4, k + 15, IceikaBlocks.snowBricks);
        world.setBlock(i + 10, j + 0, k + 0, IceikaBlocks.snowBricks);
        world.setBlock(i + 10, j + 0, k + 1, IceikaBlocks.icyStone);
        world.setBlock(i + 10, j + 0, k + 2, IceikaBlocks.icyStone);
        world.setBlock(i + 10, j + 0, k + 3, IceikaBlocks.icyStone);
        world.setBlock(i + 10, j + 0, k + 4, IceikaBlocks.icyStone);
        world.setBlock(i + 10, j + 0, k + 5, IceikaBlocks.icyStone);
        world.setBlock(i + 10, j + 0, k + 6, IceikaBlocks.icyStone);
        world.setBlock(i + 10, j + 0, k + 7, IceikaBlocks.icyStone);
        world.setBlock(i + 10, j + 0, k + 8, IceikaBlocks.icyStone);
        world.setBlock(i + 10, j + 0, k + 9, IceikaBlocks.icyStone);
        world.setBlock(i + 10, j + 0, k + 10, IceikaBlocks.icyStone);
        world.setBlock(i + 10, j + 0, k + 11, IceikaBlocks.icyStone);
        world.setBlock(i + 10, j + 0, k + 12, IceikaBlocks.icyStone);
        world.setBlock(i + 10, j + 0, k + 13, IceikaBlocks.icyStone);
        world.setBlock(i + 10, j + 0, k + 14, IceikaBlocks.icyStone);
        world.setBlock(i + 10, j + 0, k + 15, IceikaBlocks.icyStone);
        world.setBlock(i + 10, j + 0, k + 16, IceikaBlocks.snowBricks);
        world.setBlock(i + 10, j + 1, k + 0, IceikaBlocks.snowBricks);
        world.setBlock(i + 10, j + 1, k + 1, Blocks.air);
        world.setBlock(i + 10, j + 1, k + 2, Blocks.air);
        world.setBlock(i + 10, j + 1, k + 3, Blocks.air);
        world.setBlock(i + 10, j + 1, k + 4, Blocks.air);
        world.setBlock(i + 10, j + 1, k + 5, Blocks.air);
        world.setBlock(i + 10, j + 1, k + 6, Blocks.air);
        world.setBlock(i + 10, j + 1, k + 7, Blocks.air);
        world.setBlock(i + 10, j + 1, k + 8, Blocks.air);
        world.setBlock(i + 10, j + 1, k + 9, Blocks.air);
        world.setBlock(i + 10, j + 1, k + 10, Blocks.air);
        world.setBlock(i + 10, j + 1, k + 11, Blocks.air);
        world.setBlock(i + 10, j + 1, k + 12, Blocks.air);
        world.setBlock(i + 10, j + 1, k + 13, Blocks.air);
        world.setBlock(i + 10, j + 1, k + 14, Blocks.air);
        world.setBlock(i + 10, j + 1, k + 15, Blocks.air);
        world.setBlock(i + 10, j + 1, k + 16, IceikaBlocks.snowBricks);
        world.setBlock(i + 10, j + 2, k + 0, IceikaBlocks.snowBricks);
        world.setBlock(i + 10, j + 2, k + 1, Blocks.air);
        world.setBlock(i + 10, j + 2, k + 2, Blocks.air);
        world.setBlock(i + 10, j + 2, k + 3, Blocks.air);
        world.setBlock(i + 10, j + 2, k + 4, Blocks.air);
        world.setBlock(i + 10, j + 2, k + 5, Blocks.air);
        world.setBlock(i + 10, j + 2, k + 6, Blocks.air);
        world.setBlock(i + 10, j + 2, k + 7, Blocks.air);
        world.setBlock(i + 10, j + 2, k + 8, Blocks.air);
        world.setBlock(i + 10, j + 2, k + 9, Blocks.air);
        world.setBlock(i + 10, j + 2, k + 10, Blocks.air);
        world.setBlock(i + 10, j + 2, k + 11, Blocks.air);
        world.setBlock(i + 10, j + 2, k + 12, Blocks.air);
        world.setBlock(i + 10, j + 2, k + 13, Blocks.air);
        world.setBlock(i + 10, j + 2, k + 14, Blocks.air);
        world.setBlock(i + 10, j + 2, k + 15, Blocks.air);
        world.setBlock(i + 10, j + 2, k + 16, IceikaBlocks.snowBricks);
        world.setBlock(i + 10, j + 3, k + 0, IceikaBlocks.snowBricks);
        world.setBlock(i + 10, j + 3, k + 1, Blocks.air);
        world.setBlock(i + 10, j + 3, k + 2, Blocks.air);
        world.setBlock(i + 10, j + 3, k + 3, Blocks.air);
        world.setBlock(i + 10, j + 3, k + 4, Blocks.air);
        world.setBlock(i + 10, j + 3, k + 5, Blocks.air);
        world.setBlock(i + 10, j + 3, k + 6, Blocks.air);
        world.setBlock(i + 10, j + 3, k + 7, Blocks.air);
        world.setBlock(i + 10, j + 3, k + 8, Blocks.air);
        world.setBlock(i + 10, j + 3, k + 9, Blocks.air);
        world.setBlock(i + 10, j + 3, k + 10, Blocks.air);
        world.setBlock(i + 10, j + 3, k + 11, Blocks.air);
        world.setBlock(i + 10, j + 3, k + 12, Blocks.air);
        world.setBlock(i + 10, j + 3, k + 13, Blocks.air);
        world.setBlock(i + 10, j + 3, k + 14, Blocks.air);
        world.setBlock(i + 10, j + 3, k + 15, Blocks.air);
        world.setBlock(i + 10, j + 3, k + 16, IceikaBlocks.snowBricks);
        world.setBlock(i + 10, j + 4, k + 1, IceikaBlocks.snowBricks);
        world.setBlock(i + 10, j + 4, k + 2, IceikaBlocks.snowBricks);
        world.setBlock(i + 10, j + 4, k + 3, IceikaBlocks.snowBricks);
        world.setBlock(i + 10, j + 4, k + 4, IceikaBlocks.snowBricks);
        world.setBlock(i + 10, j + 4, k + 5, IceikaBlocks.snowBricks);
        world.setBlock(i + 10, j + 4, k + 6, IceikaBlocks.snowBricks);
        world.setBlock(i + 10, j + 4, k + 7, IceikaBlocks.snowBricks);
        world.setBlock(i + 10, j + 4, k + 8, IceikaBlocks.snowBricks);
        world.setBlock(i + 10, j + 4, k + 9, IceikaBlocks.snowBricks);
        world.setBlock(i + 10, j + 4, k + 10, IceikaBlocks.snowBricks);
        world.setBlock(i + 10, j + 4, k + 11, IceikaBlocks.snowBricks);
        world.setBlock(i + 10, j + 4, k + 12, IceikaBlocks.snowBricks);
        world.setBlock(i + 10, j + 4, k + 13, IceikaBlocks.snowBricks);
        world.setBlock(i + 10, j + 4, k + 14, IceikaBlocks.snowBricks);
        world.setBlock(i + 10, j + 4, k + 15, IceikaBlocks.snowBricks);
        world.setBlock(i + 11, j + 0, k + 0, IceikaBlocks.snowBricks);
        world.setBlock(i + 11, j + 0, k + 1, IceikaBlocks.icyStone);
        world.setBlock(i + 11, j + 0, k + 2, IceikaBlocks.icyStone);
        world.setBlock(i + 11, j + 0, k + 3, IceikaBlocks.icyStone);
        world.setBlock(i + 11, j + 0, k + 4, IceikaBlocks.icyStone);
        world.setBlock(i + 11, j + 0, k + 5, IceikaBlocks.icyStone);
        world.setBlock(i + 11, j + 0, k + 6, IceikaBlocks.icyStone);
        world.setBlock(i + 11, j + 0, k + 7, IceikaBlocks.icyStone);
        world.setBlock(i + 11, j + 0, k + 8, IceikaBlocks.icyStone);
        world.setBlock(i + 11, j + 0, k + 9, IceikaBlocks.icyStone);
        world.setBlock(i + 11, j + 0, k + 10, IceikaBlocks.icyStone);
        world.setBlock(i + 11, j + 0, k + 11, IceikaBlocks.icyStone);
        world.setBlock(i + 11, j + 0, k + 12, IceikaBlocks.icyStone);
        world.setBlock(i + 11, j + 0, k + 13, IceikaBlocks.icyStone);
        world.setBlock(i + 11, j + 0, k + 14, IceikaBlocks.icyStone);
        world.setBlock(i + 11, j + 0, k + 15, IceikaBlocks.icyStone);
        world.setBlock(i + 11, j + 0, k + 16, IceikaBlocks.snowBricks);
        world.setBlock(i + 11, j + 1, k + 0, IceikaBlocks.snowBricks);
        world.setBlock(i + 11, j + 1, k + 1, Blocks.air);
        world.setBlock(i + 11, j + 1, k + 2, Blocks.air);
        world.setBlock(i + 11, j + 1, k + 3, Blocks.air);
        world.setBlock(i + 11, j + 1, k + 4, Blocks.air);
        world.setBlock(i + 11, j + 1, k + 5, Blocks.air);
        world.setBlock(i + 11, j + 1, k + 6, Blocks.air);
        world.setBlock(i + 11, j + 1, k + 7, Blocks.air);
        world.setBlock(i + 11, j + 1, k + 8, Blocks.air);
        world.setBlock(i + 11, j + 1, k + 9, Blocks.air);
        world.setBlock(i + 11, j + 1, k + 10, Blocks.air);
        world.setBlock(i + 11, j + 1, k + 11, Blocks.air);
        world.setBlock(i + 11, j + 1, k + 12, Blocks.air);
        world.setBlock(i + 11, j + 1, k + 13, Blocks.air);
        world.setBlock(i + 11, j + 1, k + 14, Blocks.air);
        world.setBlock(i + 11, j + 1, k + 15, Blocks.air);
        world.setBlock(i + 11, j + 1, k + 16, IceikaBlocks.snowBricks);
        world.setBlock(i + 11, j + 2, k + 0, IceikaBlocks.snowBricks);
        world.setBlock(i + 11, j + 2, k + 1, Blocks.air);
        world.setBlock(i + 11, j + 2, k + 2, Blocks.air);
        world.setBlock(i + 11, j + 2, k + 3, Blocks.air);
        world.setBlock(i + 11, j + 2, k + 4, Blocks.air);
        world.setBlock(i + 11, j + 2, k + 5, Blocks.air);
        world.setBlock(i + 11, j + 2, k + 6, Blocks.air);
        world.setBlock(i + 11, j + 2, k + 7, Blocks.air);
        world.setBlock(i + 11, j + 2, k + 8, Blocks.air);
        world.setBlock(i + 11, j + 2, k + 9, Blocks.air);
        world.setBlock(i + 11, j + 2, k + 10, Blocks.air);
        world.setBlock(i + 11, j + 2, k + 11, Blocks.air);
        world.setBlock(i + 11, j + 2, k + 12, Blocks.air);
        world.setBlock(i + 11, j + 2, k + 13, Blocks.air);
        world.setBlock(i + 11, j + 2, k + 14, Blocks.air);
        world.setBlock(i + 11, j + 2, k + 15, Blocks.air);
        world.setBlock(i + 11, j + 2, k + 16, IceikaBlocks.snowBricks);
        world.setBlock(i + 11, j + 3, k + 0, IceikaBlocks.snowBricks);
        world.setBlock(i + 11, j + 3, k + 1, Blocks.air);
        world.setBlock(i + 11, j + 3, k + 2, Blocks.air);
        world.setBlock(i + 11, j + 3, k + 3, Blocks.air);
        world.setBlock(i + 11, j + 3, k + 4, Blocks.air);
        world.setBlock(i + 11, j + 3, k + 5, Blocks.air);
        world.setBlock(i + 11, j + 3, k + 6, Blocks.air);
        world.setBlock(i + 11, j + 3, k + 7, Blocks.air);
        world.setBlock(i + 11, j + 3, k + 8, Blocks.air);
        world.setBlock(i + 11, j + 3, k + 9, Blocks.air);
        world.setBlock(i + 11, j + 3, k + 10, Blocks.air);
        world.setBlock(i + 11, j + 3, k + 11, Blocks.air);
        world.setBlock(i + 11, j + 3, k + 12, Blocks.air);
        world.setBlock(i + 11, j + 3, k + 13, Blocks.air);
        world.setBlock(i + 11, j + 3, k + 14, Blocks.air);
        world.setBlock(i + 11, j + 3, k + 15, Blocks.air);
        world.setBlock(i + 11, j + 3, k + 16, IceikaBlocks.snowBricks);
        world.setBlock(i + 11, j + 4, k + 1, IceikaBlocks.snowBricks);
        world.setBlock(i + 11, j + 4, k + 2, IceikaBlocks.snowBricks);
        world.setBlock(i + 11, j + 4, k + 3, IceikaBlocks.snowBricks);
        world.setBlock(i + 11, j + 4, k + 4, IceikaBlocks.snowBricks);
        world.setBlock(i + 11, j + 4, k + 5, IceikaBlocks.snowBricks);
        world.setBlock(i + 11, j + 4, k + 6, IceikaBlocks.snowBricks);
        world.setBlock(i + 11, j + 4, k + 7, IceikaBlocks.snowBricks);
        world.setBlock(i + 11, j + 4, k + 8, IceikaBlocks.snowBricks);
        world.setBlock(i + 11, j + 4, k + 9, IceikaBlocks.snowBricks);
        world.setBlock(i + 11, j + 4, k + 10, IceikaBlocks.snowBricks);
        world.setBlock(i + 11, j + 4, k + 11, IceikaBlocks.snowBricks);
        world.setBlock(i + 11, j + 4, k + 12, IceikaBlocks.snowBricks);
        world.setBlock(i + 11, j + 4, k + 13, IceikaBlocks.snowBricks);
        world.setBlock(i + 11, j + 4, k + 14, IceikaBlocks.snowBricks);
        world.setBlock(i + 11, j + 4, k + 15, IceikaBlocks.snowBricks);
        world.setBlock(i + 12, j + 0, k + 0, IceikaBlocks.snowBricks);
        world.setBlock(i + 12, j + 0, k + 1, IceikaBlocks.icyStone);
        world.setBlock(i + 12, j + 0, k + 2, IceikaBlocks.icyStone);
        world.setBlock(i + 12, j + 0, k + 3, IceikaBlocks.icyStone);
        world.setBlock(i + 12, j + 0, k + 4, IceikaBlocks.icyStone);
        world.setBlock(i + 12, j + 0, k + 5, IceikaBlocks.icyStone);
        world.setBlock(i + 12, j + 0, k + 6, IceikaBlocks.icyStone);
        world.setBlock(i + 12, j + 0, k + 7, IceikaBlocks.icyStone);
        world.setBlock(i + 12, j + 0, k + 8, IceikaBlocks.snowBricks);
        world.setBlock(i + 12, j + 0, k + 9, IceikaBlocks.snowBricks);
        world.setBlock(i + 12, j + 0, k + 10, IceikaBlocks.snowBricks);
        world.setBlock(i + 12, j + 0, k + 11, IceikaBlocks.snowBricks);
        world.setBlock(i + 12, j + 0, k + 12, IceikaBlocks.snowBricks);
        world.setBlock(i + 12, j + 0, k + 13, IceikaBlocks.snowBricks);
        world.setBlock(i + 12, j + 0, k + 14, IceikaBlocks.snowBricks);
        world.setBlock(i + 12, j + 0, k + 15, IceikaBlocks.snowBricks);
        world.setBlock(i + 12, j + 0, k + 16, IceikaBlocks.snowBricks);
        world.setBlock(i + 12, j + 1, k + 0, IceikaBlocks.snowBricks);
        world.setBlock(i + 12, j + 1, k + 1, Blocks.air);
        world.setBlock(i + 12, j + 1, k + 2, Blocks.air);
        world.setBlock(i + 12, j + 1, k + 3, Blocks.air);
        world.setBlock(i + 12, j + 1, k + 4, IceikaBlocks.glacideSpawner);
        world.setBlock(i + 12, j + 1, k + 5, Blocks.air);
        world.setBlock(i + 12, j + 1, k + 6, Blocks.air);
        world.setBlock(i + 12, j + 1, k + 7, Blocks.air);
        world.setBlock(i + 12, j + 1, k + 8, IceikaBlocks.snowBricks);
        world.setBlock(i + 12, j + 1, k + 9, IceikaBlocks.snowBricks);
        world.setBlock(i + 12, j + 1, k + 10, IceikaBlocks.snowBricks);
        world.setBlock(i + 12, j + 1, k + 11, IceikaBlocks.snowBricks);
        world.setBlock(i + 12, j + 1, k + 12, IceikaBlocks.snowBricks);
        world.setBlock(i + 12, j + 1, k + 13, IceikaBlocks.snowBricks);
        world.setBlock(i + 12, j + 1, k + 14, IceikaBlocks.snowBricks);
        world.setBlock(i + 12, j + 1, k + 15, IceikaBlocks.snowBricks);
        world.setBlock(i + 12, j + 1, k + 16, IceikaBlocks.snowBricks);
        world.setBlock(i + 12, j + 2, k + 0, IceikaBlocks.snowBricks);
        world.setBlock(i + 12, j + 2, k + 1, Blocks.air);
        world.setBlock(i + 12, j + 2, k + 2, Blocks.air);
        world.setBlock(i + 12, j + 2, k + 3, Blocks.air);
        world.setBlock(i + 12, j + 2, k + 4, Blocks.air);
        world.setBlock(i + 12, j + 2, k + 5, Blocks.air);
        world.setBlock(i + 12, j + 2, k + 6, Blocks.air);
        world.setBlock(i + 12, j + 2, k + 7, Blocks.air);
        world.setBlock(i + 12, j + 2, k + 8, IceikaBlocks.snowBricks);
        world.setBlock(i + 12, j + 2, k + 9, IceikaBlocks.snowBricks);
        world.setBlock(i + 12, j + 2, k + 10, IceikaBlocks.snowBricks);
        world.setBlock(i + 12, j + 2, k + 11, IceikaBlocks.snowBricks);
        world.setBlock(i + 12, j + 2, k + 12, IceikaBlocks.snowBricks);
        world.setBlock(i + 12, j + 2, k + 13, IceikaBlocks.snowBricks);
        world.setBlock(i + 12, j + 2, k + 14, IceikaBlocks.snowBricks);
        world.setBlock(i + 12, j + 2, k + 15, IceikaBlocks.snowBricks);
        world.setBlock(i + 12, j + 2, k + 16, IceikaBlocks.snowBricks);
        world.setBlock(i + 12, j + 3, k + 0, IceikaBlocks.snowBricks);
        world.setBlock(i + 12, j + 3, k + 1, Blocks.air);
        world.setBlock(i + 12, j + 3, k + 2, Blocks.air);
        world.setBlock(i + 12, j + 3, k + 3, Blocks.air);
        world.setBlock(i + 12, j + 3, k + 4, Blocks.air);
        world.setBlock(i + 12, j + 3, k + 5, Blocks.air);
        world.setBlock(i + 12, j + 3, k + 6, Blocks.air);
        world.setBlock(i + 12, j + 3, k + 7, Blocks.air);
        world.setBlock(i + 12, j + 3, k + 8, IceikaBlocks.snowBricks);
        world.setBlock(i + 12, j + 3, k + 9, IceikaBlocks.snowBricks);
        world.setBlock(i + 12, j + 3, k + 10, IceikaBlocks.snowBricks);
        world.setBlock(i + 12, j + 3, k + 11, IceikaBlocks.snowBricks);
        world.setBlock(i + 12, j + 3, k + 12, IceikaBlocks.snowBricks);
        world.setBlock(i + 12, j + 3, k + 13, IceikaBlocks.snowBricks);
        world.setBlock(i + 12, j + 3, k + 14, IceikaBlocks.snowBricks);
        world.setBlock(i + 12, j + 3, k + 15, IceikaBlocks.snowBricks);
        world.setBlock(i + 12, j + 3, k + 16, IceikaBlocks.snowBricks);
        world.setBlock(i + 12, j + 4, k + 1, IceikaBlocks.snowBricks);
        world.setBlock(i + 12, j + 4, k + 2, IceikaBlocks.snowBricks);
        world.setBlock(i + 12, j + 4, k + 3, IceikaBlocks.snowBricks);
        world.setBlock(i + 12, j + 4, k + 4, IceikaBlocks.snowBricks);
        world.setBlock(i + 12, j + 4, k + 5, IceikaBlocks.snowBricks);
        world.setBlock(i + 12, j + 4, k + 6, IceikaBlocks.snowBricks);
        world.setBlock(i + 12, j + 4, k + 7, IceikaBlocks.snowBricks);
        world.setBlock(i + 13, j + 0, k + 0, IceikaBlocks.snowBricks);
        world.setBlock(i + 13, j + 0, k + 1, IceikaBlocks.icyStone);
        world.setBlock(i + 13, j + 0, k + 2, IceikaBlocks.icyStone);
        world.setBlock(i + 13, j + 0, k + 3, IceikaBlocks.icyStone);
        world.setBlock(i + 13, j + 0, k + 4, IceikaBlocks.icyStone);
        world.setBlock(i + 13, j + 0, k + 5, IceikaBlocks.icyStone);
        world.setBlock(i + 13, j + 0, k + 6, IceikaBlocks.icyStone);
        world.setBlock(i + 13, j + 0, k + 7, IceikaBlocks.icyStone);
        world.setBlock(i + 13, j + 0, k + 8, IceikaBlocks.snowBricks);
        world.setBlock(i + 13, j + 1, k + 0, IceikaBlocks.snowBricks);
        world.setBlock(i + 13, j + 1, k + 1, IceikaBlocks.frostedChest);
        world.setBlock(i + 13, j + 1, k + 2, Blocks.air);
        world.setBlock(i + 13, j + 1, k + 3, Blocks.air);
        world.setBlock(i + 13, j + 1, k + 4, Blocks.air);
        world.setBlock(i + 13, j + 1, k + 5, Blocks.air);
        world.setBlock(i + 13, j + 1, k + 6, Blocks.air);
        world.setBlock(i + 13, j + 1, k + 7, Blocks.air);
        world.setBlock(i + 13, j + 1, k + 8, IceikaBlocks.snowBricks);
        world.setBlock(i + 13, j + 2, k + 0, IceikaBlocks.snowBricks);
        world.setBlock(i + 13, j + 2, k + 1, Blocks.air);
        world.setBlock(i + 13, j + 2, k + 2, Blocks.air);
        world.setBlock(i + 13, j + 2, k + 3, Blocks.air);
        world.setBlock(i + 13, j + 2, k + 4, Blocks.air);
        world.setBlock(i + 13, j + 2, k + 5, Blocks.air);
        world.setBlock(i + 13, j + 2, k + 6, Blocks.air);
        world.setBlock(i + 13, j + 2, k + 7, Blocks.air);
        world.setBlock(i + 13, j + 2, k + 8, IceikaBlocks.snowBricks);
        world.setBlock(i + 13, j + 3, k + 0, IceikaBlocks.snowBricks);
        world.setBlock(i + 13, j + 3, k + 1, Blocks.air);
        world.setBlock(i + 13, j + 3, k + 2, Blocks.air);
        world.setBlock(i + 13, j + 3, k + 3, Blocks.air);
        world.setBlock(i + 13, j + 3, k + 4, Blocks.air);
        world.setBlock(i + 13, j + 3, k + 5, Blocks.air);
        world.setBlock(i + 13, j + 3, k + 6, Blocks.air);
        world.setBlock(i + 13, j + 3, k + 7, Blocks.air);
        world.setBlock(i + 13, j + 3, k + 8, IceikaBlocks.snowBricks);
        world.setBlock(i + 13, j + 4, k + 1, IceikaBlocks.snowBricks);
        world.setBlock(i + 13, j + 4, k + 2, IceikaBlocks.snowBricks);
        world.setBlock(i + 13, j + 4, k + 3, IceikaBlocks.snowBricks);
        world.setBlock(i + 13, j + 4, k + 4, IceikaBlocks.snowBricks);
        world.setBlock(i + 13, j + 4, k + 5, IceikaBlocks.snowBricks);
        world.setBlock(i + 13, j + 4, k + 6, IceikaBlocks.snowBricks);
        world.setBlock(i + 13, j + 4, k + 7, IceikaBlocks.snowBricks);
        world.setBlock(i + 14, j + 0, k + 0, IceikaBlocks.snowBricks);
        world.setBlock(i + 14, j + 0, k + 1, IceikaBlocks.snowBricks);
        world.setBlock(i + 14, j + 0, k + 2, IceikaBlocks.snowBricks);
        world.setBlock(i + 14, j + 0, k + 3, IceikaBlocks.snowBricks);
        world.setBlock(i + 14, j + 0, k + 4, IceikaBlocks.snowBricks);
        world.setBlock(i + 14, j + 0, k + 5, IceikaBlocks.snowBricks);
        world.setBlock(i + 14, j + 0, k + 6, IceikaBlocks.snowBricks);
        world.setBlock(i + 14, j + 0, k + 7, IceikaBlocks.snowBricks);
        world.setBlock(i + 14, j + 0, k + 8, IceikaBlocks.snowBricks);
        world.setBlock(i + 14, j + 1, k + 0, IceikaBlocks.snowBricks);
        world.setBlock(i + 14, j + 1, k + 1, IceikaBlocks.snowBricks);
        world.setBlock(i + 14, j + 1, k + 2, IceikaBlocks.snowBricks);
        world.setBlock(i + 14, j + 1, k + 3, IceikaBlocks.snowBricks);
        world.setBlock(i + 14, j + 1, k + 4, IceikaBlocks.snowBricks);
        world.setBlock(i + 14, j + 1, k + 5, IceikaBlocks.snowBricks);
        world.setBlock(i + 14, j + 1, k + 6, IceikaBlocks.snowBricks);
        world.setBlock(i + 14, j + 1, k + 7, IceikaBlocks.snowBricks);
        world.setBlock(i + 14, j + 1, k + 8, IceikaBlocks.snowBricks);
        world.setBlock(i + 14, j + 2, k + 0, IceikaBlocks.snowBricks);
        world.setBlock(i + 14, j + 2, k + 1, IceikaBlocks.snowBricks);
        world.setBlock(i + 14, j + 2, k + 2, IceikaBlocks.snowBricks);
        world.setBlock(i + 14, j + 2, k + 3, IceikaBlocks.snowBricks);
        world.setBlock(i + 14, j + 2, k + 4, IceikaBlocks.snowBricks);
        world.setBlock(i + 14, j + 2, k + 5, IceikaBlocks.snowBricks);
        world.setBlock(i + 14, j + 2, k + 6, IceikaBlocks.snowBricks);
        world.setBlock(i + 14, j + 2, k + 7, IceikaBlocks.snowBricks);
        world.setBlock(i + 14, j + 2, k + 8, IceikaBlocks.snowBricks);
        world.setBlock(i + 14, j + 3, k + 0, IceikaBlocks.snowBricks);
        world.setBlock(i + 14, j + 3, k + 1, IceikaBlocks.snowBricks);
        world.setBlock(i + 14, j + 3, k + 2, IceikaBlocks.snowBricks);
        world.setBlock(i + 14, j + 3, k + 4, IceikaBlocks.snowBricks);
        world.setBlock(i + 14, j + 3, k + 5, IceikaBlocks.snowBricks);
        world.setBlock(i + 14, j + 3, k + 6, IceikaBlocks.snowBricks);
        world.setBlock(i + 14, j + 3, k + 7, IceikaBlocks.snowBricks);
        world.setBlock(i + 14, j + 3, k + 8, IceikaBlocks.snowBricks);


        /*TileEntityIceikaChest var16 = (TileEntityIceikaChest)world.getBlockTileEntity(i,j,k);

        if (var16 != null)
        {      
            var16.setInventorySlotContents(rand.nextInt(var16.getSizeInventory()), new ItemStack(IceikaItemHelper.snowFlake.itemID, 1, 1));
        }*/

        this.generate1(world, i, j, k);
        this.generate2(world, i, j, k);
        this.generate3(world, i, j, k);
        this.generate4(world, i, j, k);

        return true;
    }

    public static void generate1(World world, int i, int j, int k)
    {
        world.setBlock(i + 13, j + 1, k + 1, IceikaBlocks.frostedChest);
        world.setBlock(i + 13, j + 1, k + 8, IceikaBlocks.snowBricks);
        world.setBlock(i + 13, j + 2, k + 0, IceikaBlocks.snowBricks);
        world.setBlock(i + 13, j + 2, k + 8, IceikaBlocks.snowBricks);
        world.setBlock(i + 13, j + 3, k + 0, IceikaBlocks.snowBricks);
        world.setBlock(i + 13, j + 3, k + 8, IceikaBlocks.snowBricks);
        world.setBlock(i + 13, j + 4, k + 1, IceikaBlocks.snowBricks);
        world.setBlock(i + 13, j + 4, k + 2, IceikaBlocks.snowBricks);
        world.setBlock(i + 13, j + 4, k + 3, IceikaBlocks.snowBricks);
        world.setBlock(i + 13, j + 4, k + 4, IceikaBlocks.snowBricks);
        world.setBlock(i + 13, j + 4, k + 5, IceikaBlocks.snowBricks);
        world.setBlock(i + 13, j + 4, k + 6, IceikaBlocks.snowBricks);
        world.setBlock(i + 13, j + 4, k + 7, IceikaBlocks.snowBricks);
        world.setBlock(i + 14, j + 0, k + 0, IceikaBlocks.snowBricks);
        world.setBlock(i + 14, j + 0, k + 1, IceikaBlocks.snowBricks);
        world.setBlock(i + 14, j + 0, k + 2, IceikaBlocks.snowBricks);
        world.setBlock(i + 14, j + 0, k + 3, IceikaBlocks.snowBricks);
        world.setBlock(i + 14, j + 0, k + 4, IceikaBlocks.snowBricks);
        world.setBlock(i + 14, j + 0, k + 5, IceikaBlocks.snowBricks);
        world.setBlock(i + 14, j + 0, k + 6, IceikaBlocks.snowBricks);
        world.setBlock(i + 14, j + 0, k + 7, IceikaBlocks.snowBricks);
        world.setBlock(i + 14, j + 0, k + 8, IceikaBlocks.snowBricks);
        world.setBlock(i + 14, j + 1, k + 0, IceikaBlocks.snowBricks);
        world.setBlock(i + 14, j + 1, k + 1, IceikaBlocks.snowBricks);
        world.setBlock(i + 14, j + 1, k + 2, IceikaBlocks.snowBricks);
        world.setBlock(i + 14, j + 1, k + 3, IceikaBlocks.snowBricks);
        world.setBlock(i + 14, j + 1, k + 4, IceikaBlocks.snowBricks);
        world.setBlock(i + 14, j + 1, k + 5, IceikaBlocks.snowBricks);
        world.setBlock(i + 14, j + 1, k + 6, IceikaBlocks.snowBricks);
        world.setBlock(i + 14, j + 1, k + 7, IceikaBlocks.snowBricks);
        world.setBlock(i + 14, j + 1, k + 8, IceikaBlocks.snowBricks);
        world.setBlock(i + 14, j + 2, k + 0, IceikaBlocks.snowBricks);
        world.setBlock(i + 14, j + 2, k + 1, IceikaBlocks.snowBricks);
        world.setBlock(i + 14, j + 2, k + 2, IceikaBlocks.snowBricks);
        world.setBlock(i + 14, j + 2, k + 3, IceikaBlocks.snowBricks);
        world.setBlock(i + 14, j + 2, k + 4, IceikaBlocks.snowBricks);
        world.setBlock(i + 14, j + 2, k + 5, IceikaBlocks.snowBricks);
        world.setBlock(i + 14, j + 2, k + 6, IceikaBlocks.snowBricks);
        world.setBlock(i + 14, j + 2, k + 7, IceikaBlocks.snowBricks);
        world.setBlock(i + 14, j + 2, k + 8, IceikaBlocks.snowBricks);
        world.setBlock(i + 14, j + 3, k + 0, IceikaBlocks.snowBricks);
        world.setBlock(i + 14, j + 3, k + 1, IceikaBlocks.snowBricks);
        world.setBlock(i + 14, j + 3, k + 2, IceikaBlocks.snowBricks);
        world.setBlock(i + 14, j + 3, k + 3, IceikaBlocks.snowBricks);
        world.setBlock(i + 14, j + 3, k + 4, IceikaBlocks.snowBricks);
        world.setBlock(i + 14, j + 3, k + 5, IceikaBlocks.snowBricks);
        world.setBlock(i + 14, j + 3, k + 6, IceikaBlocks.snowBricks);
        world.setBlock(i + 14, j + 3, k + 7, IceikaBlocks.snowBricks);
        world.setBlock(i + 14, j + 3, k + 8, IceikaBlocks.snowBricks);

    }

    public static void generate2(World world, int i, int j, int k)
    {
        world.setBlock(i + 9, j + 0, k + 5, IceikaBlocks.icyStone);
        world.setBlock(i + 9, j + 0, k + 6, IceikaBlocks.icyStone);
        world.setBlock(i + 9, j + 0, k + 7, IceikaBlocks.icyStone);
        world.setBlock(i + 9, j + 0, k + 8, IceikaBlocks.snowBricks);
        world.setBlock(i + 9, j + 0, k + 9, IceikaBlocks.snowBricks);
        world.setBlock(i + 9, j + 0, k + 10, IceikaBlocks.snowBricks);
        world.setBlock(i + 9, j + 0, k + 11, IceikaBlocks.snowBricks);
        world.setBlock(i + 9, j + 0, k + 12, IceikaBlocks.snowBricks);
        world.setBlock(i + 9, j + 0, k + 13, IceikaBlocks.snowBricks);
        world.setBlock(i + 9, j + 0, k + 14, IceikaBlocks.icyStone);
        world.setBlock(i + 9, j + 0, k + 15, IceikaBlocks.icyStone);
        world.setBlock(i + 9, j + 0, k + 16, IceikaBlocks.snowBricks);
        world.setBlock(i + 9, j + 1, k + 0, IceikaBlocks.snowBricks);
        world.setBlock(i + 9, j + 1, k + 4, IceikaBlocks.glacideSpawner);
        world.setBlock(i + 9, j + 1, k + 8, IceikaBlocks.snowBricks);
        world.setBlock(i + 9, j + 1, k + 9, IceikaBlocks.snowBricks);
        world.setBlock(i + 9, j + 1, k + 10, IceikaBlocks.snowBricks);
        world.setBlock(i + 9, j + 1, k + 11, IceikaBlocks.snowBricks);
        world.setBlock(i + 9, j + 1, k + 12, IceikaBlocks.snowBricks);
        world.setBlock(i + 9, j + 1, k + 13, IceikaBlocks.snowBricks);
        world.setBlock(i + 9, j + 1, k + 16, IceikaBlocks.snowBricks);
        world.setBlock(i + 9, j + 2, k + 0, IceikaBlocks.snowBricks);
        world.setBlock(i + 9, j + 2, k + 8, IceikaBlocks.snowBricks);
        world.setBlock(i + 9, j + 2, k + 9, IceikaBlocks.snowBricks);
        world.setBlock(i + 9, j + 2, k + 10, IceikaBlocks.snowBricks);
        world.setBlock(i + 9, j + 2, k + 11, IceikaBlocks.snowBricks);
        world.setBlock(i + 9, j + 2, k + 12, IceikaBlocks.snowBricks);
        world.setBlock(i + 9, j + 2, k + 13, IceikaBlocks.snowBricks);
        world.setBlock(i + 9, j + 2, k + 16, IceikaBlocks.snowBricks);
        world.setBlock(i + 9, j + 3, k + 0, IceikaBlocks.snowBricks);
        world.setBlock(i + 9, j + 3, k + 8, IceikaBlocks.snowBricks);
        world.setBlock(i + 9, j + 3, k + 9, IceikaBlocks.snowBricks);
        world.setBlock(i + 9, j + 3, k + 10, IceikaBlocks.snowBricks);
        world.setBlock(i + 9, j + 3, k + 11, IceikaBlocks.snowBricks);
        world.setBlock(i + 9, j + 3, k + 12, IceikaBlocks.snowBricks);
        world.setBlock(i + 9, j + 3, k + 13, IceikaBlocks.snowBricks);
        world.setBlock(i + 9, j + 3, k + 16, IceikaBlocks.snowBricks);
        world.setBlock(i + 9, j + 4, k + 1, IceikaBlocks.snowBricks);
        world.setBlock(i + 9, j + 4, k + 2, IceikaBlocks.snowBricks);
        world.setBlock(i + 9, j + 4, k + 3, IceikaBlocks.snowBricks);
        world.setBlock(i + 9, j + 4, k + 4, IceikaBlocks.snowBricks);
        world.setBlock(i + 9, j + 4, k + 5, IceikaBlocks.snowBricks);
        world.setBlock(i + 9, j + 4, k + 6, IceikaBlocks.snowBricks);
        world.setBlock(i + 9, j + 4, k + 7, IceikaBlocks.snowBricks);
        world.setBlock(i + 9, j + 4, k + 14, IceikaBlocks.snowBricks);
        world.setBlock(i + 9, j + 4, k + 15, IceikaBlocks.snowBricks);
        world.setBlock(i + 10, j + 0, k + 0, IceikaBlocks.snowBricks);
        world.setBlock(i + 10, j + 0, k + 1, IceikaBlocks.icyStone);
        world.setBlock(i + 10, j + 0, k + 2, IceikaBlocks.icyStone);
        world.setBlock(i + 10, j + 0, k + 3, IceikaBlocks.icyStone);
        world.setBlock(i + 10, j + 0, k + 4, IceikaBlocks.icyStone);
        world.setBlock(i + 10, j + 0, k + 5, IceikaBlocks.icyStone);
        world.setBlock(i + 10, j + 0, k + 6, IceikaBlocks.icyStone);
        world.setBlock(i + 10, j + 0, k + 7, IceikaBlocks.icyStone);
        world.setBlock(i + 10, j + 0, k + 8, IceikaBlocks.icyStone);
        world.setBlock(i + 10, j + 0, k + 9, IceikaBlocks.icyStone);
        world.setBlock(i + 10, j + 0, k + 10, IceikaBlocks.icyStone);
        world.setBlock(i + 10, j + 0, k + 11, IceikaBlocks.icyStone);
        world.setBlock(i + 10, j + 0, k + 12, IceikaBlocks.icyStone);
        world.setBlock(i + 10, j + 0, k + 13, IceikaBlocks.icyStone);
        world.setBlock(i + 10, j + 0, k + 14, IceikaBlocks.icyStone);
        world.setBlock(i + 10, j + 0, k + 15, IceikaBlocks.icyStone);
        world.setBlock(i + 10, j + 0, k + 16, IceikaBlocks.snowBricks);
        world.setBlock(i + 10, j + 1, k + 0, IceikaBlocks.snowBricks);
        world.setBlock(i + 10, j + 1, k + 16, IceikaBlocks.snowBricks);
        world.setBlock(i + 10, j + 2, k + 0, IceikaBlocks.snowBricks);
        world.setBlock(i + 10, j + 2, k + 16, IceikaBlocks.snowBricks);
        world.setBlock(i + 10, j + 3, k + 0, IceikaBlocks.snowBricks);
        world.setBlock(i + 10, j + 3, k + 16, IceikaBlocks.snowBricks);
        world.setBlock(i + 10, j + 4, k + 1, IceikaBlocks.snowBricks);
        world.setBlock(i + 10, j + 4, k + 2, IceikaBlocks.snowBricks);
        world.setBlock(i + 10, j + 4, k + 3, IceikaBlocks.snowBricks);
        world.setBlock(i + 10, j + 4, k + 4, IceikaBlocks.snowBricks);
        world.setBlock(i + 10, j + 4, k + 5, IceikaBlocks.snowBricks);
        world.setBlock(i + 10, j + 4, k + 6, IceikaBlocks.snowBricks);
        world.setBlock(i + 10, j + 4, k + 7, IceikaBlocks.snowBricks);
        world.setBlock(i + 10, j + 4, k + 8, IceikaBlocks.snowBricks);
        world.setBlock(i + 10, j + 4, k + 9, IceikaBlocks.snowBricks);
        world.setBlock(i + 10, j + 4, k + 10, IceikaBlocks.snowBricks);
        world.setBlock(i + 10, j + 4, k + 11, IceikaBlocks.snowBricks);
        world.setBlock(i + 10, j + 4, k + 12, IceikaBlocks.snowBricks);
        world.setBlock(i + 10, j + 4, k + 13, IceikaBlocks.snowBricks);
        world.setBlock(i + 10, j + 4, k + 14, IceikaBlocks.snowBricks);
        world.setBlock(i + 10, j + 4, k + 15, IceikaBlocks.snowBricks);
        world.setBlock(i + 11, j + 0, k + 0, IceikaBlocks.snowBricks);
        world.setBlock(i + 11, j + 0, k + 1, IceikaBlocks.icyStone);
        world.setBlock(i + 11, j + 0, k + 2, IceikaBlocks.icyStone);
        world.setBlock(i + 11, j + 0, k + 3, IceikaBlocks.icyStone);
        world.setBlock(i + 11, j + 0, k + 4, IceikaBlocks.icyStone);
        world.setBlock(i + 11, j + 0, k + 5, IceikaBlocks.icyStone);
        world.setBlock(i + 11, j + 0, k + 6, IceikaBlocks.icyStone);
        world.setBlock(i + 11, j + 0, k + 7, IceikaBlocks.icyStone);
        world.setBlock(i + 11, j + 0, k + 8, IceikaBlocks.icyStone);
        world.setBlock(i + 11, j + 0, k + 9, IceikaBlocks.icyStone);
        world.setBlock(i + 11, j + 0, k + 10, IceikaBlocks.icyStone);
        world.setBlock(i + 11, j + 0, k + 11, IceikaBlocks.icyStone);
        world.setBlock(i + 11, j + 0, k + 12, IceikaBlocks.icyStone);
        world.setBlock(i + 11, j + 0, k + 13, IceikaBlocks.icyStone);
        world.setBlock(i + 11, j + 0, k + 14, IceikaBlocks.icyStone);
        world.setBlock(i + 11, j + 0, k + 15, IceikaBlocks.icyStone);
        world.setBlock(i + 11, j + 0, k + 16, IceikaBlocks.snowBricks);
        world.setBlock(i + 11, j + 1, k + 0, IceikaBlocks.snowBricks);
        world.setBlock(i + 11, j + 1, k + 16, IceikaBlocks.snowBricks);
        world.setBlock(i + 11, j + 2, k + 0, IceikaBlocks.snowBricks);
        world.setBlock(i + 11, j + 2, k + 16, IceikaBlocks.snowBricks);
        world.setBlock(i + 11, j + 3, k + 0, IceikaBlocks.snowBricks);
        world.setBlock(i + 11, j + 3, k + 16, IceikaBlocks.snowBricks);
        world.setBlock(i + 11, j + 4, k + 1, IceikaBlocks.snowBricks);
        world.setBlock(i + 11, j + 4, k + 2, IceikaBlocks.snowBricks);
        world.setBlock(i + 11, j + 4, k + 3, IceikaBlocks.snowBricks);
        world.setBlock(i + 11, j + 4, k + 4, IceikaBlocks.snowBricks);
        world.setBlock(i + 11, j + 4, k + 5, IceikaBlocks.snowBricks);
        world.setBlock(i + 11, j + 4, k + 6, IceikaBlocks.snowBricks);
        world.setBlock(i + 11, j + 4, k + 7, IceikaBlocks.snowBricks);
        world.setBlock(i + 11, j + 4, k + 8, IceikaBlocks.snowBricks);
        world.setBlock(i + 11, j + 4, k + 9, IceikaBlocks.snowBricks);
        world.setBlock(i + 11, j + 4, k + 10, IceikaBlocks.snowBricks);
        world.setBlock(i + 11, j + 4, k + 11, IceikaBlocks.snowBricks);
        world.setBlock(i + 11, j + 4, k + 12, IceikaBlocks.snowBricks);
        world.setBlock(i + 11, j + 4, k + 13, IceikaBlocks.snowBricks);
        world.setBlock(i + 11, j + 4, k + 14, IceikaBlocks.snowBricks);
        world.setBlock(i + 11, j + 4, k + 15, IceikaBlocks.snowBricks);
        world.setBlock(i + 12, j + 0, k + 0, IceikaBlocks.snowBricks);
        world.setBlock(i + 12, j + 0, k + 1, IceikaBlocks.icyStone);
        world.setBlock(i + 12, j + 0, k + 2, IceikaBlocks.icyStone);
        world.setBlock(i + 12, j + 0, k + 3, IceikaBlocks.icyStone);
        world.setBlock(i + 12, j + 0, k + 4, IceikaBlocks.icyStone);
        world.setBlock(i + 12, j + 0, k + 5, IceikaBlocks.icyStone);
        world.setBlock(i + 12, j + 0, k + 6, IceikaBlocks.icyStone);
        world.setBlock(i + 12, j + 0, k + 7, IceikaBlocks.icyStone);
        world.setBlock(i + 12, j + 0, k + 8, IceikaBlocks.snowBricks);
        world.setBlock(i + 12, j + 0, k + 9, IceikaBlocks.snowBricks);
        world.setBlock(i + 12, j + 0, k + 10, IceikaBlocks.snowBricks);
        world.setBlock(i + 12, j + 0, k + 11, IceikaBlocks.snowBricks);
        world.setBlock(i + 12, j + 0, k + 12, IceikaBlocks.snowBricks);
        world.setBlock(i + 12, j + 0, k + 13, IceikaBlocks.snowBricks);
        world.setBlock(i + 12, j + 0, k + 14, IceikaBlocks.snowBricks);
        world.setBlock(i + 12, j + 0, k + 15, IceikaBlocks.snowBricks);
        world.setBlock(i + 12, j + 0, k + 16, IceikaBlocks.snowBricks);
        world.setBlock(i + 12, j + 1, k + 0, IceikaBlocks.snowBricks);
        world.setBlock(i + 12, j + 1, k + 4, IceikaBlocks.glacideSpawner);
        world.setBlock(i + 12, j + 1, k + 8, IceikaBlocks.snowBricks);
        world.setBlock(i + 12, j + 1, k + 9, IceikaBlocks.snowBricks);
        world.setBlock(i + 12, j + 1, k + 10, IceikaBlocks.snowBricks);
        world.setBlock(i + 12, j + 1, k + 11, IceikaBlocks.snowBricks);
        world.setBlock(i + 12, j + 1, k + 12, IceikaBlocks.snowBricks);
        world.setBlock(i + 12, j + 1, k + 13, IceikaBlocks.snowBricks);
        world.setBlock(i + 12, j + 1, k + 14, IceikaBlocks.snowBricks);
        world.setBlock(i + 12, j + 1, k + 15, IceikaBlocks.snowBricks);
        world.setBlock(i + 12, j + 1, k + 16, IceikaBlocks.snowBricks);
        world.setBlock(i + 12, j + 2, k + 0, IceikaBlocks.snowBricks);
        world.setBlock(i + 12, j + 2, k + 8, IceikaBlocks.snowBricks);
        world.setBlock(i + 12, j + 2, k + 9, IceikaBlocks.snowBricks);
        world.setBlock(i + 12, j + 2, k + 10, IceikaBlocks.snowBricks);
        world.setBlock(i + 12, j + 2, k + 11, IceikaBlocks.snowBricks);
        world.setBlock(i + 12, j + 2, k + 12, IceikaBlocks.snowBricks);
        world.setBlock(i + 12, j + 2, k + 13, IceikaBlocks.snowBricks);
        world.setBlock(i + 12, j + 2, k + 14, IceikaBlocks.snowBricks);
        world.setBlock(i + 12, j + 2, k + 15, IceikaBlocks.snowBricks);
        world.setBlock(i + 12, j + 2, k + 16, IceikaBlocks.snowBricks);
        world.setBlock(i + 12, j + 3, k + 0, IceikaBlocks.snowBricks);
        world.setBlock(i + 12, j + 3, k + 8, IceikaBlocks.snowBricks);
        world.setBlock(i + 12, j + 3, k + 9, IceikaBlocks.snowBricks);
        world.setBlock(i + 12, j + 3, k + 10, IceikaBlocks.snowBricks);
        world.setBlock(i + 12, j + 3, k + 11, IceikaBlocks.snowBricks);
        world.setBlock(i + 12, j + 3, k + 12, IceikaBlocks.snowBricks);
        world.setBlock(i + 12, j + 3, k + 13, IceikaBlocks.snowBricks);
        world.setBlock(i + 12, j + 3, k + 14, IceikaBlocks.snowBricks);
        world.setBlock(i + 12, j + 3, k + 15, IceikaBlocks.snowBricks);
        world.setBlock(i + 12, j + 3, k + 16, IceikaBlocks.snowBricks);
        world.setBlock(i + 12, j + 4, k + 1, IceikaBlocks.snowBricks);
        world.setBlock(i + 12, j + 4, k + 2, IceikaBlocks.snowBricks);
        world.setBlock(i + 12, j + 4, k + 3, IceikaBlocks.snowBricks);
        world.setBlock(i + 12, j + 4, k + 4, IceikaBlocks.snowBricks);
        world.setBlock(i + 12, j + 4, k + 5, IceikaBlocks.snowBricks);
        world.setBlock(i + 12, j + 4, k + 6, IceikaBlocks.snowBricks);
        world.setBlock(i + 12, j + 4, k + 7, IceikaBlocks.snowBricks);
        world.setBlock(i + 13, j + 0, k + 0, IceikaBlocks.snowBricks);
        world.setBlock(i + 13, j + 0, k + 1, IceikaBlocks.icyStone);
        world.setBlock(i + 13, j + 0, k + 2, IceikaBlocks.icyStone);
        world.setBlock(i + 13, j + 0, k + 3, IceikaBlocks.icyStone);
        world.setBlock(i + 13, j + 0, k + 4, IceikaBlocks.icyStone);
        world.setBlock(i + 13, j + 0, k + 5, IceikaBlocks.icyStone);
        world.setBlock(i + 13, j + 0, k + 6, IceikaBlocks.icyStone);
        world.setBlock(i + 13, j + 0, k + 7, IceikaBlocks.icyStone);
        world.setBlock(i + 13, j + 0, k + 8, IceikaBlocks.snowBricks);
        world.setBlock(i + 13, j + 1, k + 0, IceikaBlocks.snowBricks);
    }

    public static void generate3(World world, int i, int j, int k)
    {
        world.setBlock(i + 3, j + 4, k + 12, IceikaBlocks.snowBricks);
        world.setBlock(i + 3, j + 4, k + 13, IceikaBlocks.snowBricks);
        world.setBlock(i + 3, j + 4, k + 14, IceikaBlocks.snowBricks);
        world.setBlock(i + 3, j + 4, k + 15, IceikaBlocks.snowBricks);
        world.setBlock(i + 3, j + 4, k + 16, IceikaBlocks.snowBricks);
        world.setBlock(i + 3, j + 4, k + 17, IceikaBlocks.snowBricks);
        world.setBlock(i + 3, j + 4, k + 20, IceikaBlocks.snowBricks);
        world.setBlock(i + 3, j + 4, k + 21, IceikaBlocks.snowBricks);
        world.setBlock(i + 4, j + 0, k + 11, IceikaBlocks.snowBricks);
        world.setBlock(i + 4, j + 0, k + 12, IceikaBlocks.icyStone);
        world.setBlock(i + 4, j + 0, k + 13, IceikaBlocks.icyStone);
        world.setBlock(i + 4, j + 0, k + 14, IceikaBlocks.icyStone);
        world.setBlock(i + 4, j + 0, k + 15, IceikaBlocks.icyStone);
        world.setBlock(i + 4, j + 0, k + 16, IceikaBlocks.icyStone);
        world.setBlock(i + 4, j + 0, k + 17, IceikaBlocks.icyStone);
        world.setBlock(i + 4, j + 0, k + 18, IceikaBlocks.snowBricks);
        world.setBlock(i + 4, j + 0, k + 19, IceikaBlocks.snowBricks);
        world.setBlock(i + 4, j + 0, k + 20, IceikaBlocks.icyStone);
        world.setBlock(i + 4, j + 0, k + 21, IceikaBlocks.icyStone);
        world.setBlock(i + 4, j + 0, k + 22, IceikaBlocks.snowBricks);
        world.setBlock(i + 4, j + 0, k + 23, IceikaBlocks.snowBricks);
        world.setBlock(i + 4, j + 0, k + 24, IceikaBlocks.snowBricks);
        world.setBlock(i + 4, j + 0, k + 25, IceikaBlocks.snowBricks);
        world.setBlock(i + 4, j + 1, k + 11, IceikaBlocks.snowBricks);
        world.setBlock(i + 4, j + 1, k + 14, IceikaBlocks.glacideSpawner);
        world.setBlock(i + 4, j + 1, k + 18, IceikaBlocks.snowBricks);
        world.setBlock(i + 4, j + 1, k + 19, IceikaBlocks.snowBricks);
        world.setBlock(i + 4, j + 1, k + 22, IceikaBlocks.snowBricks);
        world.setBlock(i + 4, j + 1, k + 23, IceikaBlocks.snowBricks);
        world.setBlock(i + 4, j + 1, k + 24, IceikaBlocks.snowBricks);
        world.setBlock(i + 4, j + 1, k + 25, IceikaBlocks.snowBricks);
        world.setBlock(i + 4, j + 2, k + 11, IceikaBlocks.snowBricks);
        world.setBlock(i + 4, j + 2, k + 18, IceikaBlocks.snowBricks);
        world.setBlock(i + 4, j + 2, k + 19, IceikaBlocks.snowBricks);
        world.setBlock(i + 4, j + 2, k + 22, IceikaBlocks.snowBricks);
        world.setBlock(i + 4, j + 2, k + 23, IceikaBlocks.snowBricks);
        world.setBlock(i + 4, j + 2, k + 24, IceikaBlocks.snowBricks);
        world.setBlock(i + 4, j + 2, k + 25, IceikaBlocks.snowBricks);
        world.setBlock(i + 4, j + 3, k + 11, IceikaBlocks.snowBricks);
        world.setBlock(i + 4, j + 3, k + 18, IceikaBlocks.snowBricks);
        world.setBlock(i + 4, j + 3, k + 19, IceikaBlocks.snowBricks);
        world.setBlock(i + 4, j + 3, k + 22, IceikaBlocks.snowBricks);
        world.setBlock(i + 4, j + 3, k + 23, IceikaBlocks.snowBricks);
        world.setBlock(i + 4, j + 3, k + 24, IceikaBlocks.snowBricks);
        world.setBlock(i + 4, j + 3, k + 25, IceikaBlocks.snowBricks);
        world.setBlock(i + 4, j + 4, k + 12, IceikaBlocks.snowBricks);
        world.setBlock(i + 4, j + 4, k + 13, IceikaBlocks.snowBricks);
        world.setBlock(i + 4, j + 4, k + 14, IceikaBlocks.snowBricks);
        world.setBlock(i + 4, j + 4, k + 15, IceikaBlocks.snowBricks);
        world.setBlock(i + 4, j + 4, k + 16, IceikaBlocks.snowBricks);
        world.setBlock(i + 4, j + 4, k + 17, IceikaBlocks.snowBricks);
        world.setBlock(i + 4, j + 4, k + 20, IceikaBlocks.snowBricks);
        world.setBlock(i + 4, j + 4, k + 21, IceikaBlocks.snowBricks);
        world.setBlock(i + 5, j + 0, k + 11, IceikaBlocks.snowBricks);
        world.setBlock(i + 5, j + 0, k + 12, IceikaBlocks.icyStone);
        world.setBlock(i + 5, j + 0, k + 13, IceikaBlocks.icyStone);
        world.setBlock(i + 5, j + 0, k + 14, IceikaBlocks.icyStone);
        world.setBlock(i + 5, j + 0, k + 15, IceikaBlocks.icyStone);
        world.setBlock(i + 5, j + 0, k + 16, IceikaBlocks.icyStone);
        world.setBlock(i + 5, j + 0, k + 17, IceikaBlocks.icyStone);
        world.setBlock(i + 5, j + 0, k + 18, IceikaBlocks.snowBricks);
        world.setBlock(i + 5, j + 0, k + 19, IceikaBlocks.snowBricks);
        world.setBlock(i + 5, j + 0, k + 20, IceikaBlocks.icyStone);
        world.setBlock(i + 5, j + 0, k + 21, IceikaBlocks.icyStone);
        world.setBlock(i + 5, j + 0, k + 22, IceikaBlocks.icyStone);
        world.setBlock(i + 5, j + 0, k + 23, IceikaBlocks.icyStone);
        world.setBlock(i + 5, j + 0, k + 24, IceikaBlocks.icyStone);
        world.setBlock(i + 5, j + 0, k + 25, IceikaBlocks.icyStone);
        world.setBlock(i + 5, j + 1, k + 11, IceikaBlocks.snowBricks);
        world.setBlock(i + 5, j + 1, k + 18, IceikaBlocks.snowBricks);
        world.setBlock(i + 5, j + 1, k + 19, IceikaBlocks.snowBricks);
        world.setBlock(i + 5, j + 2, k + 11, IceikaBlocks.snowBricks);
        world.setBlock(i + 5, j + 2, k + 18, IceikaBlocks.snowBricks);
        world.setBlock(i + 5, j + 2, k + 19, IceikaBlocks.snowBricks);
        world.setBlock(i + 5, j + 3, k + 11, IceikaBlocks.snowBricks);
        world.setBlock(i + 5, j + 3, k + 18, IceikaBlocks.snowBricks);
        world.setBlock(i + 5, j + 3, k + 19, IceikaBlocks.snowBricks);
        world.setBlock(i + 5, j + 4, k + 12, IceikaBlocks.snowBricks);
        world.setBlock(i + 5, j + 4, k + 13, IceikaBlocks.snowBricks);
        world.setBlock(i + 5, j + 4, k + 14, IceikaBlocks.snowBricks);
        world.setBlock(i + 5, j + 4, k + 15, IceikaBlocks.snowBricks);
        world.setBlock(i + 5, j + 4, k + 16, IceikaBlocks.snowBricks);
        world.setBlock(i + 5, j + 4, k + 17, IceikaBlocks.snowBricks);
        world.setBlock(i + 5, j + 4, k + 20, IceikaBlocks.snowBricks);
        world.setBlock(i + 5, j + 4, k + 21, IceikaBlocks.snowBricks);
        world.setBlock(i + 5, j + 4, k + 22, IceikaBlocks.snowBricks);
        world.setBlock(i + 5, j + 4, k + 23, IceikaBlocks.snowBricks);
        world.setBlock(i + 5, j + 4, k + 24, IceikaBlocks.snowBricks);
        world.setBlock(i + 5, j + 4, k + 25, IceikaBlocks.snowBricks);
        world.setBlock(i + 6, j + 0, k + 11, IceikaBlocks.snowBricks);
        world.setBlock(i + 6, j + 0, k + 12, IceikaBlocks.icyStone);
        world.setBlock(i + 6, j + 0, k + 13, IceikaBlocks.icyStone);
        world.setBlock(i + 6, j + 0, k + 14, IceikaBlocks.icyStone);
        world.setBlock(i + 6, j + 0, k + 15, IceikaBlocks.icyStone);
        world.setBlock(i + 6, j + 0, k + 16, IceikaBlocks.icyStone);
        world.setBlock(i + 6, j + 0, k + 17, IceikaBlocks.icyStone);
        world.setBlock(i + 6, j + 0, k + 18, IceikaBlocks.snowBricks);
        world.setBlock(i + 6, j + 0, k + 19, IceikaBlocks.snowBricks);
        world.setBlock(i + 6, j + 0, k + 20, IceikaBlocks.icyStone);
        world.setBlock(i + 6, j + 0, k + 21, IceikaBlocks.icyStone);
        world.setBlock(i + 6, j + 0, k + 22, IceikaBlocks.icyStone);
        world.setBlock(i + 6, j + 0, k + 23, IceikaBlocks.icyStone);
        world.setBlock(i + 6, j + 0, k + 24, IceikaBlocks.icyStone);
        world.setBlock(i + 6, j + 0, k + 25, IceikaBlocks.icyStone);
        world.setBlock(i + 6, j + 1, k + 11, IceikaBlocks.snowBricks);
        world.setBlock(i + 6, j + 1, k + 18, IceikaBlocks.snowBricks);
        world.setBlock(i + 6, j + 1, k + 19, IceikaBlocks.snowBricks);
        world.setBlock(i + 6, j + 2, k + 11, IceikaBlocks.snowBricks);
        world.setBlock(i + 6, j + 2, k + 18, IceikaBlocks.snowBricks);
        world.setBlock(i + 6, j + 2, k + 19, IceikaBlocks.snowBricks);
        world.setBlock(i + 6, j + 3, k + 11, IceikaBlocks.snowBricks);
        world.setBlock(i + 6, j + 3, k + 18, IceikaBlocks.snowBricks);
        world.setBlock(i + 6, j + 3, k + 19, IceikaBlocks.snowBricks);
        world.setBlock(i + 6, j + 4, k + 12, IceikaBlocks.snowBricks);
        world.setBlock(i + 6, j + 4, k + 13, IceikaBlocks.snowBricks);
        world.setBlock(i + 6, j + 4, k + 14, IceikaBlocks.snowBricks);
        world.setBlock(i + 6, j + 4, k + 15, IceikaBlocks.snowBricks);
        world.setBlock(i + 6, j + 4, k + 16, IceikaBlocks.snowBricks);
        world.setBlock(i + 6, j + 4, k + 17, IceikaBlocks.snowBricks);
        world.setBlock(i + 6, j + 4, k + 20, IceikaBlocks.snowBricks);
        world.setBlock(i + 6, j + 4, k + 21, IceikaBlocks.snowBricks);
        world.setBlock(i + 6, j + 4, k + 22, IceikaBlocks.snowBricks);
        world.setBlock(i + 6, j + 4, k + 23, IceikaBlocks.snowBricks);
        world.setBlock(i + 6, j + 4, k + 24, IceikaBlocks.snowBricks);
        world.setBlock(i + 6, j + 4, k + 25, IceikaBlocks.snowBricks);
        world.setBlock(i + 7, j + 0, k + 0, IceikaBlocks.snowBricks);
        world.setBlock(i + 7, j + 0, k + 1, IceikaBlocks.snowBricks);
        world.setBlock(i + 7, j + 0, k + 2, IceikaBlocks.snowBricks);
        world.setBlock(i + 7, j + 0, k + 3, IceikaBlocks.snowBricks);
        world.setBlock(i + 7, j + 0, k + 4, IceikaBlocks.snowBricks);
        world.setBlock(i + 7, j + 0, k + 5, IceikaBlocks.snowBricks);
        world.setBlock(i + 7, j + 0, k + 6, IceikaBlocks.snowBricks);
        world.setBlock(i + 7, j + 0, k + 7, IceikaBlocks.snowBricks);
        world.setBlock(i + 7, j + 0, k + 8, IceikaBlocks.snowBricks);
        world.setBlock(i + 7, j + 0, k + 11, IceikaBlocks.snowBricks);
        world.setBlock(i + 7, j + 0, k + 12, IceikaBlocks.snowBricks);
        world.setBlock(i + 7, j + 0, k + 13, IceikaBlocks.snowBricks);
        world.setBlock(i + 7, j + 0, k + 14, IceikaBlocks.icyStone);
        world.setBlock(i + 7, j + 0, k + 15, IceikaBlocks.icyStone);
        world.setBlock(i + 7, j + 0, k + 16, IceikaBlocks.snowBricks);
        world.setBlock(i + 7, j + 0, k + 17, IceikaBlocks.snowBricks);
        world.setBlock(i + 7, j + 0, k + 18, IceikaBlocks.snowBricks);
        world.setBlock(i + 7, j + 0, k + 19, IceikaBlocks.snowBricks);
        world.setBlock(i + 7, j + 0, k + 20, IceikaBlocks.snowBricks);
        world.setBlock(i + 7, j + 0, k + 21, IceikaBlocks.snowBricks);
        world.setBlock(i + 7, j + 0, k + 22, IceikaBlocks.snowBricks);
        world.setBlock(i + 7, j + 0, k + 23, IceikaBlocks.snowBricks);
        world.setBlock(i + 7, j + 0, k + 24, IceikaBlocks.snowBricks);
        world.setBlock(i + 7, j + 0, k + 25, IceikaBlocks.snowBricks);
        world.setBlock(i + 7, j + 1, k + 0, IceikaBlocks.snowBricks);
        world.setBlock(i + 7, j + 1, k + 1, IceikaBlocks.snowBricks);
        world.setBlock(i + 7, j + 1, k + 2, IceikaBlocks.snowBricks);
        world.setBlock(i + 7, j + 1, k + 3, IceikaBlocks.snowBricks);
        world.setBlock(i + 7, j + 1, k + 4, IceikaBlocks.snowBricks);
        world.setBlock(i + 7, j + 1, k + 5, IceikaBlocks.snowBricks);
        world.setBlock(i + 7, j + 1, k + 6, IceikaBlocks.snowBricks);
        world.setBlock(i + 7, j + 1, k + 7, IceikaBlocks.snowBricks);
        world.setBlock(i + 7, j + 1, k + 8, IceikaBlocks.snowBricks);
        world.setBlock(i + 7, j + 1, k + 11, IceikaBlocks.snowBricks);
        world.setBlock(i + 7, j + 1, k + 12, IceikaBlocks.snowBricks);
        world.setBlock(i + 7, j + 1, k + 13, IceikaBlocks.snowBricks);
        world.setBlock(i + 7, j + 1, k + 16, IceikaBlocks.snowBricks);
        world.setBlock(i + 7, j + 1, k + 17, IceikaBlocks.snowBricks);
        world.setBlock(i + 7, j + 1, k + 18, IceikaBlocks.snowBricks);
        world.setBlock(i + 7, j + 1, k + 19, IceikaBlocks.snowBricks);
        world.setBlock(i + 7, j + 1, k + 20, IceikaBlocks.snowBricks);
        world.setBlock(i + 7, j + 1, k + 21, IceikaBlocks.snowBricks);
        world.setBlock(i + 7, j + 1, k + 22, IceikaBlocks.snowBricks);
        world.setBlock(i + 7, j + 1, k + 23, IceikaBlocks.snowBricks);
        world.setBlock(i + 7, j + 1, k + 24, IceikaBlocks.snowBricks);
        world.setBlock(i + 7, j + 1, k + 25, IceikaBlocks.snowBricks);
        world.setBlock(i + 7, j + 2, k + 0, IceikaBlocks.snowBricks);
        world.setBlock(i + 7, j + 2, k + 1, IceikaBlocks.snowBricks);
        world.setBlock(i + 7, j + 2, k + 2, IceikaBlocks.snowBricks);
        world.setBlock(i + 7, j + 2, k + 3, IceikaBlocks.snowBricks);
        world.setBlock(i + 7, j + 2, k + 4, IceikaBlocks.snowBricks);
        world.setBlock(i + 7, j + 2, k + 5, IceikaBlocks.snowBricks);
        world.setBlock(i + 7, j + 2, k + 6, IceikaBlocks.snowBricks);
        world.setBlock(i + 7, j + 2, k + 7, IceikaBlocks.snowBricks);
        world.setBlock(i + 7, j + 2, k + 8, IceikaBlocks.snowBricks);
        world.setBlock(i + 7, j + 2, k + 11, IceikaBlocks.snowBricks);
        world.setBlock(i + 7, j + 2, k + 12, IceikaBlocks.snowBricks);
        world.setBlock(i + 7, j + 2, k + 13, IceikaBlocks.snowBricks);
        world.setBlock(i + 7, j + 2, k + 16, IceikaBlocks.snowBricks);
        world.setBlock(i + 7, j + 2, k + 17, IceikaBlocks.snowBricks);
        world.setBlock(i + 7, j + 2, k + 18, IceikaBlocks.snowBricks);
        world.setBlock(i + 7, j + 2, k + 19, IceikaBlocks.snowBricks);
        world.setBlock(i + 7, j + 2, k + 20, IceikaBlocks.snowBricks);
        world.setBlock(i + 7, j + 2, k + 21, IceikaBlocks.snowBricks);
        world.setBlock(i + 7, j + 2, k + 22, IceikaBlocks.snowBricks);
        world.setBlock(i + 7, j + 2, k + 23, IceikaBlocks.snowBricks);
        world.setBlock(i + 7, j + 2, k + 24, IceikaBlocks.snowBricks);
        world.setBlock(i + 7, j + 2, k + 25, IceikaBlocks.snowBricks);
        world.setBlock(i + 7, j + 3, k + 0, IceikaBlocks.snowBricks);
        world.setBlock(i + 7, j + 3, k + 1, IceikaBlocks.snowBricks);
        world.setBlock(i + 7, j + 3, k + 2, IceikaBlocks.snowBricks);
        world.setBlock(i + 7, j + 3, k + 3, IceikaBlocks.snowBricks);
        world.setBlock(i + 7, j + 3, k + 4, IceikaBlocks.snowBricks);
        world.setBlock(i + 7, j + 3, k + 5, IceikaBlocks.snowBricks);
        world.setBlock(i + 7, j + 3, k + 6, IceikaBlocks.snowBricks);
        world.setBlock(i + 7, j + 3, k + 7, IceikaBlocks.snowBricks);
        world.setBlock(i + 7, j + 3, k + 8, IceikaBlocks.snowBricks);
        world.setBlock(i + 7, j + 3, k + 11, IceikaBlocks.snowBricks);
        world.setBlock(i + 7, j + 3, k + 12, IceikaBlocks.snowBricks);
        world.setBlock(i + 7, j + 3, k + 13, IceikaBlocks.snowBricks);
        world.setBlock(i + 7, j + 3, k + 16, IceikaBlocks.snowBricks);
        world.setBlock(i + 7, j + 3, k + 17, IceikaBlocks.snowBricks);
        world.setBlock(i + 7, j + 3, k + 18, IceikaBlocks.snowBricks);
        world.setBlock(i + 7, j + 3, k + 19, IceikaBlocks.snowBricks);
        world.setBlock(i + 7, j + 3, k + 20, IceikaBlocks.snowBricks);
        world.setBlock(i + 7, j + 3, k + 21, IceikaBlocks.snowBricks);
        world.setBlock(i + 7, j + 3, k + 22, IceikaBlocks.snowBricks);
        world.setBlock(i + 7, j + 3, k + 23, IceikaBlocks.snowBricks);
        world.setBlock(i + 7, j + 3, k + 24, IceikaBlocks.snowBricks);
        world.setBlock(i + 7, j + 3, k + 25, IceikaBlocks.snowBricks);
        world.setBlock(i + 7, j + 4, k + 14, IceikaBlocks.snowBricks);
        world.setBlock(i + 7, j + 4, k + 15, IceikaBlocks.snowBricks);
        world.setBlock(i + 8, j + 0, k + 0, IceikaBlocks.snowBricks);
        world.setBlock(i + 8, j + 0, k + 1, IceikaBlocks.icyStone);
        world.setBlock(i + 8, j + 0, k + 2, IceikaBlocks.icyStone);
        world.setBlock(i + 8, j + 0, k + 3, IceikaBlocks.icyStone);
        world.setBlock(i + 8, j + 0, k + 4, IceikaBlocks.icyStone);
        world.setBlock(i + 8, j + 0, k + 5, IceikaBlocks.icyStone);
        world.setBlock(i + 8, j + 0, k + 6, IceikaBlocks.icyStone);
        world.setBlock(i + 8, j + 0, k + 7, IceikaBlocks.icyStone);
        world.setBlock(i + 8, j + 0, k + 8, IceikaBlocks.snowBricks);
        world.setBlock(i + 8, j + 0, k + 13, IceikaBlocks.snowBricks);
        world.setBlock(i + 8, j + 0, k + 14, IceikaBlocks.icyStone);
        world.setBlock(i + 8, j + 0, k + 15, IceikaBlocks.icyStone);
        world.setBlock(i + 8, j + 0, k + 16, IceikaBlocks.snowBricks);
