/*
*** MADE BY MITHION'S .SCHEMATIC TO JAVA CONVERTING TOOL v1.6 ***
*/

package net.divinerpg.dimension.gen.vethea.layer1;
import java.util.Random;

import net.divinerpg.entity.vethea.EntityCryptKeeper;
import net.divinerpg.helper.blocks.VetheaBlocks;
import net.minecraft.entity.EntityLiving;
import net.minecraft.init.Blocks;
import net.minecraft.world.World;
import net.minecraft.world.gen.feature.WorldGenerator;
 
public class Crypt1 extends WorldGenerator
{
	public Crypt1() { }

	public boolean generate(World world, Random rand, int i, int j, int k) {		
		world.setBlock(i + 0, j + 0, k + 0, VetheaBlocks.dreamDirt);
		world.setBlock(i + 0, j + 0, k + 1, VetheaBlocks.dreamDirt);
		world.setBlock(i + 0, j + 0, k + 2, VetheaBlocks.dreamDirt);
		world.setBlock(i + 0, j + 0, k + 3, VetheaBlocks.dreamDirt);
		world.setBlock(i + 0, j + 0, k + 4, VetheaBlocks.dreamDirt);
		world.setBlock(i + 0, j + 0, k + 5, VetheaBlocks.dreamDirt);
		world.setBlock(i + 0, j + 0, k + 6, VetheaBlocks.dreamDirt);
		world.setBlock(i + 0, j + 0, k + 7, VetheaBlocks.dreamDirt);
		world.setBlock(i + 0, j + 0, k + 8, VetheaBlocks.dreamDirt);
		world.setBlock(i + 0, j + 0, k + 9, VetheaBlocks.dreamDirt);
		world.setBlock(i + 0, j + 0, k + 10, VetheaBlocks.dreamDirt);
		world.setBlock(i + 0, j + 0, k + 11, VetheaBlocks.dreamDirt);
		world.setBlock(i + 0, j + 0, k + 12, VetheaBlocks.dreamDirt);
		world.setBlock(i + 0, j + 0, k + 13, VetheaBlocks.dreamDirt);
		world.setBlock(i + 0, j + 0, k + 14, VetheaBlocks.dreamDirt);
		world.setBlock(i + 0, j + 0, k + 15, VetheaBlocks.dreamDirt);
		world.setBlock(i + 0, j + 0, k + 16, VetheaBlocks.dreamDirt);
		world.setBlock(i + 0, j + 0, k + 17, VetheaBlocks.dreamDirt);
		world.setBlock(i + 0, j + 0, k + 18, VetheaBlocks.dreamDirt);
		world.setBlock(i + 0, j + 0, k + 19, VetheaBlocks.dreamDirt);
		world.setBlock(i + 0, j + 1, k + 0, VetheaBlocks.dreamDirt);
		world.setBlock(i + 0, j + 1, k + 1, VetheaBlocks.dreamDirt);
		world.setBlock(i + 0, j + 1, k + 2, VetheaBlocks.dreamDirt);
		world.setBlock(i + 0, j + 1, k + 3, VetheaBlocks.dreamDirt);
		world.setBlock(i + 0, j + 1, k + 4, VetheaBlocks.dreamDirt);
		world.setBlock(i + 0, j + 1, k + 5, VetheaBlocks.dreamDirt);
		world.setBlock(i + 0, j + 1, k + 6, VetheaBlocks.dreamDirt);
		world.setBlock(i + 0, j + 1, k + 7, VetheaBlocks.dreamDirt);
		world.setBlock(i + 0, j + 1, k + 8, VetheaBlocks.dreamDirt);
		world.setBlock(i + 0, j + 1, k + 9, VetheaBlocks.dreamDirt);
		world.setBlock(i + 0, j + 1, k + 10, VetheaBlocks.dreamDirt);
		world.setBlock(i + 0, j + 1, k + 11, VetheaBlocks.dreamDirt);
		world.setBlock(i + 0, j + 1, k + 12, VetheaBlocks.dreamDirt);
		world.setBlock(i + 0, j + 1, k + 13, VetheaBlocks.dreamDirt);
		world.setBlock(i + 0, j + 1, k + 14, VetheaBlocks.dreamDirt);
		world.setBlock(i + 0, j + 1, k + 15, VetheaBlocks.dreamDirt);
		world.setBlock(i + 0, j + 1, k + 16, VetheaBlocks.dreamDirt);
		world.setBlock(i + 0, j + 1, k + 17, VetheaBlocks.dreamDirt);
		world.setBlock(i + 0, j + 1, k + 18, VetheaBlocks.dreamDirt);
		world.setBlock(i + 0, j + 1, k + 19, VetheaBlocks.dreamDirt);
		world.setBlock(i + 0, j + 2, k + 0, VetheaBlocks.dreamDirt);
		world.setBlock(i + 0, j + 2, k + 1, VetheaBlocks.dreamDirt);
		world.setBlock(i + 0, j + 2, k + 2, VetheaBlocks.dreamDirt);
		world.setBlock(i + 0, j + 2, k + 3, VetheaBlocks.dreamDirt);
		world.setBlock(i + 0, j + 2, k + 4, VetheaBlocks.dreamDirt);
		world.setBlock(i + 0, j + 2, k + 5, VetheaBlocks.dreamDirt);
		world.setBlock(i + 0, j + 2, k + 6, VetheaBlocks.dreamDirt);
		world.setBlock(i + 0, j + 2, k + 7, VetheaBlocks.dreamDirt);
		world.setBlock(i + 0, j + 2, k + 8, VetheaBlocks.dreamDirt);
		world.setBlock(i + 0, j + 2, k + 9, VetheaBlocks.dreamDirt);
		world.setBlock(i + 0, j + 2, k + 10, VetheaBlocks.dreamDirt);
		world.setBlock(i + 0, j + 2, k + 11, VetheaBlocks.dreamDirt);
		world.setBlock(i + 0, j + 2, k + 12, VetheaBlocks.dreamDirt);
		world.setBlock(i + 0, j + 2, k + 13, VetheaBlocks.dreamDirt);
		world.setBlock(i + 0, j + 2, k + 14, VetheaBlocks.dreamDirt);
		world.setBlock(i + 0, j + 2, k + 15, VetheaBlocks.dreamDirt);
		world.setBlock(i + 0, j + 2, k + 16, VetheaBlocks.dreamDirt);
		world.setBlock(i + 0, j + 2, k + 17, VetheaBlocks.dreamDirt);
		world.setBlock(i + 0, j + 2, k + 18, VetheaBlocks.dreamDirt);
		world.setBlock(i + 0, j + 2, k + 19, VetheaBlocks.dreamDirt);
		world.setBlock(i + 0, j + 3, k + 0, VetheaBlocks.dreamDirt);
		world.setBlock(i + 0, j + 3, k + 1, VetheaBlocks.dreamDirt);
		world.setBlock(i + 0, j + 3, k + 2, VetheaBlocks.dreamDirt);
		world.setBlock(i + 0, j + 3, k + 3, VetheaBlocks.dreamDirt);
		world.setBlock(i + 0, j + 3, k + 4, VetheaBlocks.dreamDirt);
		world.setBlock(i + 0, j + 3, k + 5, VetheaBlocks.dreamDirt);
		world.setBlock(i + 0, j + 3, k + 6, VetheaBlocks.dreamDirt);
		world.setBlock(i + 0, j + 3, k + 7, VetheaBlocks.dreamDirt);
		world.setBlock(i + 0, j + 3, k + 8, VetheaBlocks.dreamDirt);
		world.setBlock(i + 0, j + 3, k + 9, VetheaBlocks.dreamDirt);
		world.setBlock(i + 0, j + 3, k + 10, VetheaBlocks.dreamDirt);
		world.setBlock(i + 0, j + 3, k + 11, VetheaBlocks.dreamDirt);
		world.setBlock(i + 0, j + 3, k + 12, VetheaBlocks.dreamDirt);
		world.setBlock(i + 0, j + 3, k + 13, VetheaBlocks.dreamDirt);
		world.setBlock(i + 0, j + 3, k + 14, VetheaBlocks.dreamDirt);
		world.setBlock(i + 0, j + 3, k + 15, VetheaBlocks.dreamDirt);
		world.setBlock(i + 0, j + 3, k + 16, VetheaBlocks.dreamDirt);
		world.setBlock(i + 0, j + 3, k + 17, VetheaBlocks.dreamDirt);
		world.setBlock(i + 0, j + 3, k + 18, VetheaBlocks.dreamDirt);
		world.setBlock(i + 0, j + 3, k + 19, VetheaBlocks.dreamDirt);
		world.setBlock(i + 0, j + 4, k + 0, VetheaBlocks.dreamDirt);
		world.setBlock(i + 0, j + 4, k + 1, VetheaBlocks.dreamDirt);
		world.setBlock(i + 0, j + 4, k + 2, VetheaBlocks.dreamDirt);
		world.setBlock(i + 0, j + 4, k + 3, VetheaBlocks.dreamDirt);
		world.setBlock(i + 0, j + 4, k + 4, VetheaBlocks.dreamDirt);
		world.setBlock(i + 0, j + 4, k + 5, VetheaBlocks.dreamDirt);
		world.setBlock(i + 0, j + 4, k + 6, VetheaBlocks.dreamDirt);
		world.setBlock(i + 0, j + 4, k + 7, VetheaBlocks.dreamDirt);
		world.setBlock(i + 0, j + 4, k + 8, VetheaBlocks.dreamDirt);
		world.setBlock(i + 0, j + 4, k + 9, VetheaBlocks.dreamDirt);
		world.setBlock(i + 0, j + 4, k + 10, VetheaBlocks.dreamDirt);
		world.setBlock(i + 0, j + 4, k + 11, VetheaBlocks.dreamDirt);
		world.setBlock(i + 0, j + 4, k + 12, VetheaBlocks.dreamDirt);
		world.setBlock(i + 0, j + 4, k + 13, VetheaBlocks.dreamDirt);
		world.setBlock(i + 0, j + 4, k + 14, VetheaBlocks.dreamDirt);
		world.setBlock(i + 0, j + 4, k + 15, VetheaBlocks.dreamDirt);
		world.setBlock(i + 0, j + 4, k + 16, VetheaBlocks.dreamDirt);
		world.setBlock(i + 0, j + 4, k + 17, VetheaBlocks.dreamDirt);
		world.setBlock(i + 0, j + 4, k + 18, VetheaBlocks.dreamDirt);
		world.setBlock(i + 0, j + 4, k + 19, VetheaBlocks.dreamDirt);
		world.setBlock(i + 0, j + 5, k + 0, VetheaBlocks.dreamDirt);
		world.setBlock(i + 0, j + 5, k + 1, VetheaBlocks.dreamDirt);
		world.setBlock(i + 0, j + 5, k + 2, VetheaBlocks.dreamDirt);
		world.setBlock(i + 0, j + 5, k + 3, VetheaBlocks.cryptWall);
		world.setBlock(i + 0, j + 5, k + 4, VetheaBlocks.cryptWall);
		world.setBlock(i + 0, j + 5, k + 5, VetheaBlocks.dreamDirt);
		world.setBlock(i + 0, j + 5, k + 6, VetheaBlocks.dreamDirt);
		world.setBlock(i + 0, j + 5, k + 7, VetheaBlocks.dreamDirt);
		world.setBlock(i + 0, j + 5, k + 8, VetheaBlocks.dreamDirt);
		world.setBlock(i + 0, j + 5, k + 9, VetheaBlocks.dreamDirt);
		world.setBlock(i + 0, j + 5, k + 10, VetheaBlocks.dreamDirt);
		world.setBlock(i + 0, j + 5, k + 11, VetheaBlocks.dreamDirt);
		world.setBlock(i + 0, j + 5, k + 12, VetheaBlocks.dreamDirt);
		world.setBlock(i + 0, j + 5, k + 13, VetheaBlocks.dreamDirt);
		world.setBlock(i + 0, j + 5, k + 14, VetheaBlocks.cryptWall);
		world.setBlock(i + 0, j + 5, k + 15, VetheaBlocks.cryptWall);
		world.setBlock(i + 0, j + 5, k + 16, VetheaBlocks.dreamDirt);
		world.setBlock(i + 0, j + 5, k + 17, VetheaBlocks.dreamDirt);
		world.setBlock(i + 0, j + 5, k + 18, VetheaBlocks.dreamDirt);
		world.setBlock(i + 0, j + 5, k + 19, VetheaBlocks.dreamDirt);
		world.setBlock(i + 0, j + 6, k + 0, VetheaBlocks.metalCaging);
		world.setBlock(i + 0, j + 6, k + 1, VetheaBlocks.metalCaging);
		world.setBlock(i + 0, j + 6, k + 2, VetheaBlocks.hungerstone1);
		world.setBlock(i + 0, j + 6, k + 3, Blocks.air);
		world.setBlock(i + 0, j + 6, k + 4, Blocks.air);
		world.setBlock(i + 0, j + 6, k + 5, VetheaBlocks.hungerstone1);
		world.setBlock(i + 0, j + 6, k + 6, VetheaBlocks.metalCaging);
		world.setBlock(i + 0, j + 6, k + 7, VetheaBlocks.metalCaging);
		world.setBlock(i + 0, j + 6, k + 8, VetheaBlocks.metalCaging);
		world.setBlock(i + 0, j + 6, k + 9, VetheaBlocks.metalCaging);
		world.setBlock(i + 0, j + 6, k + 10, VetheaBlocks.metalCaging);
		world.setBlock(i + 0, j + 6, k + 11, VetheaBlocks.metalCaging);
		world.setBlock(i + 0, j + 6, k + 12, VetheaBlocks.metalCaging);
		world.setBlock(i + 0, j + 6, k + 13, VetheaBlocks.hungerstone1);
		world.setBlock(i + 0, j + 6, k + 14, Blocks.air);
		world.setBlock(i + 0, j + 6, k + 15, Blocks.air);
		world.setBlock(i + 0, j + 6, k + 16, VetheaBlocks.hungerstone1);
		world.setBlock(i + 0, j + 6, k + 17, VetheaBlocks.metalCaging);
		world.setBlock(i + 0, j + 6, k + 18, VetheaBlocks.metalCaging);
		world.setBlock(i + 0, j + 6, k + 19, VetheaBlocks.metalCaging);
		world.setBlock(i + 0, j + 7, k + 0, VetheaBlocks.hungerstone1);
		world.setBlock(i + 0, j + 7, k + 1, VetheaBlocks.hungerstone1);
		world.setBlock(i + 0, j + 7, k + 2, VetheaBlocks.hungerstone1);
		world.setBlock(i + 0, j + 7, k + 3, Blocks.air);
		world.setBlock(i + 0, j + 7, k + 4, Blocks.air);
		world.setBlock(i + 0, j + 7, k + 5, VetheaBlocks.hungerstone1);
		world.setBlock(i + 0, j + 7, k + 6, VetheaBlocks.hungerstone1);
		world.setBlock(i + 0, j + 7, k + 7, VetheaBlocks.hungerstone1);
		world.setBlock(i + 0, j + 7, k + 8, VetheaBlocks.hungerstone1);
		world.setBlock(i + 0, j + 7, k + 9, VetheaBlocks.hungerstone1);
		world.setBlock(i + 0, j + 7, k + 10, VetheaBlocks.hungerstone1);
		world.setBlock(i + 0, j + 7, k + 11, VetheaBlocks.hungerstone1);
		world.setBlock(i + 0, j + 7, k + 12, VetheaBlocks.hungerstone1);
		world.setBlock(i + 0, j + 7, k + 13, VetheaBlocks.hungerstone1);
		world.setBlock(i + 0, j + 7, k + 14, Blocks.air);
		world.setBlock(i + 0, j + 7, k + 15, Blocks.air);
		world.setBlock(i + 0, j + 7, k + 16, VetheaBlocks.hungerstone1);
		world.setBlock(i + 0, j + 7, k + 17, VetheaBlocks.hungerstone1);
		world.setBlock(i + 0, j + 7, k + 18, VetheaBlocks.hungerstone1);
		world.setBlock(i + 0, j + 7, k + 19, VetheaBlocks.hungerstone1);
		world.setBlock(i + 0, j + 8, k + 0, Blocks.air);
		world.setBlock(i + 0, j + 8, k + 1, Blocks.air);
		world.setBlock(i + 0, j + 8, k + 2, VetheaBlocks.hungerstone1);
		world.setBlock(i + 0, j + 8, k + 3, VetheaBlocks.hungerstone1);
		world.setBlock(i + 0, j + 8, k + 4, VetheaBlocks.hungerstone1);
		world.setBlock(i + 0, j + 8, k + 5, VetheaBlocks.hungerstone1);
		world.setBlock(i + 0, j + 8, k + 6, Blocks.air);
		world.setBlock(i + 0, j + 8, k + 7, Blocks.air);
		world.setBlock(i + 0, j + 8, k + 8, Blocks.air);
		world.setBlock(i + 0, j + 8, k + 9, Blocks.air);
		world.setBlock(i + 0, j + 8, k + 10, Blocks.air);
		world.setBlock(i + 0, j + 8, k + 11, Blocks.air);
		world.setBlock(i + 0, j + 8, k + 12, Blocks.air);
		world.setBlock(i + 0, j + 8, k + 13, VetheaBlocks.hungerstone1);
		world.setBlock(i + 0, j + 8, k + 14, VetheaBlocks.hungerstone1);
		world.setBlock(i + 0, j + 8, k + 15, VetheaBlocks.hungerstone1);
		world.setBlock(i + 0, j + 8, k + 16, VetheaBlocks.hungerstone1);
		world.setBlock(i + 0, j + 8, k + 17, Blocks.air);
		world.setBlock(i + 0, j + 8, k + 18, Blocks.air);
		world.setBlock(i + 0, j + 8, k + 19, Blocks.air);
		world.setBlock(i + 0, j + 9, k + 0, Blocks.air);
		world.setBlock(i + 0, j + 9, k + 1, Blocks.air);
		world.setBlock(i + 0, j + 9, k + 2, Blocks.air);
		world.setBlock(i + 0, j + 9, k + 3, Blocks.air);
		world.setBlock(i + 0, j + 9, k + 4, Blocks.air);
		world.setBlock(i + 0, j + 9, k + 5, Blocks.air);
		world.setBlock(i + 0, j + 9, k + 6, Blocks.air);
		world.setBlock(i + 0, j + 9, k + 7, Blocks.air);
		world.setBlock(i + 0, j + 9, k + 8, Blocks.air);
		world.setBlock(i + 0, j + 9, k + 9, Blocks.air);
		world.setBlock(i + 0, j + 9, k + 10, Blocks.air);
		world.setBlock(i + 0, j + 9, k + 11, Blocks.air);
		world.setBlock(i + 0, j + 9, k + 12, Blocks.air);
		world.setBlock(i + 0, j + 9, k + 13, Blocks.air);
		world.setBlock(i + 0, j + 9, k + 14, Blocks.air);
		world.setBlock(i + 0, j + 9, k + 15, Blocks.air);
		world.setBlock(i + 0, j + 9, k + 16, Blocks.air);
		world.setBlock(i + 0, j + 9, k + 17, Blocks.air);
		world.setBlock(i + 0, j + 9, k + 18, Blocks.air);
		world.setBlock(i + 0, j + 9, k + 19, Blocks.air);
		world.setBlock(i + 0, j + 10, k + 0, Blocks.air);
		world.setBlock(i + 0, j + 10, k + 1, Blocks.air);
		world.setBlock(i + 0, j + 10, k + 2, Blocks.air);
		world.setBlock(i + 0, j + 10, k + 3, Blocks.air);
		world.setBlock(i + 0, j + 10, k + 4, Blocks.air);
		world.setBlock(i + 0, j + 10, k + 5, Blocks.air);
		world.setBlock(i + 0, j + 10, k + 6, Blocks.air);
		world.setBlock(i + 0, j + 10, k + 7, Blocks.air);
		world.setBlock(i + 0, j + 10, k + 8, Blocks.air);
		world.setBlock(i + 0, j + 10, k + 9, Blocks.air);
		world.setBlock(i + 0, j + 10, k + 10, Blocks.air);
		world.setBlock(i + 0, j + 10, k + 11, Blocks.air);
		world.setBlock(i + 0, j + 10, k + 12, Blocks.air);
		world.setBlock(i + 0, j + 10, k + 13, Blocks.air);
		world.setBlock(i + 0, j + 10, k + 14, Blocks.air);
		world.setBlock(i + 0, j + 10, k + 15, Blocks.air);
		world.setBlock(i + 0, j + 10, k + 16, Blocks.air);
		world.setBlock(i + 0, j + 10, k + 17, Blocks.air);
		world.setBlock(i + 0, j + 10, k + 18, Blocks.air);
		world.setBlock(i + 0, j + 10, k + 19, Blocks.air);
		world.setBlock(i + 1, j + 0, k + 0, VetheaBlocks.dreamDirt);
		world.setBlock(i + 1, j + 0, k + 1, VetheaBlocks.dreamDirt);
		world.setBlock(i + 1, j + 0, k + 2, VetheaBlocks.dreamDirt);
		world.setBlock(i + 1, j + 0, k + 3, VetheaBlocks.dreamDirt);
		world.setBlock(i + 1, j + 0, k + 4, VetheaBlocks.dreamDirt);
		world.setBlock(i + 1, j + 0, k + 5, VetheaBlocks.dreamDirt);
		world.setBlock(i + 1, j + 0, k + 6, VetheaBlocks.dreamDirt);
		world.setBlock(i + 1, j + 0, k + 7, VetheaBlocks.dreamDirt);
		world.setBlock(i + 1, j + 0, k + 8, VetheaBlocks.dreamDirt);
		world.setBlock(i + 1, j + 0, k + 9, VetheaBlocks.dreamDirt);
		world.setBlock(i + 1, j + 0, k + 10, VetheaBlocks.cryptWall);
		world.setBlock(i + 1, j + 0, k + 11, VetheaBlocks.cryptWall);
		world.setBlock(i + 1, j + 0, k + 12, VetheaBlocks.cryptWall);
		world.setBlock(i + 1, j + 0, k + 13, VetheaBlocks.dreamDirt);
		world.setBlock(i + 1, j + 0, k + 14, VetheaBlocks.dreamDirt);
		world.setBlock(i + 1, j + 0, k + 15, VetheaBlocks.dreamDirt);
		world.setBlock(i + 1, j + 0, k + 16, VetheaBlocks.dreamDirt);
		world.setBlock(i + 1, j + 0, k + 17, VetheaBlocks.dreamDirt);
		world.setBlock(i + 1, j + 0, k + 18, VetheaBlocks.dreamDirt);
		world.setBlock(i + 1, j + 0, k + 19, VetheaBlocks.dreamDirt);
		world.setBlock(i + 1, j + 1, k + 0, VetheaBlocks.dreamDirt);
		world.setBlock(i + 1, j + 1, k + 1, VetheaBlocks.dreamDirt);
		world.setBlock(i + 1, j + 1, k + 2, VetheaBlocks.dreamDirt);
		world.setBlock(i + 1, j + 1, k + 3, VetheaBlocks.dreamDirt);
		world.setBlock(i + 1, j + 1, k + 4, VetheaBlocks.dreamDirt);
		world.setBlock(i + 1, j + 1, k + 5, VetheaBlocks.dreamDirt);
		world.setBlock(i + 1, j + 1, k + 6, VetheaBlocks.dreamDirt);
		world.setBlock(i + 1, j + 1, k + 7, VetheaBlocks.dreamDirt);
		world.setBlock(i + 1, j + 1, k + 8, VetheaBlocks.dreamDirt);
		world.setBlock(i + 1, j + 1, k + 9, VetheaBlocks.dreamDirt);
		world.setBlock(i + 1, j + 1, k + 10, VetheaBlocks.cryptWall);
		world.setBlock(i + 1, j + 1, k + 11, VetheaBlocks.cryptWall);
		world.setBlock(i + 1, j + 1, k + 12, VetheaBlocks.cryptWall);
		world.setBlock(i + 1, j + 1, k + 13, VetheaBlocks.cryptWall);
		world.setBlock(i + 1, j + 1, k + 14, VetheaBlocks.cryptWall);
		world.setBlock(i + 1, j + 1, k + 15, VetheaBlocks.cryptWall);
		world.setBlock(i + 1, j + 1, k + 16, VetheaBlocks.dreamDirt);
		world.setBlock(i + 1, j + 1, k + 17, VetheaBlocks.dreamDirt);
		world.setBlock(i + 1, j + 1, k + 18, VetheaBlocks.dreamDirt);
		world.setBlock(i + 1, j + 1, k + 19, VetheaBlocks.dreamDirt);
		world.setBlock(i + 1, j + 2, k + 0, VetheaBlocks.dreamDirt);
		world.setBlock(i + 1, j + 2, k + 1, VetheaBlocks.dreamDirt);
		world.setBlock(i + 1, j + 2, k + 2, VetheaBlocks.dreamDirt);
		world.setBlock(i + 1, j + 2, k + 3, VetheaBlocks.dreamDirt);
		world.setBlock(i + 1, j + 2, k + 4, VetheaBlocks.dreamDirt);
		world.setBlock(i + 1, j + 2, k + 5, VetheaBlocks.dreamDirt);
		world.setBlock(i + 1, j + 2, k + 6, VetheaBlocks.dreamDirt);
		world.setBlock(i + 1, j + 2, k + 7, VetheaBlocks.dreamDirt);
		world.setBlock(i + 1, j + 2, k + 8, VetheaBlocks.dreamDirt);
		world.setBlock(i + 1, j + 2, k + 9, VetheaBlocks.dreamDirt);
		world.setBlock(i + 1, j + 2, k + 10, VetheaBlocks.cryptWall);
		world.setBlock(i + 1, j + 2, k + 11, VetheaBlocks.cryptWall);
		world.setBlock(i + 1, j + 2, k + 12, VetheaBlocks.cryptWall);
		world.setBlock(i + 1, j + 2, k + 13, VetheaBlocks.cryptWall);
		world.setBlock(i + 1, j + 2, k + 14, VetheaBlocks.cryptWall);
		world.setBlock(i + 1, j + 2, k + 15, VetheaBlocks.cryptWall);
		world.setBlock(i + 1, j + 2, k + 16, VetheaBlocks.dreamDirt);
		world.setBlock(i + 1, j + 2, k + 17, VetheaBlocks.dreamDirt);
		world.setBlock(i + 1, j + 2, k + 18, VetheaBlocks.dreamDirt);
		world.setBlock(i + 1, j + 2, k + 19, VetheaBlocks.dreamDirt);
		world.setBlock(i + 1, j + 3, k + 0, VetheaBlocks.dreamDirt);
		world.setBlock(i + 1, j + 3, k + 1, VetheaBlocks.dreamDirt);
		world.setBlock(i + 1, j + 3, k + 2, VetheaBlocks.dreamDirt);
		world.setBlock(i + 1, j + 3, k + 3, VetheaBlocks.dreamDirt);
		world.setBlock(i + 1, j + 3, k + 4, VetheaBlocks.dreamDirt);
		world.setBlock(i + 1, j + 3, k + 5, VetheaBlocks.dreamDirt);
		world.setBlock(i + 1, j + 3, k + 6, VetheaBlocks.dreamDirt);
		world.setBlock(i + 1, j + 3, k + 7, VetheaBlocks.dreamDirt);
		world.setBlock(i + 1, j + 3, k + 8, VetheaBlocks.dreamDirt);
		world.setBlock(i + 1, j + 3, k + 9, VetheaBlocks.dreamDirt);
		world.setBlock(i + 1, j + 3, k + 10, VetheaBlocks.cryptWall);
		world.setBlock(i + 1, j + 3, k + 11, VetheaBlocks.cryptWall);
		world.setBlock(i + 1, j + 3, k + 12, VetheaBlocks.cryptWall);
		world.setBlock(i + 1, j + 3, k + 13, VetheaBlocks.cryptWall);
		world.setBlock(i + 1, j + 3, k + 14, VetheaBlocks.cryptWall);
		world.setBlock(i + 1, j + 3, k + 15, VetheaBlocks.cryptWall);
		world.setBlock(i + 1, j + 3, k + 16, VetheaBlocks.dreamDirt);
		world.setBlock(i + 1, j + 3, k + 17, VetheaBlocks.dreamDirt);
		world.setBlock(i + 1, j + 3, k + 18, VetheaBlocks.dreamDirt);
		world.setBlock(i + 1, j + 3, k + 19, VetheaBlocks.dreamDirt);
		world.setBlock(i + 1, j + 4, k + 0, VetheaBlocks.dreamDirt);
		world.setBlock(i + 1, j + 4, k + 1, VetheaBlocks.dreamDirt);
		world.setBlock(i + 1, j + 4, k + 2, VetheaBlocks.dreamDirt);
		world.setBlock(i + 1, j + 4, k + 3, VetheaBlocks.dreamDirt);
		world.setBlock(i + 1, j + 4, k + 4, VetheaBlocks.dreamDirt);
		world.setBlock(i + 1, j + 4, k + 5, VetheaBlocks.dreamDirt);
		world.setBlock(i + 1, j + 4, k + 6, VetheaBlocks.dreamDirt);
		world.setBlock(i + 1, j + 4, k + 7, VetheaBlocks.dreamDirt);
		world.setBlock(i + 1, j + 4, k + 8, VetheaBlocks.dreamDirt);
		world.setBlock(i + 1, j + 4, k + 9, VetheaBlocks.dreamDirt);
		world.setBlock(i + 1, j + 4, k + 10, VetheaBlocks.dreamDirt);
		world.setBlock(i + 1, j + 4, k + 11, VetheaBlocks.dreamDirt);
		world.setBlock(i + 1, j + 4, k + 12, VetheaBlocks.dreamDirt);
		world.setBlock(i + 1, j + 4, k + 13, VetheaBlocks.dreamDirt);
		world.setBlock(i + 1, j + 4, k + 14, VetheaBlocks.dreamDirt);
		world.setBlock(i + 1, j + 4, k + 15, VetheaBlocks.dreamDirt);
		world.setBlock(i + 1, j + 4, k + 16, VetheaBlocks.dreamDirt);
		world.setBlock(i + 1, j + 4, k + 17, VetheaBlocks.dreamDirt);
		world.setBlock(i + 1, j + 4, k + 18, VetheaBlocks.dreamDirt);
		world.setBlock(i + 1, j + 4, k + 19, VetheaBlocks.dreamDirt);
		world.setBlock(i + 1, j + 5, k + 0, VetheaBlocks.dreamDirt);
		world.setBlock(i + 1, j + 5, k + 1, VetheaBlocks.dreamDirt);
		world.setBlock(i + 1, j + 5, k + 2, VetheaBlocks.dreamDirt);
		world.setBlock(i + 1, j + 5, k + 3, VetheaBlocks.cryptWall);
		world.setBlock(i + 1, j + 5, k + 4, VetheaBlocks.cryptWall);
		world.setBlock(i + 1, j + 5, k + 5, VetheaBlocks.dreamDirt);
		world.setBlock(i + 1, j + 5, k + 6, VetheaBlocks.dreamDirt);
		world.setBlock(i + 1, j + 5, k + 7, VetheaBlocks.dreamDirt);
		world.setBlock(i + 1, j + 5, k + 8, VetheaBlocks.dreamDirt);
		world.setBlock(i + 1, j + 5, k + 9, VetheaBlocks.dreamDirt);
		world.setBlock(i + 1, j + 5, k + 10, VetheaBlocks.dreamDirt);
		world.setBlock(i + 1, j + 5, k + 11, VetheaBlocks.dreamDirt);
		world.setBlock(i + 1, j + 5, k + 12, VetheaBlocks.dreamDirt);
		world.setBlock(i + 1, j + 5, k + 13, VetheaBlocks.dreamDirt);
		world.setBlock(i + 1, j + 5, k + 14, VetheaBlocks.cryptWall);
		world.setBlock(i + 1, j + 5, k + 15, VetheaBlocks.cryptWall);
		world.setBlock(i + 1, j + 5, k + 16, VetheaBlocks.dreamDirt);
		world.setBlock(i + 1, j + 5, k + 17, VetheaBlocks.dreamDirt);
		world.setBlock(i + 1, j + 5, k + 18, VetheaBlocks.dreamDirt);
		world.setBlock(i + 1, j + 5, k + 19, VetheaBlocks.dreamDirt);
		world.setBlock(i + 1, j + 6, k + 0, VetheaBlocks.metalCaging);
		world.setBlock(i + 1, j + 6, k + 1, Blocks.air);
		world.setBlock(i + 1, j + 6, k + 2, Blocks.air);
		world.setBlock(i + 1, j + 6, k + 3, Blocks.air);
		world.setBlock(i + 1, j + 6, k + 4, Blocks.air);
		world.setBlock(i + 1, j + 6, k + 5, Blocks.air);
		world.setBlock(i + 1, j + 6, k + 6, Blocks.air);
		world.setBlock(i + 1, j + 6, k + 7, Blocks.air);
		world.setBlock(i + 1, j + 6, k + 8, Blocks.air);
		world.setBlock(i + 1, j + 6, k + 9, Blocks.air);
		world.setBlock(i + 1, j + 6, k + 10, Blocks.air);
		world.setBlock(i + 1, j + 6, k + 11, Blocks.air);
		world.setBlock(i + 1, j + 6, k + 12, Blocks.air);
		world.setBlock(i + 1, j + 6, k + 13, Blocks.air);
		world.setBlock(i + 1, j + 6, k + 14, Blocks.air);
		world.setBlock(i + 1, j + 6, k + 15, Blocks.air);
		world.setBlock(i + 1, j + 6, k + 16, Blocks.air);
		world.setBlock(i + 1, j + 6, k + 17, Blocks.air);
		world.setBlock(i + 1, j + 6, k + 18, Blocks.air);
		world.setBlock(i + 1, j + 6, k + 19, VetheaBlocks.metalCaging);
		world.setBlock(i + 1, j + 7, k + 0, VetheaBlocks.hungerstone1);
		world.setBlock(i + 1, j + 7, k + 1, Blocks.air);
		world.setBlock(i + 1, j + 7, k + 2, Blocks.air);
		world.setBlock(i + 1, j + 7, k + 3, Blocks.air);
		world.setBlock(i + 1, j + 7, k + 4, Blocks.air);
		world.setBlock(i + 1, j + 7, k + 5, Blocks.air);
		world.setBlock(i + 1, j + 7, k + 6, Blocks.air);
		world.setBlock(i + 1, j + 7, k + 7, Blocks.air);
		world.setBlock(i + 1, j + 7, k + 8, Blocks.air);
		world.setBlock(i + 1, j + 7, k + 9, Blocks.air);
		world.setBlock(i + 1, j + 7, k + 10, Blocks.air);
		world.setBlock(i + 1, j + 7, k + 11, Blocks.air);
		world.setBlock(i + 1, j + 7, k + 12, Blocks.air);
		world.setBlock(i + 1, j + 7, k + 13, Blocks.air);
		world.setBlock(i + 1, j + 7, k + 14, Blocks.air);
		world.setBlock(i + 1, j + 7, k + 15, Blocks.air);
		world.setBlock(i + 1, j + 7, k + 16, Blocks.air);
		world.setBlock(i + 1, j + 7, k + 17, Blocks.air);
		world.setBlock(i + 1, j + 7, k + 18, Blocks.air);
		world.setBlock(i + 1, j + 7, k + 19, VetheaBlocks.hungerstone1);
		world.setBlock(i + 1, j + 8, k + 0, Blocks.air);
		world.setBlock(i + 1, j + 8, k + 1, Blocks.air);
		world.setBlock(i + 1, j + 8, k + 2, Blocks.air);
		world.setBlock(i + 1, j + 8, k + 3, Blocks.air);
		world.setBlock(i + 1, j + 8, k + 4, Blocks.air);
		world.setBlock(i + 1, j + 8, k + 5, Blocks.air);
		world.setBlock(i + 1, j + 8, k + 6, Blocks.air);
		world.setBlock(i + 1, j + 8, k + 7, Blocks.air);
		world.setBlock(i + 1, j + 8, k + 8, Blocks.air);
		world.setBlock(i + 1, j + 8, k + 9, Blocks.air);
		world.setBlock(i + 1, j + 8, k + 10, Blocks.air);
		world.setBlock(i + 1, j + 8, k + 11, Blocks.air);
		world.setBlock(i + 1, j + 8, k + 12, Blocks.air);
		world.setBlock(i + 1, j + 8, k + 13, Blocks.air);
		world.setBlock(i + 1, j + 8, k + 14, Blocks.air);
		world.setBlock(i + 1, j + 8, k + 15, Blocks.air);
		world.setBlock(i + 1, j + 8, k + 16, Blocks.air);
		world.setBlock(i + 1, j + 8, k + 17, Blocks.air);
		world.setBlock(i + 1, j + 8, k + 18, Blocks.air);
		world.setBlock(i + 1, j + 8, k + 19, Blocks.air);
		world.setBlock(i + 1, j + 9, k + 0, Blocks.air);
		world.setBlock(i + 1, j + 9, k + 1, Blocks.air);
		world.setBlock(i + 1, j + 9, k + 2, Blocks.air);
		world.setBlock(i + 1, j + 9, k + 3, Blocks.air);
		world.setBlock(i + 1, j + 9, k + 4, Blocks.air);
		world.setBlock(i + 1, j + 9, k + 5, Blocks.air);
		world.setBlock(i + 1, j + 9, k + 6, Blocks.air);
		world.setBlock(i + 1, j + 9, k + 7, Blocks.air);
		world.setBlock(i + 1, j + 9, k + 8, Blocks.air);
		world.setBlock(i + 1, j + 9, k + 9, Blocks.air);
		world.setBlock(i + 1, j + 9, k + 10, Blocks.air);
		world.setBlock(i + 1, j + 9, k + 11, Blocks.air);
		world.setBlock(i + 1, j + 9, k + 12, Blocks.air);
		world.setBlock(i + 1, j + 9, k + 13, Blocks.air);
		world.setBlock(i + 1, j + 9, k + 14, Blocks.air);
		world.setBlock(i + 1, j + 9, k + 15, Blocks.air);
		world.setBlock(i + 1, j + 9, k + 16, Blocks.air);
		world.setBlock(i + 1, j + 9, k + 17, Blocks.air);
		world.setBlock(i + 1, j + 9, k + 18, Blocks.air);
		world.setBlock(i + 1, j + 9, k + 19, Blocks.air);
		world.setBlock(i + 1, j + 10, k + 0, Blocks.air);
		world.setBlock(i + 1, j + 10, k + 1, Blocks.air);
		world.setBlock(i + 1, j + 10, k + 2, Blocks.air);
		world.setBlock(i + 1, j + 10, k + 3, Blocks.air);
		world.setBlock(i + 1, j + 10, k + 4, Blocks.air);
		world.setBlock(i + 1, j + 10, k + 5, Blocks.air);
		world.setBlock(i + 1, j + 10, k + 6, Blocks.air);
		world.setBlock(i + 1, j + 10, k + 7, Blocks.air);
		world.setBlock(i + 1, j + 10, k + 8, Blocks.air);
		world.setBlock(i + 1, j + 10, k + 9, Blocks.air);
		world.setBlock(i + 1, j + 10, k + 10, Blocks.air);
		world.setBlock(i + 1, j + 10, k + 11, Blocks.air);
		world.setBlock(i + 1, j + 10, k + 12, Blocks.air);
		world.setBlock(i + 1, j + 10, k + 13, Blocks.air);
		world.setBlock(i + 1, j + 10, k + 14, Blocks.air);
		world.setBlock(i + 1, j + 10, k + 15, Blocks.air);
		world.setBlock(i + 1, j + 10, k + 16, Blocks.air);
		world.setBlock(i + 1, j + 10, k + 17, Blocks.air);
		world.setBlock(i + 1, j + 10, k + 18, Blocks.air);
		world.setBlock(i + 1, j + 10, k + 19, Blocks.air);
		world.setBlock(i + 2, j + 0, k + 0, VetheaBlocks.dreamDirt);
		world.setBlock(i + 2, j + 0, k + 1, VetheaBlocks.cryptWall);
		world.setBlock(i + 2, j + 0, k + 2, VetheaBlocks.cryptWall);
		world.setBlock(i + 2, j + 0, k + 3, VetheaBlocks.cryptWall);
		world.setBlock(i + 2, j + 0, k + 4, VetheaBlocks.cryptWall);
		world.setBlock(i + 2, j + 0, k + 5, VetheaBlocks.cryptWall);
		world.setBlock(i + 2, j + 0, k + 6, VetheaBlocks.cryptWall);
		world.setBlock(i + 2, j + 0, k + 7, VetheaBlocks.cryptWall);
		world.setBlock(i + 2, j + 0, k + 8, VetheaBlocks.cryptWall);
		world.setBlock(i + 2, j + 0, k + 9, VetheaBlocks.cryptWall);
		world.setBlock(i + 2, j + 0, k + 10, Blocks.air);
		world.setBlock(i + 2, j + 0, k + 11, Blocks.air);
		world.setBlock(i + 2, j + 0, k + 12, Blocks.air);
		world.setBlock(i + 2, j + 0, k + 13, VetheaBlocks.cryptFloor);
		world.setBlock(i + 2, j + 0, k + 14, VetheaBlocks.cryptFloor);
		world.setBlock(i + 2, j + 0, k + 15, VetheaBlocks.cryptFloor);
		world.setBlock(i + 2, j + 0, k + 16, VetheaBlocks.dreamDirt);
		world.setBlock(i + 2, j + 0, k + 17, VetheaBlocks.dreamDirt);
		world.setBlock(i + 2, j + 0, k + 18, VetheaBlocks.dreamDirt);
		world.setBlock(i + 2, j + 0, k + 19, VetheaBlocks.dreamDirt);
		world.setBlock(i + 2, j + 1, k + 0, VetheaBlocks.dreamDirt);
		world.setBlock(i + 2, j + 1, k + 1, VetheaBlocks.cryptWall);
		world.setBlock(i + 2, j + 1, k + 2, VetheaBlocks.cryptWall);
		world.setBlock(i + 2, j + 1, k + 3, VetheaBlocks.cryptWall);
		world.setBlock(i + 2, j + 1, k + 4, VetheaBlocks.cryptWall);
		world.setBlock(i + 2, j + 1, k + 5, VetheaBlocks.cryptWall);
		world.setBlock(i + 2, j + 1, k + 6, VetheaBlocks.cryptWall);
		world.setBlock(i + 2, j + 1, k + 7, VetheaBlocks.cryptWall);
		world.setBlock(i + 2, j + 1, k + 8, VetheaBlocks.cryptWall);
		world.setBlock(i + 2, j + 1, k + 9, VetheaBlocks.cryptWall);
		world.setBlock(i + 2, j + 1, k + 10, Blocks.air);
		world.setBlock(i + 2, j + 1, k + 11, Blocks.air);
		world.setBlock(i + 2, j + 1, k + 12, Blocks.air);
		world.setBlock(i + 2, j + 1, k + 13, Blocks.air);
		world.setBlock(i + 2, j + 1, k + 14, Blocks.air);
		world.setBlock(i + 2, j + 1, k + 15, VetheaBlocks.biphronSpawner);
		world.setBlock(i + 2, j + 1, k + 16, VetheaBlocks.cryptWall);
		world.setBlock(i + 2, j + 1, k + 17, VetheaBlocks.dreamDirt);
		world.setBlock(i + 2, j + 1, k + 18, VetheaBlocks.dreamDirt);
		world.setBlock(i + 2, j + 1, k + 19, VetheaBlocks.dreamDirt);
		world.setBlock(i + 2, j + 2, k + 0, VetheaBlocks.dreamDirt);
		world.setBlock(i + 2, j + 2, k + 1, VetheaBlocks.cryptWall);
		world.setBlock(i + 2, j + 2, k + 2, VetheaBlocks.cryptWall);
		world.setBlock(i + 2, j + 2, k + 3, VetheaBlocks.cryptWall);
		world.setBlock(i + 2, j + 2, k + 4, VetheaBlocks.cryptWall);
		world.setBlock(i + 2, j + 2, k + 5, VetheaBlocks.cryptWall);
		world.setBlock(i + 2, j + 2, k + 6, VetheaBlocks.cryptWall);
		world.setBlock(i + 2, j + 2, k + 7, VetheaBlocks.cryptWall);
		world.setBlock(i + 2, j + 2, k + 8, VetheaBlocks.cryptWall);
		world.setBlock(i + 2, j + 2, k + 9, VetheaBlocks.cryptWall);
		world.setBlock(i + 2, j + 2, k + 10, Blocks.air);
		world.setBlock(i + 2, j + 2, k + 11, Blocks.air);
		world.setBlock(i + 2, j + 2, k + 12, Blocks.air);
		world.setBlock(i + 2, j + 2, k + 13, Blocks.air);
		world.setBlock(i + 2, j + 2, k + 14, Blocks.air);
		world.setBlock(i + 2, j + 2, k + 15, Blocks.air);
		world.setBlock(i + 2, j + 2, k + 16, VetheaBlocks.cryptWall);
		world.setBlock(i + 2, j + 2, k + 17, VetheaBlocks.dreamDirt);
		world.setBlock(i + 2, j + 2, k + 18, VetheaBlocks.dreamDirt);
		world.setBlock(i + 2, j + 2, k + 19, VetheaBlocks.dreamDirt);
		world.setBlock(i + 2, j + 3, k + 0, VetheaBlocks.dreamDirt);
		world.setBlock(i + 2, j + 3, k + 1, VetheaBlocks.dreamDirt);
		world.setBlock(i + 2, j + 3, k + 2, VetheaBlocks.dreamDirt);
		world.setBlock(i + 2, j + 3, k + 3, VetheaBlocks.dreamDirt);
		world.setBlock(i + 2, j + 3, k + 4, VetheaBlocks.dreamDirt);
		world.setBlock(i + 2, j + 3, k + 5, VetheaBlocks.dreamDirt);
		world.setBlock(i + 2, j + 3, k + 6, VetheaBlocks.dreamDirt);
		world.setBlock(i + 2, j + 3, k + 7, VetheaBlocks.dreamDirt);
		world.setBlock(i + 2, j + 3, k + 8, VetheaBlocks.dreamDirt);
		world.setBlock(i + 2, j + 3, k + 9, VetheaBlocks.cryptWall);
		world.setBlock(i + 2, j + 3, k + 10, Blocks.air);
		world.setBlock(i + 2, j + 3, k + 11, Blocks.air);
		world.setBlock(i + 2, j + 3, k + 12, Blocks.air);
		world.setBlock(i + 2, j + 3, k + 13, Blocks.air);
		world.setBlock(i + 2, j + 3, k + 14, Blocks.air);
		world.setBlock(i + 2, j + 3, k + 15, Blocks.air);
		world.setBlock(i + 2, j + 3, k + 16, VetheaBlocks.cryptWall);
		world.setBlock(i + 2, j + 3, k + 17, VetheaBlocks.dreamDirt);
		world.setBlock(i + 2, j + 3, k + 18, VetheaBlocks.dreamDirt);
		world.setBlock(i + 2, j + 3, k + 19, VetheaBlocks.dreamDirt);
		world.setBlock(i + 2, j + 4, k + 0, VetheaBlocks.dreamDirt);
		world.setBlock(i + 2, j + 4, k + 1, VetheaBlocks.dreamDirt);
		world.setBlock(i + 2, j + 4, k + 2, VetheaBlocks.dreamDirt);
		world.setBlock(i + 2, j + 4, k + 3, VetheaBlocks.dreamDirt);
		world.setBlock(i + 2, j + 4, k + 4, VetheaBlocks.dreamDirt);
		world.setBlock(i + 2, j + 4, k + 5, VetheaBlocks.dreamDirt);
		world.setBlock(i + 2, j + 4, k + 6, VetheaBlocks.dreamDirt);
		world.setBlock(i + 2, j + 4, k + 7, VetheaBlocks.dreamDirt);
		world.setBlock(i + 2, j + 4, k + 8, VetheaBlocks.dreamDirt);
		world.setBlock(i + 2, j + 4, k + 9, VetheaBlocks.dreamDirt);
		world.setBlock(i + 2, j + 4, k + 10, VetheaBlocks.hungerstone2);
		world.setBlock(i + 2, j + 4, k + 11, VetheaBlocks.hungerstone2);
		world.setBlock(i + 2, j + 4, k + 12, VetheaBlocks.hungerstone2);
		world.setBlock(i + 2, j + 4, k + 13, VetheaBlocks.hungerstone2);
		world.setBlock(i + 2, j + 4, k + 14, VetheaBlocks.hungerstone2);
		world.setBlock(i + 2, j + 4, k + 15, VetheaBlocks.hungerstone2);
		world.setBlock(i + 2, j + 4, k + 16, VetheaBlocks.dreamDirt);
		world.setBlock(i + 2, j + 4, k + 17, VetheaBlocks.dreamDirt);
		world.setBlock(i + 2, j + 4, k + 18, VetheaBlocks.dreamDirt);
		world.setBlock(i + 2, j + 4, k + 19, VetheaBlocks.dreamDirt);
		world.setBlock(i + 2, j + 5, k + 0, VetheaBlocks.dreamDirt);
		world.setBlock(i + 2, j + 5, k + 1, VetheaBlocks.dreamDirt);
		world.setBlock(i + 2, j + 5, k + 2, VetheaBlocks.dreamDirt);
		world.setBlock(i + 2, j + 5, k + 3, VetheaBlocks.cryptWall);
		world.setBlock(i + 2, j + 5, k + 4, VetheaBlocks.cryptWall);
		world.setBlock(i + 2, j + 5, k + 5, VetheaBlocks.dreamDirt);
		world.setBlock(i + 2, j + 5, k + 6, VetheaBlocks.dreamDirt);
		world.setBlock(i + 2, j + 5, k + 7, VetheaBlocks.dreamDirt);
		world.setBlock(i + 2, j + 5, k + 8, VetheaBlocks.dreamDirt);
		world.setBlock(i + 2, j + 5, k + 9, VetheaBlocks.dreamDirt);
		world.setBlock(i + 2, j + 5, k + 10, VetheaBlocks.dreamDirt);
		world.setBlock(i + 2, j + 5, k + 11, VetheaBlocks.dreamDirt);
		world.setBlock(i + 2, j + 5, k + 12, VetheaBlocks.dreamDirt);
		world.setBlock(i + 2, j + 5, k + 13, VetheaBlocks.dreamDirt);
		world.setBlock(i + 2, j + 5, k + 14, VetheaBlocks.cryptWall);
		world.setBlock(i + 2, j + 5, k + 15, VetheaBlocks.cryptWall);
		world.setBlock(i + 2, j + 5, k + 16, VetheaBlocks.dreamDirt);
		world.setBlock(i + 2, j + 5, k + 17, VetheaBlocks.dreamDirt);
		world.setBlock(i + 2, j + 5, k + 18, VetheaBlocks.dreamDirt);
		world.setBlock(i + 2, j + 5, k + 19, VetheaBlocks.dreamDirt);
		world.setBlock(i + 2, j + 6, k + 0, VetheaBlocks.metalCaging);
		world.setBlock(i + 2, j + 6, k + 1, Blocks.air);
		world.setBlock(i + 2, j + 6, k + 2, Blocks.air);
		world.setBlock(i + 2, j + 6, k + 3, Blocks.air);
		world.setBlock(i + 2, j + 6, k + 4, Blocks.air);
		world.setBlock(i + 2, j + 6, k + 5, Blocks.air);
		world.setBlock(i + 2, j + 6, k + 6, Blocks.air);
		world.setBlock(i + 2, j + 6, k + 7, Blocks.air);
		world.setBlock(i + 2, j + 6, k + 8, Blocks.air);
		world.setBlock(i + 2, j + 6, k + 9, Blocks.air);
		world.setBlock(i + 2, j + 6, k + 10, Blocks.air);
		world.setBlock(i + 2, j + 6, k + 11, Blocks.air);
		world.setBlock(i + 2, j + 6, k + 12, Blocks.air);
		world.setBlock(i + 2, j + 6, k + 13, Blocks.air);
		world.setBlock(i + 2, j + 6, k + 14, Blocks.air);
		world.setBlock(i + 2, j + 6, k + 15, Blocks.air);
		world.setBlock(i + 2, j + 6, k + 16, Blocks.air);
		world.setBlock(i + 2, j + 6, k + 17, Blocks.air);
		world.setBlock(i + 2, j + 6, k + 18, Blocks.air);
		world.setBlock(i + 2, j + 6, k + 19, VetheaBlocks.metalCaging);
		world.setBlock(i + 2, j + 7, k + 0, VetheaBlocks.hungerstone1);
		world.setBlock(i + 2, j + 7, k + 1, Blocks.air);
		world.setBlock(i + 2, j + 7, k + 2, Blocks.air);
		world.setBlock(i + 2, j + 7, k + 3, Blocks.air);
		world.setBlock(i + 2, j + 7, k + 4, Blocks.air);
		world.setBlock(i + 2, j + 7, k + 5, Blocks.air);
		world.setBlock(i + 2, j + 7, k + 6, Blocks.air);
		world.setBlock(i + 2, j + 7, k + 7, Blocks.air);
		world.setBlock(i + 2, j + 7, k + 8, Blocks.air);
		world.setBlock(i + 2, j + 7, k + 9, Blocks.air);
		world.setBlock(i + 2, j + 7, k + 10, Blocks.air);
		world.setBlock(i + 2, j + 7, k + 11, Blocks.air);
		world.setBlock(i + 2, j + 7, k + 12, Blocks.air);
		world.setBlock(i + 2, j + 7, k + 13, Blocks.air);
		world.setBlock(i + 2, j + 7, k + 14, Blocks.air);
		world.setBlock(i + 2, j + 7, k + 15, Blocks.air);
		world.setBlock(i + 2, j + 7, k + 16, Blocks.air);
		world.setBlock(i + 2, j + 7, k + 17, Blocks.air);
		world.setBlock(i + 2, j + 7, k + 18, Blocks.air);
		world.setBlock(i + 2, j + 7, k + 19, VetheaBlocks.hungerstone1);
		world.setBlock(i + 2, j + 8, k + 0, Blocks.air);
		world.setBlock(i + 2, j + 8, k + 1, Blocks.air);
		world.setBlock(i + 2, j + 8, k + 2, Blocks.air);
		world.setBlock(i + 2, j + 8, k + 3, Blocks.air);
		world.setBlock(i + 2, j + 8, k + 4, Blocks.air);
		world.setBlock(i + 2, j + 8, k + 5, Blocks.air);
		world.setBlock(i + 2, j + 8, k + 6, Blocks.air);
		world.setBlock(i + 2, j + 8, k + 7, Blocks.air);
		world.setBlock(i + 2, j + 8, k + 8, Blocks.air);
		world.setBlock(i + 2, j + 8, k + 9, Blocks.air);
		world.setBlock(i + 2, j + 8, k + 10, Blocks.air);
		world.setBlock(i + 2, j + 8, k + 11, Blocks.air);
		world.setBlock(i + 2, j + 8, k + 12, Blocks.air);
		world.setBlock(i + 2, j + 8, k + 13, Blocks.air);
		world.setBlock(i + 2, j + 8, k + 14, Blocks.air);
		world.setBlock(i + 2, j + 8, k + 15, Blocks.air);
		world.setBlock(i + 2, j + 8, k + 16, Blocks.air);
		world.setBlock(i + 2, j + 8, k + 17, Blocks.air);
		world.setBlock(i + 2, j + 8, k + 18, Blocks.air);
		world.setBlock(i + 2, j + 8, k + 19, Blocks.air);
		world.setBlock(i + 2, j + 9, k + 0, Blocks.air);
		world.setBlock(i + 2, j + 9, k + 1, Blocks.air);
		world.setBlock(i + 2, j + 9, k + 2, Blocks.air);
		world.setBlock(i + 2, j + 9, k + 3, Blocks.air);
		world.setBlock(i + 2, j + 9, k + 4, Blocks.air);
		world.setBlock(i + 2, j + 9, k + 5, Blocks.air);
		world.setBlock(i + 2, j + 9, k + 6, Blocks.air);
		world.setBlock(i + 2, j + 9, k + 7, Blocks.air);
		world.setBlock(i + 2, j + 9, k + 8, Blocks.air);
		world.setBlock(i + 2, j + 9, k + 9, Blocks.air);
		world.setBlock(i + 2, j + 9, k + 10, Blocks.air);
		world.setBlock(i + 2, j + 9, k + 11, Blocks.air);
		world.setBlock(i + 2, j + 9, k + 12, Blocks.air);
		world.setBlock(i + 2, j + 9, k + 13, Blocks.air);
		world.setBlock(i + 2, j + 9, k + 14, Blocks.air);
		world.setBlock(i + 2, j + 9, k + 15, Blocks.air);
		world.setBlock(i + 2, j + 9, k + 16, Blocks.air);
		world.setBlock(i + 2, j + 9, k + 17, Blocks.air);
		world.setBlock(i + 2, j + 9, k + 18, Blocks.air);
		world.setBlock(i + 2, j + 9, k + 19, Blocks.air);
		world.setBlock(i + 2, j + 10, k + 0, Blocks.air);
		world.setBlock(i + 2, j + 10, k + 1, Blocks.air);
		world.setBlock(i + 2, j + 10, k + 2, Blocks.air);
		world.setBlock(i + 2, j + 10, k + 3, Blocks.air);
		world.setBlock(i + 2, j + 10, k + 4, Blocks.air);
		world.setBlock(i + 2, j + 10, k + 5, Blocks.air);
		world.setBlock(i + 2, j + 10, k + 6, Blocks.air);
		world.setBlock(i + 2, j + 10, k + 7, Blocks.air);
		world.setBlock(i + 2, j + 10, k + 8, Blocks.air);
		world.setBlock(i + 2, j + 10, k + 9, Blocks.air);
		world.setBlock(i + 2, j + 10, k + 10, Blocks.air);
		world.setBlock(i + 2, j + 10, k + 11, Blocks.air);
		world.setBlock(i + 2, j + 10, k + 12, Blocks.air);
		world.setBlock(i + 2, j + 10, k + 13, Blocks.air);
		world.setBlock(i + 2, j + 10, k + 14, Blocks.air);
		world.setBlock(i + 2, j + 10, k + 15, Blocks.air);
		world.setBlock(i + 2, j + 10, k + 16, Blocks.air);
		world.setBlock(i + 2, j + 10, k + 17, Blocks.air);
		world.setBlock(i + 2, j + 10, k + 18, Blocks.air);
		world.setBlock(i + 2, j + 10, k + 19, Blocks.air);
		world.setBlock(i + 3, j + 0, k + 0, VetheaBlocks.cryptWall);
		world.setBlock(i + 3, j + 0, k + 1, Blocks.air);
		world.setBlock(i + 3, j + 0, k + 2, Blocks.air);
		world.setBlock(i + 3, j + 0, k + 3, Blocks.air);
		world.setBlock(i + 3, j + 0, k + 4, Blocks.air);
		world.setBlock(i + 3, j + 0, k + 5, Blocks.air);
		world.setBlock(i + 3, j + 0, k + 6, Blocks.air);
		world.setBlock(i + 3, j + 0, k + 7, Blocks.air);
		world.setBlock(i + 3, j + 0, k + 8, Blocks.air);
		world.setBlock(i + 3, j + 0, k + 9, Blocks.air);
		world.setBlock(i + 3, j + 0, k + 10, Blocks.air);
		world.setBlock(i + 3, j + 0, k + 11, Blocks.air);
		world.setBlock(i + 3, j + 0, k + 12, Blocks.air);
		world.setBlock(i + 3, j + 0, k + 13, VetheaBlocks.cryptFloor);
		world.setBlock(i + 3, j + 0, k + 14, VetheaBlocks.cryptFloor);
		world.setBlock(i + 3, j + 0, k + 15, VetheaBlocks.cryptFloor);
		world.setBlock(i + 3, j + 0, k + 16, VetheaBlocks.dreamDirt);
		world.setBlock(i + 3, j + 0, k + 17, VetheaBlocks.dreamDirt);
		world.setBlock(i + 3, j + 0, k + 18, VetheaBlocks.dreamDirt);
		world.setBlock(i + 3, j + 0, k + 19, VetheaBlocks.dreamDirt);
		world.setBlock(i + 3, j + 1, k + 0, VetheaBlocks.cryptWall);
		world.setBlock(i + 3, j + 1, k + 1, Blocks.air);
		world.setBlock(i + 3, j + 1, k + 2, Blocks.air);
		world.setBlock(i + 3, j + 1, k + 3, Blocks.air);
		world.setBlock(i + 3, j + 1, k + 4, Blocks.air);
		world.setBlock(i + 3, j + 1, k + 5, Blocks.air);
		world.setBlock(i + 3, j + 1, k + 6, Blocks.air);
		world.setBlock(i + 3, j + 1, k + 7, Blocks.air);
		world.setBlock(i + 3, j + 1, k + 8, Blocks.air);
		world.setBlock(i + 3, j + 1, k + 9, Blocks.air);
		world.setBlock(i + 3, j + 1, k + 10, Blocks.air);
		world.setBlock(i + 3, j + 1, k + 11, Blocks.air);
		world.setBlock(i + 3, j + 1, k + 12, Blocks.air);
		world.setBlock(i + 3, j + 1, k + 13, Blocks.air);
		world.setBlock(i + 3, j + 1, k + 14, Blocks.air);
		world.setBlock(i + 3, j + 1, k + 15, Blocks.air);
		world.setBlock(i + 3, j + 1, k + 16, VetheaBlocks.cryptWall);
		world.setBlock(i + 3, j + 1, k + 17, VetheaBlocks.dreamDirt);
		world.setBlock(i + 3, j + 1, k + 18, VetheaBlocks.dreamDirt);
		world.setBlock(i + 3, j + 1, k + 19, VetheaBlocks.dreamDirt);
		world.setBlock(i + 3, j + 2, k + 0, VetheaBlocks.cryptWall);
		world.setBlock(i + 3, j + 2, k + 1, Blocks.air);
		world.setBlock(i + 3, j + 2, k + 2, Blocks.air);
		world.setBlock(i + 3, j + 2, k + 3, Blocks.air);
		world.setBlock(i + 3, j + 2, k + 4, Blocks.air);
		world.setBlock(i + 3, j + 2, k + 5, Blocks.air);
		world.setBlock(i + 3, j + 2, k + 6, Blocks.air);
		world.setBlock(i + 3, j + 2, k + 7, Blocks.air);
		world.setBlock(i + 3, j + 2, k + 8, Blocks.air);
		world.setBlock(i + 3, j + 2, k + 9, Blocks.air);
		world.setBlock(i + 3, j + 2, k + 10, Blocks.air);
		world.setBlock(i + 3, j + 2, k + 11, Blocks.air);
		world.setBlock(i + 3, j + 2, k + 12, Blocks.air);
		world.setBlock(i + 3, j + 2, k + 13, Blocks.air);
		world.setBlock(i + 3, j + 2, k + 14, Blocks.air);
		world.setBlock(i + 3, j + 2, k + 15, Blocks.air);
		world.setBlock(i + 3, j + 2, k + 16, VetheaBlocks.cryptWall);
		world.setBlock(i + 3, j + 2, k + 17, VetheaBlocks.dreamDirt);
		world.setBlock(i + 3, j + 2, k + 18, VetheaBlocks.dreamDirt);
		world.setBlock(i + 3, j + 2, k + 19, VetheaBlocks.dreamDirt);
		world.setBlock(i + 3, j + 3, k + 0, VetheaBlocks.dreamDirt);
		world.setBlock(i + 3, j + 3, k + 1, VetheaBlocks.hungerstone2);
		world.setBlock(i + 3, j + 3, k + 2, VetheaBlocks.hungerstone2);
		world.setBlock(i + 3, j + 3, k + 3, VetheaBlocks.hungerstone2);
		world.setBlock(i + 3, j + 3, k + 4, VetheaBlocks.hungerstone2);
		world.setBlock(i + 3, j + 3, k + 5, VetheaBlocks.hungerstone2);
		world.setBlock(i + 3, j + 3, k + 6, VetheaBlocks.hungerstone2);
		world.setBlock(i + 3, j + 3, k + 7, VetheaBlocks.hungerstone2);
		world.setBlock(i + 3, j + 3, k + 8, VetheaBlocks.hungerstone2);
		world.setBlock(i + 3, j + 3, k + 9, VetheaBlocks.cryptWall);
		world.setBlock(i + 3, j + 3, k + 10, Blocks.air);
		world.setBlock(i + 3, j + 3, k + 11, Blocks.air);
		world.setBlock(i + 3, j + 3, k + 12, Blocks.air);
		world.setBlock(i + 3, j + 3, k + 13, Blocks.air);
		world.setBlock(i + 3, j + 3, k + 14, Blocks.air);
		world.setBlock(i + 3, j + 3, k + 15, Blocks.air);
		world.setBlock(i + 3, j + 3, k + 16, VetheaBlocks.cryptWall);
		world.setBlock(i + 3, j + 3, k + 17, VetheaBlocks.dreamDirt);
		world.setBlock(i + 3, j + 3, k + 18, VetheaBlocks.dreamDirt);
		world.setBlock(i + 3, j + 3, k + 19, VetheaBlocks.dreamDirt);
		world.setBlock(i + 3, j + 4, k + 0, VetheaBlocks.dreamDirt);
		world.setBlock(i + 3, j + 4, k + 1, VetheaBlocks.dreamDirt);
		world.setBlock(i + 3, j + 4, k + 2, VetheaBlocks.dreamDirt);
		world.setBlock(i + 3, j + 4, k + 3, VetheaBlocks.dreamDirt);
		world.setBlock(i + 3, j + 4, k + 4, VetheaBlocks.dreamDirt);
		world.setBlock(i + 3, j + 4, k + 5, VetheaBlocks.dreamDirt);
		world.setBlock(i + 3, j + 4, k + 6, VetheaBlocks.dreamDirt);
		world.setBlock(i + 3, j + 4, k + 7, Blocks.air);
		world.setBlock(i + 3, j + 4, k + 8, VetheaBlocks.dreamDirt);
		world.setBlock(i + 3, j + 4, k + 9, VetheaBlocks.dreamDirt);
		world.setBlock(i + 3, j + 4, k + 10, VetheaBlocks.hungerstone2);
		world.setBlock(i + 3, j + 4, k + 11, VetheaBlocks.hungerstone2);
		world.setBlock(i + 3, j + 4, k + 12, VetheaBlocks.hungerstone2);
		world.setBlock(i + 3, j + 4, k + 13, VetheaBlocks.hungerstone2);
		world.setBlock(i + 3, j + 4, k + 14, VetheaBlocks.hungerstone2);
		world.setBlock(i + 3, j + 4, k + 15, VetheaBlocks.hungerstone2);
		world.setBlock(i + 3, j + 4, k + 16, VetheaBlocks.dreamDirt);
		world.setBlock(i + 3, j + 4, k + 17, VetheaBlocks.dreamDirt);
		world.setBlock(i + 3, j + 4, k + 18, VetheaBlocks.dreamDirt);
		world.setBlock(i + 3, j + 4, k + 19, VetheaBlocks.dreamDirt);
		world.setBlock(i + 3, j + 5, k + 0, VetheaBlocks.dreamDirt);
		world.setBlock(i + 3, j + 5, k + 1, VetheaBlocks.dreamDirt);
		world.setBlock(i + 3, j + 5, k + 2, VetheaBlocks.dreamDirt);
		world.setBlock(i + 3, j + 5, k + 3, VetheaBlocks.cryptWall);
		world.setBlock(i + 3, j + 5, k + 4, VetheaBlocks.cryptWall);
		world.setBlock(i + 3, j + 5, k + 5, VetheaBlocks.dreamDirt);
		world.setBlock(i + 3, j + 5, k + 6, VetheaBlocks.dreamDirt);
		world.setBlock(i + 3, j + 5, k + 7, VetheaBlocks.dreamDirt);
		world.setBlock(i + 3, j + 5, k + 8, VetheaBlocks.dreamDirt);
		world.setBlock(i + 3, j + 5, k + 9, VetheaBlocks.dreamDirt);
		world.setBlock(i + 3, j + 5, k + 10, VetheaBlocks.dreamDirt);
		world.setBlock(i + 3, j + 5, k + 11, VetheaBlocks.dreamDirt);
		world.setBlock(i + 3, j + 5, k + 12, VetheaBlocks.dreamDirt);
		world.setBlock(i + 3, j + 5, k + 13, VetheaBlocks.dreamDirt);
		world.setBlock(i + 3, j + 5, k + 14, VetheaBlocks.cryptWall);
		world.setBlock(i + 3, j + 5, k + 15, VetheaBlocks.cryptWall);
		world.setBlock(i + 3, j + 5, k + 16, VetheaBlocks.dreamDirt);
		world.setBlock(i + 3, j + 5, k + 17, VetheaBlocks.dreamDirt);
		world.setBlock(i + 3, j + 5, k + 18, VetheaBlocks.dreamDirt);
		world.setBlock(i + 3, j + 5, k + 19, VetheaBlocks.dreamDirt);
		world.setBlock(i + 3, j + 6, k + 0, VetheaBlocks.metalCaging);
		world.setBlock(i + 3, j + 6, k + 1, Blocks.air);
		world.setBlock(i + 3, j + 6, k + 2, Blocks.air);
		world.setBlock(i + 3, j + 6, k + 3, Blocks.air);
		world.setBlock(i + 3, j + 6, k + 4, Blocks.air);
		world.setBlock(i + 3, j + 6, k + 5, Blocks.air);
		world.setBlock(i + 3, j + 6, k + 6, Blocks.air);
		world.setBlock(i + 3, j + 6, k + 7, Blocks.air);
		world.setBlock(i + 3, j + 6, k + 8, Blocks.air);
		world.setBlock(i + 3, j + 6, k + 9, Blocks.air);
		world.setBlock(i + 3, j + 6, k + 10, Blocks.air);
		world.setBlock(i + 3, j + 6, k + 11, VetheaBlocks.hungerstone1);
		world.setBlock(i + 3, j + 6, k + 12, VetheaBlocks.hungerstone1);
		world.setBlock(i + 3, j + 6, k + 13, VetheaBlocks.hungerstone1);
		world.setBlock(i + 3, j + 6, k + 14, Blocks.air);
		world.setBlock(i + 3, j + 6, k + 15, Blocks.air);
		world.setBlock(i + 3, j + 6, k + 16, Blocks.air);
		world.setBlock(i + 3, j + 6, k + 17, Blocks.air);
		world.setBlock(i + 3, j + 6, k + 18, Blocks.air);
		world.setBlock(i + 3, j + 6, k + 19, VetheaBlocks.metalCaging);
		world.setBlock(i + 3, j + 7, k + 0, VetheaBlocks.hungerstone1);
		world.setBlock(i + 3, j + 7, k + 1, Blocks.air);
		world.setBlock(i + 3, j + 7, k + 2, Blocks.air);
		world.setBlock(i + 3, j + 7, k + 3, Blocks.air);
		world.setBlock(i + 3, j + 7, k + 4, Blocks.air);
		world.setBlock(i + 3, j + 7, k + 5, Blocks.air);
		world.setBlock(i + 3, j + 7, k + 6, Blocks.air);
		world.setBlock(i + 3, j + 7, k + 7, Blocks.air);
		world.setBlock(i + 3, j + 7, k + 8, Blocks.air);
		world.setBlock(i + 3, j + 7, k + 9, Blocks.air);
		world.setBlock(i + 3, j + 7, k + 10, Blocks.air);
		world.setBlock(i + 3, j + 7, k + 11, Blocks.air);
		world.setBlock(i + 3, j + 7, k + 12, Blocks.air);
		world.setBlock(i + 3, j + 7, k + 13, Blocks.air);
		world.setBlock(i + 3, j + 7, k + 14, Blocks.air);
		world.setBlock(i + 3, j + 7, k + 15, Blocks.air);
		world.setBlock(i + 3, j + 7, k + 16, Blocks.air);
		world.setBlock(i + 3, j + 7, k + 17, Blocks.air);
		world.setBlock(i + 3, j + 7, k + 18, Blocks.air);
		world.setBlock(i + 3, j + 7, k + 19, VetheaBlocks.hungerstone1);
		world.setBlock(i + 3, j + 8, k + 0, Blocks.air);
		world.setBlock(i + 3, j + 8, k + 1, Blocks.air);
		world.setBlock(i + 3, j + 8, k + 2, Blocks.air);
		world.setBlock(i + 3, j + 8, k + 3, Blocks.air);
		world.setBlock(i + 3, j + 8, k + 4, Blocks.air);
		world.setBlock(i + 3, j + 8, k + 5, Blocks.air);
		world.setBlock(i + 3, j + 8, k + 6, Blocks.air);
		world.setBlock(i + 3, j + 8, k + 7, Blocks.air);
		world.setBlock(i + 3, j + 8, k + 8, Blocks.air);
		world.setBlock(i + 3, j + 8, k + 9, Blocks.air);
		world.setBlock(i + 3, j + 8, k + 10, Blocks.air);
		world.setBlock(i + 3, j + 8, k + 11, Blocks.air);
		world.setBlock(i + 3, j + 8, k + 12, Blocks.air);
		world.setBlock(i + 3, j + 8, k + 13, Blocks.air);
		world.setBlock(i + 3, j + 8, k + 14, Blocks.air);
		world.setBlock(i + 3, j + 8, k + 15, Blocks.air);
		world.setBlock(i + 3, j + 8, k + 16, Blocks.air);
		world.setBlock(i + 3, j + 8, k + 17, Blocks.air);
		world.setBlock(i + 3, j + 8, k + 18, Blocks.air);
		world.setBlock(i + 3, j + 8, k + 19, Blocks.air);
		world.setBlock(i + 3, j + 9, k + 0, Blocks.air);
		world.setBlock(i + 3, j + 9, k + 1, Blocks.air);
		world.setBlock(i + 3, j + 9, k + 2, Blocks.air);
		world.setBlock(i + 3, j + 9, k + 3, Blocks.air);
		world.setBlock(i + 3, j + 9, k + 4, Blocks.air);
		world.setBlock(i + 3, j + 9, k + 5, Blocks.air);
		world.setBlock(i + 3, j + 9, k + 6, Blocks.air);
		world.setBlock(i + 3, j + 9, k + 7, Blocks.air);
		world.setBlock(i + 3, j + 9, k + 8, Blocks.air);
		world.setBlock(i + 3, j + 9, k + 9, Blocks.air);
		world.setBlock(i + 3, j + 9, k + 10, Blocks.air);
		world.setBlock(i + 3, j + 9, k + 11, Blocks.air);
		world.setBlock(i + 3, j + 9, k + 12, Blocks.air);
		world.setBlock(i + 3, j + 9, k + 13, Blocks.air);
		world.setBlock(i + 3, j + 9, k + 14, Blocks.air);
		world.setBlock(i + 3, j + 9, k + 15, Blocks.air);
		world.setBlock(i + 3, j + 9, k + 16, Blocks.air);
		world.setBlock(i + 3, j + 9, k + 17, Blocks.air);
		world.setBlock(i + 3, j + 9, k + 18, Blocks.air);
		world.setBlock(i + 3, j + 9, k + 19, Blocks.air);
		world.setBlock(i + 3, j + 10, k + 0, Blocks.air);
		world.setBlock(i + 3, j + 10, k + 1, Blocks.air);
		world.setBlock(i + 3, j + 10, k + 2, Blocks.air);
		world.setBlock(i + 3, j + 10, k + 3, Blocks.air);
		world.setBlock(i + 3, j + 10, k + 4, Blocks.air);
		world.setBlock(i + 3, j + 10, k + 5, Blocks.air);
		world.setBlock(i + 3, j + 10, k + 6, Blocks.air);
		world.setBlock(i + 3, j + 10, k + 7, Blocks.air);
		world.setBlock(i + 3, j + 10, k + 8, Blocks.air);
		world.setBlock(i + 3, j + 10, k + 9, Blocks.air);
		world.setBlock(i + 3, j + 10, k + 10, Blocks.air);
		world.setBlock(i + 3, j + 10, k + 11, Blocks.air);
		world.setBlock(i + 3, j + 10, k + 12, Blocks.air);
		world.setBlock(i + 3, j + 10, k + 13, Blocks.air);
		world.setBlock(i + 3, j + 10, k + 14, Blocks.air);
		world.setBlock(i + 3, j + 10, k + 15, Blocks.air);
		world.setBlock(i + 3, j + 10, k + 16, Blocks.air);
		world.setBlock(i + 3, j + 10, k + 17, Blocks.air);
		world.setBlock(i + 3, j + 10, k + 18, Blocks.air);
		world.setBlock(i + 3, j + 10, k + 19, Blocks.air);
		world.setBlock(i + 4, j + 0, k + 0, VetheaBlocks.cryptWall);
		world.setBlock(i + 4, j + 0, k + 1, Blocks.air);
		world.setBlock(i + 4, j + 0, k + 2, VetheaBlocks.cryptWall);
		world.setBlock(i + 4, j + 0, k + 3, VetheaBlocks.cryptWall);
		world.setBlock(i + 4, j + 0, k + 4, VetheaBlocks.cryptWall);
		world.setBlock(i + 4, j + 0, k + 5, VetheaBlocks.cryptWall);
		world.setBlock(i + 4, j + 0, k + 6, VetheaBlocks.cryptWall);
		world.setBlock(i + 4, j + 0, k + 7, VetheaBlocks.cryptWall);
		world.setBlock(i + 4, j + 0, k + 8, VetheaBlocks.cryptWall);
		world.setBlock(i + 4, j + 0, k + 9, VetheaBlocks.cryptWall);
		world.setBlock(i + 4, j + 0, k + 10, Blocks.air);
		world.setBlock(i + 4, j + 0, k + 11, Blocks.air);
		world.setBlock(i + 4, j + 0, k + 12, Blocks.air);
		world.setBlock(i + 4, j + 0, k + 13, VetheaBlocks.cryptFloor);
		world.setBlock(i + 4, j + 0, k + 14, VetheaBlocks.cryptFloor);
		world.setBlock(i + 4, j + 0, k + 15, VetheaBlocks.cryptFloor);
		world.setBlock(i + 4, j + 0, k + 16, VetheaBlocks.dreamDirt);
		world.setBlock(i + 4, j + 0, k + 17, VetheaBlocks.dreamDirt);
		world.setBlock(i + 4, j + 0, k + 18, VetheaBlocks.dreamDirt);
		world.setBlock(i + 4, j + 0, k + 19, VetheaBlocks.dreamDirt);
		world.setBlock(i + 4, j + 1, k + 0, VetheaBlocks.cryptWall);
		world.setBlock(i + 4, j + 1, k + 1, Blocks.air);
		world.setBlock(i + 4, j + 1, k + 2, VetheaBlocks.cryptWall);
		world.setBlock(i + 4, j + 1, k + 3, VetheaBlocks.cryptWall);
		world.setBlock(i + 4, j + 1, k + 4, VetheaBlocks.cryptWall);
		world.setBlock(i + 4, j + 1, k + 5, VetheaBlocks.cryptWall);
		world.setBlock(i + 4, j + 1, k + 6, VetheaBlocks.cryptWall);
		world.setBlock(i + 4, j + 1, k + 7, VetheaBlocks.cryptWall);
		world.setBlock(i + 4, j + 1, k + 8, VetheaBlocks.cryptWall);
		world.setBlock(i + 4, j + 1, k + 9, VetheaBlocks.cryptWall);
		world.setBlock(i + 4, j + 1, k + 10, Blocks.air);
		world.setBlock(i + 4, j + 1, k + 11, Blocks.air);
		world.setBlock(i + 4, j + 1, k + 12, Blocks.air);
		world.setBlock(i + 4, j + 1, k + 13, Blocks.air);
		world.setBlock(i + 4, j + 1, k + 14, Blocks.air);
		world.setBlock(i + 4, j + 1, k + 15, Blocks.air);
		world.setBlock(i + 4, j + 1, k + 16, VetheaBlocks.cryptWall);
		world.setBlock(i + 4, j + 1, k + 17, VetheaBlocks.dreamDirt);
		world.setBlock(i + 4, j + 1, k + 18, VetheaBlocks.dreamDirt);
		world.setBlock(i + 4, j + 1, k + 19, VetheaBlocks.dreamDirt);
		world.setBlock(i + 4, j + 2, k + 0, VetheaBlocks.cryptWall);
		world.setBlock(i + 4, j + 2, k + 1, Blocks.air);
		world.setBlock(i + 4, j + 2, k + 2, VetheaBlocks.cryptWall);
		world.setBlock(i + 4, j + 2, k + 3, VetheaBlocks.cryptWall);
		world.setBlock(i + 4, j + 2, k + 4, VetheaBlocks.cryptWall);
		world.setBlock(i + 4, j + 2, k + 5, VetheaBlocks.cryptWall);
		world.setBlock(i + 4, j + 2, k + 6, VetheaBlocks.cryptWall);
		world.setBlock(i + 4, j + 2, k + 7, VetheaBlocks.cryptWall);
		world.setBlock(i + 4, j + 2, k + 8, VetheaBlocks.cryptWall);
		world.setBlock(i + 4, j + 2, k + 9, VetheaBlocks.cryptWall);
		world.setBlock(i + 4, j + 2, k + 10, Blocks.air);
		world.setBlock(i + 4, j + 2, k + 11, Blocks.air);
		world.setBlock(i + 4, j + 2, k + 12, Blocks.air);
		world.setBlock(i + 4, j + 2, k + 13, Blocks.air);
		world.setBlock(i + 4, j + 2, k + 14, Blocks.air);
		world.setBlock(i + 4, j + 2, k + 15, Blocks.air);
		world.setBlock(i + 4, j + 2, k + 16, VetheaBlocks.cryptWall);
		world.setBlock(i + 4, j + 2, k + 17, VetheaBlocks.dreamDirt);
		world.setBlock(i + 4, j + 2, k + 18, VetheaBlocks.dreamDirt);
		world.setBlock(i + 4, j + 2, k + 19, VetheaBlocks.dreamDirt);
		world.setBlock(i + 4, j + 3, k + 0, VetheaBlocks.dreamDirt);
		world.setBlock(i + 4, j + 3, k + 1, VetheaBlocks.hungerstone2);
		world.setBlock(i + 4, j + 3, k + 2, VetheaBlocks.dreamDirt);
		world.setBlock(i + 4, j + 3, k + 3, VetheaBlocks.dreamDirt);
		world.setBlock(i + 4, j + 3, k + 4, VetheaBlocks.dreamDirt);
		world.setBlock(i + 4, j + 3, k + 5, VetheaBlocks.dreamDirt);
		world.setBlock(i + 4, j + 3, k + 6, VetheaBlocks.dreamDirt);
		world.setBlock(i + 4, j + 3, k + 7, VetheaBlocks.dreamDirt);
		world.setBlock(i + 4, j + 3, k + 8, VetheaBlocks.dreamDirt);
		world.setBlock(i + 4, j + 3, k + 9, VetheaBlocks.cryptWall);
		world.setBlock(i + 4, j + 3, k + 10, Blocks.air);
		world.setBlock(i + 4, j + 3, k + 11, Blocks.air);
		world.setBlock(i + 4, j + 3, k + 12, Blocks.air);
		world.setBlock(i + 4, j + 3, k + 13, Blocks.air);
		world.setBlock(i + 4, j + 3, k + 14, Blocks.air);
		world.setBlock(i + 4, j + 3, k + 15, Blocks.air);
		world.setBlock(i + 4, j + 3, k + 16, VetheaBlocks.cryptWall);
		world.setBlock(i + 4, j + 3, k + 17, VetheaBlocks.dreamDirt);
		world.setBlock(i + 4, j + 3, k + 18, VetheaBlocks.dreamDirt);
		world.setBlock(i + 4, j + 3, k + 19, VetheaBlocks.dreamDirt);
		world.setBlock(i + 4, j + 4, k + 0, VetheaBlocks.dreamDirt);
		world.setBlock(i + 4, j + 4, k + 1, VetheaBlocks.dreamDirt);
		world.setBlock(i + 4, j + 4, k + 2, VetheaBlocks.dreamDirt);
		world.setBlock(i + 4, j + 4, k + 3, VetheaBlocks.dreamDirt);
		world.setBlock(i + 4, j + 4, k + 4, VetheaBlocks.dreamDirt);
		world.setBlock(i + 4, j + 4, k + 5, VetheaBlocks.dreamDirt);
		world.setBlock(i + 4, j + 4, k + 6, VetheaBlocks.dreamDirt);
		world.setBlock(i + 4, j + 4, k + 7, VetheaBlocks.dreamDirt);
		world.setBlock(i + 4, j + 4, k + 8, VetheaBlocks.dreamDirt);
		world.setBlock(i + 4, j + 4, k + 9, VetheaBlocks.dreamDirt);
		world.setBlock(i + 4, j + 4, k + 10, VetheaBlocks.hungerstone2);
		world.setBlock(i + 4, j + 4, k + 11, VetheaBlocks.hungerstone2);
		world.setBlock(i + 4, j + 4, k + 12, VetheaBlocks.hungerstone2);
		world.setBlock(i + 4, j + 4, k + 13, VetheaBlocks.hungerstone2);
		world.setBlock(i + 4, j + 4, k + 14, VetheaBlocks.hungerstone2);
		world.setBlock(i + 4, j + 4, k + 15, VetheaBlocks.hungerstone2);
		world.setBlock(i + 4, j + 4, k + 16, VetheaBlocks.dreamDirt);
		world.setBlock(i + 4, j + 4, k + 17, VetheaBlocks.dreamDirt);
		world.setBlock(i + 4, j + 4, k + 18, VetheaBlocks.dreamDirt);
		world.setBlock(i + 4, j + 4, k + 19, VetheaBlocks.dreamDirt);
		world.setBlock(i + 4, j + 5, k + 0, VetheaBlocks.dreamDirt);
		world.setBlock(i + 4, j + 5, k + 1, VetheaBlocks.dreamDirt);
		world.setBlock(i + 4, j + 5, k + 2, VetheaBlocks.dreamDirt);
		world.setBlock(i + 4, j + 5, k + 3, VetheaBlocks.cryptWall);
		world.setBlock(i + 4, j + 5, k + 4, VetheaBlocks.cryptWall);
		world.setBlock(i + 4, j + 5, k + 5, VetheaBlocks.dreamDirt);
		world.setBlock(i + 4, j + 5, k + 6, VetheaBlocks.dreamDirt);
		world.setBlock(i + 4, j + 5, k + 7, VetheaBlocks.dreamDirt);
		world.setBlock(i + 4, j + 5, k + 8, VetheaBlocks.dreamDirt);
		world.setBlock(i + 4, j + 5, k + 9, VetheaBlocks.dreamDirt);
		world.setBlock(i + 4, j + 5, k + 10, VetheaBlocks.dreamDirt);
		world.setBlock(i + 4, j + 5, k + 11, VetheaBlocks.dreamDirt);
		world.setBlock(i + 4, j + 5, k + 12, VetheaBlocks.dreamDirt);
		world.setBlock(i + 4, j + 5, k + 13, VetheaBlocks.dreamDirt);
		world.setBlock(i + 4, j + 5, k + 14, VetheaBlocks.cryptWall);
		world.setBlock(i + 4, j + 5, k + 15, VetheaBlocks.cryptWall);
		world.setBlock(i + 4, j + 5, k + 16, VetheaBlocks.dreamDirt);
		world.setBlock(i + 4, j + 5, k + 17, VetheaBlocks.dreamDirt);
		world.setBlock(i + 4, j + 5, k + 18, VetheaBlocks.dreamDirt);
		world.setBlock(i + 4, j + 5, k + 19, VetheaBlocks.dreamDirt);
		world.setBlock(i + 4, j + 6, k + 0, VetheaBlocks.metalCaging);
		world.setBlock(i + 4, j + 6, k + 1, Blocks.air);
		world.setBlock(i + 4, j + 6, k + 2, Blocks.air);
		world.setBlock(i + 4, j + 6, k + 3, Blocks.air);
		world.setBlock(i + 4, j + 6, k + 4, Blocks.air);
		world.setBlock(i + 4, j + 6, k + 5, Blocks.air);
		world.setBlock(i + 4, j + 6, k + 6, Blocks.air);
		world.setBlock(i + 4, j + 6, k + 7, Blocks.air);
		world.setBlock(i + 4, j + 6, k + 8, Blocks.air);
		world.setBlock(i + 4, j + 6, k + 9, Blocks.air);
		world.setBlock(i + 4, j + 6, k + 10, Blocks.air);
		world.setBlock(i + 4, j + 6, k + 11, VetheaBlocks.hungerstone1);
		world.setBlock(i + 4, j + 6, k + 12, VetheaBlocks.hungerstone1);
		world.setBlock(i + 4, j + 6, k + 13, VetheaBlocks.hungerstone1);
		world.setBlock(i + 4, j + 6, k + 14, Blocks.air);
		world.setBlock(i + 4, j + 6, k + 15, Blocks.air);
		world.setBlock(i + 4, j + 6, k + 16, Blocks.air);
		world.setBlock(i + 4, j + 6, k + 17, Blocks.air);
		world.setBlock(i + 4, j + 6, k + 18, Blocks.air);
		world.setBlock(i + 4, j + 6, k + 19, VetheaBlocks.metalCaging);
		world.setBlock(i + 4, j + 7, k + 0, VetheaBlocks.hungerstone1);
		world.setBlock(i + 4, j + 7, k + 1, Blocks.air);
		world.setBlock(i + 4, j + 7, k + 2, Blocks.air);
		world.setBlock(i + 4, j + 7, k + 3, Blocks.air);
		world.setBlock(i + 4, j + 7, k + 4, Blocks.air);
		world.setBlock(i + 4, j + 7, k + 5, Blocks.air);
		world.setBlock(i + 4, j + 7, k + 6, Blocks.air);
		world.setBlock(i + 4, j + 7, k + 7, Blocks.air);
		world.setBlock(i + 4, j + 7, k + 8, Blocks.air);
		world.setBlock(i + 4, j + 7, k + 9, Blocks.air);
		world.setBlock(i + 4, j + 7, k + 10, Blocks.air);
		world.setBlock(i + 4, j + 7, k + 11, Blocks.air);
		world.setBlock(i + 4, j + 7, k + 12, VetheaBlocks.hungerstone1);
		world.setBlock(i + 4, j + 7, k + 13, Blocks.air);
		world.setBlock(i + 4, j + 7, k + 14, Blocks.air);
		world.setBlock(i + 4, j + 7, k + 15, Blocks.air);
		world.setBlock(i + 4, j + 7, k + 16, Blocks.air);
		world.setBlock(i + 4, j + 7, k + 17, Blocks.air);
		world.setBlock(i + 4, j + 7, k + 18, Blocks.air);
		world.setBlock(i + 4, j + 7, k + 19, VetheaBlocks.hungerstone1);
		world.setBlock(i + 4, j + 8, k + 0, Blocks.air);
		world.setBlock(i + 4, j + 8, k + 1, Blocks.air);
		world.setBlock(i + 4, j + 8, k + 2, Blocks.air);
		world.setBlock(i + 4, j + 8, k + 3, Blocks.air);
		world.setBlock(i + 4, j + 8, k + 4, Blocks.air);
		world.setBlock(i + 4, j + 8, k + 5, Blocks.air);
		world.setBlock(i + 4, j + 8, k + 6, Blocks.air);
		world.setBlock(i + 4, j + 8, k + 7, Blocks.air);
		world.setBlock(i + 4, j + 8, k + 8, Blocks.air);
		world.setBlock(i + 4, j + 8, k + 9, Blocks.air);
		world.setBlock(i + 4, j + 8, k + 10, Blocks.air);
		world.setBlock(i + 4, j + 8, k + 11, Blocks.air);
		world.setBlock(i + 4, j + 8, k + 12, VetheaBlocks.fireCrystal);
		world.setBlock(i + 4, j + 8, k + 13, Blocks.air);
		world.setBlock(i + 4, j + 8, k + 14, Blocks.air);
		world.setBlock(i + 4, j + 8, k + 15, Blocks.air);
		world.setBlock(i + 4, j + 8, k + 16, Blocks.air);
		world.setBlock(i + 4, j + 8, k + 17, Blocks.air);
		world.setBlock(i + 4, j + 8, k + 18, Blocks.air);
		world.setBlock(i + 4, j + 8, k + 19, Blocks.air);
		world.setBlock(i + 4, j + 9, k + 0, Blocks.air);
		world.setBlock(i + 4, j + 9, k + 1, Blocks.air);
		world.setBlock(i + 4, j + 9, k + 2, Blocks.air);
		world.setBlock(i + 4, j + 9, k + 3, Blocks.air);
		world.setBlock(i + 4, j + 9, k + 4, Blocks.air);
		world.setBlock(i + 4, j + 9, k + 5, Blocks.air);
		world.setBlock(i + 4, j + 9, k + 6, Blocks.air);
		world.setBlock(i + 4, j + 9, k + 7, Blocks.air);
		world.setBlock(i + 4, j + 9, k + 8, Blocks.air);
		world.setBlock(i + 4, j + 9, k + 9, Blocks.air);
		world.setBlock(i + 4, j + 9, k + 10, Blocks.air);
		world.setBlock(i + 4, j + 9, k + 11, Blocks.air);
		world.setBlock(i + 4, j + 9, k + 12, Blocks.air);
		world.setBlock(i + 4, j + 9, k + 13, Blocks.air);
		world.setBlock(i + 4, j + 9, k + 14, Blocks.air);
		world.setBlock(i + 4, j + 9, k + 15, Blocks.air);
		world.setBlock(i + 4, j + 9, k + 16, Blocks.air);
		world.setBlock(i + 4, j + 9, k + 17, Blocks.air);
		world.setBlock(i + 4, j + 9, k + 18, Blocks.air);
		world.setBlock(i + 4, j + 9, k + 19, Blocks.air);
		world.setBlock(i + 4, j + 10, k + 0, Blocks.air);
		world.setBlock(i + 4, j + 10, k + 1, Blocks.air);
		world.setBlock(i + 4, j + 10, k + 2, Blocks.air);
		world.setBlock(i + 4, j + 10, k + 3, Blocks.air);
		world.setBlock(i + 4, j + 10, k + 4, Blocks.air);
		world.setBlock(i + 4, j + 10, k + 5, Blocks.air);
		world.setBlock(i + 4, j + 10, k + 6, Blocks.air);
		world.setBlock(i + 4, j + 10, k + 7, Blocks.air);
		world.setBlock(i + 4, j + 10, k + 8, Blocks.air);
		world.setBlock(i + 4, j + 10, k + 9, Blocks.air);
		world.setBlock(i + 4, j + 10, k + 10, Blocks.air);
		world.setBlock(i + 4, j + 10, k + 11, Blocks.air);
		world.setBlock(i + 4, j + 10, k + 12, Blocks.air);
		world.setBlock(i + 4, j + 10, k + 13, Blocks.air);
		world.setBlock(i + 4, j + 10, k + 14, Blocks.air);
		world.setBlock(i + 4, j + 10, k + 15, Blocks.air);
		world.setBlock(i + 4, j + 10, k + 16, Blocks.air);
		world.setBlock(i + 4, j + 10, k + 17, Blocks.air);
		world.setBlock(i + 4, j + 10, k + 18, Blocks.air);
		world.setBlock(i + 4, j + 10, k + 19, Blocks.air);
		world.setBlock(i + 5, j + 0, k + 0, VetheaBlocks.cryptWall);
		world.setBlock(i + 5, j + 0, k + 1, Blocks.air);
		world.setBlock(i + 5, j + 0, k + 2, VetheaBlocks.cryptWall);
		world.setBlock(i + 5, j + 0, k + 3, VetheaBlocks.dreamDirt);
		world.setBlock(i + 5, j + 0, k + 4, VetheaBlocks.dreamDirt);
		world.setBlock(i + 5, j + 0, k + 5, VetheaBlocks.dreamDirt);
		world.setBlock(i + 5, j + 0, k + 6, VetheaBlocks.dreamDirt);
		world.setBlock(i + 5, j + 0, k + 7, VetheaBlocks.dreamDirt);
		world.setBlock(i + 5, j + 0, k + 8, VetheaBlocks.dreamDirt);
		world.setBlock(i + 5, j + 0, k + 9, VetheaBlocks.dreamDirt);
		world.setBlock(i + 5, j + 0, k + 10, VetheaBlocks.cryptFloor);
		world.setBlock(i + 5, j + 0, k + 11, VetheaBlocks.cryptFloor);
		world.setBlock(i + 5, j + 0, k + 12, VetheaBlocks.cryptFloor);
		world.setBlock(i + 5, j + 0, k + 13, VetheaBlocks.cryptFloor);
		world.setBlock(i + 5, j + 0, k + 14, VetheaBlocks.cryptFloor);
		world.setBlock(i + 5, j + 0, k + 15, VetheaBlocks.cryptFloor);
		world.setBlock(i + 5, j + 0, k + 16, VetheaBlocks.dreamDirt);
		world.setBlock(i + 5, j + 0, k + 17, VetheaBlocks.dreamDirt);
		world.setBlock(i + 5, j + 0, k + 18, VetheaBlocks.dreamDirt);
		world.setBlock(i + 5, j + 0, k + 19, VetheaBlocks.dreamDirt);
		world.setBlock(i + 5, j + 1, k + 0, VetheaBlocks.cryptWall);
		world.setBlock(i + 5, j + 1, k + 1, Blocks.air);
		world.setBlock(i + 5, j + 1, k + 2, VetheaBlocks.cryptWall);
		world.setBlock(i + 5, j + 1, k + 3, VetheaBlocks.dreamDirt);
		world.setBlock(i + 5, j + 1, k + 4, VetheaBlocks.dreamDirt);
		world.setBlock(i + 5, j + 1, k + 5, VetheaBlocks.dreamDirt);
		world.setBlock(i + 5, j + 1, k + 6, VetheaBlocks.dreamDirt);
		world.setBlock(i + 5, j + 1, k + 7, VetheaBlocks.dreamDirt);
		world.setBlock(i + 5, j + 1, k + 8, VetheaBlocks.dreamDirt);
		world.setBlock(i + 5, j + 1, k + 9, VetheaBlocks.cryptWall);
		world.setBlock(i + 5, j + 1, k + 10, Blocks.air);
		world.setBlock(i + 5, j + 1, k + 11, Blocks.air);
		world.setBlock(i + 5, j + 1, k + 12, Blocks.air);
		world.setBlock(i + 5, j + 1, k + 13, Blocks.air);
		world.setBlock(i + 5, j + 1, k + 14, Blocks.air);
		world.setBlock(i + 5, j + 1, k + 15, Blocks.air);
		world.setBlock(i + 5, j + 1, k + 16, VetheaBlocks.cryptWall);
		world.setBlock(i + 5, j + 1, k + 17, VetheaBlocks.dreamDirt);
		world.setBlock(i + 5, j + 1, k + 18, VetheaBlocks.dreamDirt);
		world.setBlock(i + 5, j + 1, k + 19, VetheaBlocks.dreamDirt);
		world.setBlock(i + 5, j + 2, k + 0, VetheaBlocks.cryptWall);
		world.setBlock(i + 5, j + 2, k + 1, Blocks.air);
		world.setBlock(i + 5, j + 2, k + 2, VetheaBlocks.cryptWall);
		world.setBlock(i + 5, j + 2, k + 3, VetheaBlocks.dreamDirt);
		world.setBlock(i + 5, j + 2, k + 4, VetheaBlocks.dreamDirt);
		world.setBlock(i + 5, j + 2, k + 5, VetheaBlocks.dreamDirt);
		world.setBlock(i + 5, j + 2, k + 6, VetheaBlocks.dreamDirt);
		world.setBlock(i + 5, j + 2, k + 7, VetheaBlocks.dreamDirt);
		world.setBlock(i + 5, j + 2, k + 8, VetheaBlocks.dreamDirt);
		world.setBlock(i + 5, j + 2, k + 9, VetheaBlocks.cryptWall);
		world.setBlock(i + 5, j + 2, k + 10, Blocks.air);
		world.setBlock(i + 5, j + 2, k + 11, Blocks.air);
		world.setBlock(i + 5, j + 2, k + 12, Blocks.air);
		world.setBlock(i + 5, j + 2, k + 13, Blocks.air);
		world.setBlock(i + 5, j + 2, k + 14, Blocks.air);
		world.setBlock(i + 5, j + 2, k + 15, Blocks.air);
		world.setBlock(i + 5, j + 2, k + 16, VetheaBlocks.cryptWall);
		world.setBlock(i + 5, j + 2, k + 17, VetheaBlocks.dreamDirt);
		world.setBlock(i + 5, j + 2, k + 18, VetheaBlocks.dreamDirt);
		world.setBlock(i + 5, j + 2, k + 19, VetheaBlocks.dreamDirt);
		world.setBlock(i + 5, j + 3, k + 0, VetheaBlocks.dreamDirt);
		world.setBlock(i + 5, j + 3, k + 1, VetheaBlocks.hungerstone2);
		world.setBlock(i + 5, j + 3, k + 2, VetheaBlocks.dreamDirt);
		world.setBlock(i + 5, j + 3, k + 3, VetheaBlocks.dreamDirt);
		world.setBlock(i + 5, j + 3, k + 4, VetheaBlocks.dreamDirt);
		world.setBlock(i + 5, j + 3, k + 5, VetheaBlocks.dreamDirt);
		world.setBlock(i + 5, j + 3, k + 6, VetheaBlocks.dreamDirt);
		world.setBlock(i + 5, j + 3, k + 7, VetheaBlocks.dreamDirt);
		world.setBlock(i + 5, j + 3, k + 8, VetheaBlocks.dreamDirt);
		world.setBlock(i + 5, j + 3, k + 9, VetheaBlocks.cryptWall);
		world.setBlock(i + 5, j + 3, k + 10, Blocks.air);
		world.setBlock(i + 5, j + 3, k + 11, Blocks.air);
		world.setBlock(i + 5, j + 3, k + 12, Blocks.air);
		world.setBlock(i + 5, j + 3, k + 13, Blocks.air);
		world.setBlock(i + 5, j + 3, k + 14, Blocks.air);
		world.setBlock(i + 5, j + 3, k + 15, Blocks.air);
		world.setBlock(i + 5, j + 3, k + 16, VetheaBlocks.cryptWall);
		world.setBlock(i + 5, j + 3, k + 17, VetheaBlocks.dreamDirt);
		world.setBlock(i + 5, j + 3, k + 18, VetheaBlocks.dreamDirt);
		world.setBlock(i + 5, j + 3, k + 19, VetheaBlocks.dreamDirt);
		world.setBlock(i + 5, j + 4, k + 0, VetheaBlocks.dreamDirt);
		world.setBlock(i + 5, j + 4, k + 1, VetheaBlocks.dreamDirt);
		world.setBlock(i + 5, j + 4, k + 2, VetheaBlocks.dreamDirt);
		world.setBlock(i + 5, j + 4, k + 3, VetheaBlocks.dreamDirt);
		world.setBlock(i + 5, j + 4, k + 4, VetheaBlocks.dreamDirt);
		world.setBlock(i + 5, j + 4, k + 5, VetheaBlocks.dreamDirt);
		world.setBlock(i + 5, j + 4, k + 6, VetheaBlocks.dreamDirt);
		world.setBlock(i + 5, j + 4, k + 7, VetheaBlocks.dreamDirt);
		world.setBlock(i + 5, j + 4, k + 8, VetheaBlocks.dreamDirt);
		world.setBlock(i + 5, j + 4, k + 9, VetheaBlocks.dreamDirt);
		world.setBlock(i + 5, j + 4, k + 10, VetheaBlocks.hungerstone2);
		world.setBlock(i + 5, j + 4, k + 11, VetheaBlocks.hungerstone2);
		world.setBlock(i + 5, j + 4, k + 12, VetheaBlocks.hungerstone2);
		world.setBlock(i + 5, j + 4, k + 13, VetheaBlocks.hungerstone2);
		world.setBlock(i + 5, j + 4, k + 14, VetheaBlocks.hungerstone2);
		world.setBlock(i + 5, j + 4, k + 15, VetheaBlocks.hungerstone2);
		world.setBlock(i + 5, j + 4, k + 16, VetheaBlocks.dreamDirt);
		world.setBlock(i + 5, j + 4, k + 17, VetheaBlocks.dreamDirt);
		world.setBlock(i + 5, j + 4, k + 18, VetheaBlocks.dreamDirt);
		world.setBlock(i + 5, j + 4, k + 19, VetheaBlocks.dreamDirt);
		world.setBlock(i + 5, j + 5, k + 0, VetheaBlocks.dreamDirt);
		world.setBlock(i + 5, j + 5, k + 1, VetheaBlocks.dreamDirt);
		world.setBlock(i + 5, j + 5, k + 2, VetheaBlocks.dreamDirt);
		world.setBlock(i + 5, j + 5, k + 3, VetheaBlocks.cryptWall);
		world.setBlock(i + 5, j + 5, k + 4, VetheaBlocks.cryptWall);
		world.setBlock(i + 5, j + 5, k + 5, VetheaBlocks.dreamDirt);
		world.setBlock(i + 5, j + 5, k + 6, VetheaBlocks.dreamDirt);
		world.setBlock(i + 5, j + 5, k + 7, VetheaBlocks.dreamDirt);
		world.setBlock(i + 5, j + 5, k + 8, VetheaBlocks.dreamDirt);
		world.setBlock(i + 5, j + 5, k + 9, VetheaBlocks.dreamDirt);
		world.setBlock(i + 5, j + 5, k + 10, VetheaBlocks.dreamDirt);
		world.setBlock(i + 5, j + 5, k + 11, VetheaBlocks.dreamDirt);
		world.setBlock(i + 5, j + 5, k + 12, VetheaBlocks.dreamDirt);
		world.setBlock(i + 5, j + 5, k + 13, VetheaBlocks.dreamDirt);
		world.setBlock(i + 5, j + 5, k + 14, VetheaBlocks.cryptWall);
		world.setBlock(i + 5, j + 5, k + 15, VetheaBlocks.cryptWall);
		world.setBlock(i + 5, j + 5, k + 16, VetheaBlocks.dreamDirt);
		world.setBlock(i + 5, j + 5, k + 17, VetheaBlocks.dreamDirt);
		world.setBlock(i + 5, j + 5, k + 18, VetheaBlocks.dreamDirt);
		world.setBlock(i + 5, j + 5, k + 19, VetheaBlocks.dreamDirt);
		world.setBlock(i + 5, j + 6, k + 0, VetheaBlocks.hungerstone1);
		world.setBlock(i + 5, j + 6, k + 1, Blocks.air);
		world.setBlock(i + 5, j + 6, k + 2, Blocks.air);
		world.setBlock(i + 5, j + 6, k + 3, Blocks.air);
		world.setBlock(i + 5, j + 6, k + 4, Blocks.air);
		world.setBlock(i + 5, j + 6, k + 5, Blocks.air);
		world.setBlock(i + 5, j + 6, k + 6, Blocks.air);
		world.setBlock(i + 5, j + 6, k + 7, Blocks.air);
		world.setBlock(i + 5, j + 6, k + 8, Blocks.air);
		world.setBlock(i + 5, j + 6, k + 9, Blocks.air);
		world.setBlock(i + 5, j + 6, k + 10, Blocks.air);
		world.setBlock(i + 5, j + 6, k + 11, VetheaBlocks.hungerstone1);
		world.setBlock(i + 5, j + 6, k + 12, VetheaBlocks.hungerstone1);
		world.setBlock(i + 5, j + 6, k + 13, VetheaBlocks.hungerstone1);
		world.setBlock(i + 5, j + 6, k + 14, Blocks.air);
		world.setBlock(i + 5, j + 6, k + 15, Blocks.air);
		world.setBlock(i + 5, j + 6, k + 16, Blocks.air);
		world.setBlock(i + 5, j + 6, k + 17, Blocks.air);
		world.setBlock(i + 5, j + 6, k + 18, Blocks.air);
		world.setBlock(i + 5, j + 6, k + 19, VetheaBlocks.hungerstone1);
		world.setBlock(i + 5, j + 7, k + 0, VetheaBlocks.hungerstone1);
		world.setBlock(i + 5, j + 7, k + 1, Blocks.air);
		world.setBlock(i + 5, j + 7, k + 2, Blocks.air);
		world.setBlock(i + 5, j + 7, k + 3, Blocks.air);
		world.setBlock(i + 5, j + 7, k + 4, Blocks.air);
		world.setBlock(i + 5, j + 7, k + 5, Blocks.air);
		world.setBlock(i + 5, j + 7, k + 6, Blocks.air);
		world.setBlock(i + 5, j + 7, k + 7, Blocks.air);
		world.setBlock(i + 5, j + 7, k + 8, Blocks.air);
		world.setBlock(i + 5, j + 7, k + 9, Blocks.air);
		world.setBlock(i + 5, j + 7, k + 10, Blocks.air);
		world.setBlock(i + 5, j + 7, k + 11, Blocks.air);
		world.setBlock(i + 5, j + 7, k + 12, Blocks.air);
		world.setBlock(i + 5, j + 7, k + 13, Blocks.air);
		world.setBlock(i + 5, j + 7, k + 14, Blocks.air);
		world.setBlock(i + 5, j + 7, k + 15, Blocks.air);
		world.setBlock(i + 5, j + 7, k + 16, Blocks.air);
		world.setBlock(i + 5, j + 7, k + 17, Blocks.air);
		world.setBlock(i + 5, j + 7, k + 18, Blocks.air);
		world.setBlock(i + 5, j + 7, k + 19, VetheaBlocks.hungerstone1);
		world.setBlock(i + 5, j + 8, k + 0, VetheaBlocks.hungerstone1);
		world.setBlock(i + 5, j + 8, k + 1, Blocks.air);
		world.setBlock(i + 5, j + 8, k + 2, Blocks.air);
		world.setBlock(i + 5, j + 8, k + 3, Blocks.air);
		world.setBlock(i + 5, j + 8, k + 4, Blocks.air);
		world.setBlock(i + 5, j + 8, k + 5, Blocks.air);
		world.setBlock(i + 5, j + 8, k + 6, Blocks.air);
		world.setBlock(i + 5, j + 8, k + 7, Blocks.air);
		world.setBlock(i + 5, j + 8, k + 8, Blocks.air);
		world.setBlock(i + 5, j + 8, k + 9, Blocks.air);
		world.setBlock(i + 5, j + 8, k + 10, Blocks.air);
		world.setBlock(i + 5, j + 8, k + 11, Blocks.air);
		world.setBlock(i + 5, j + 8, k + 12, Blocks.air);
		world.setBlock(i + 5, j + 8, k + 13, Blocks.air);
		world.setBlock(i + 5, j + 8, k + 14, Blocks.air);
		world.setBlock(i + 5, j + 8, k + 15, Blocks.air);
		world.setBlock(i + 5, j + 8, k + 16, Blocks.air);
		world.setBlock(i + 5, j + 8, k + 17, Blocks.air);
		world.setBlock(i + 5, j + 8, k + 18, Blocks.air);
		world.setBlock(i + 5, j + 8, k + 19, VetheaBlocks.hungerstone1);
		world.setBlock(i + 5, j + 9, k + 0, Blocks.air);
		world.setBlock(i + 5, j + 9, k + 1, Blocks.air);
		world.setBlock(i + 5, j + 9, k + 2, Blocks.air);
		world.setBlock(i + 5, j + 9, k + 3, Blocks.air);
		world.setBlock(i + 5, j + 9, k + 4, Blocks.air);
		world.setBlock(i + 5, j + 9, k + 5, Blocks.air);
		world.setBlock(i + 5, j + 9, k + 6, Blocks.air);
		world.setBlock(i + 5, j + 9, k + 7, Blocks.air);
		world.setBlock(i + 5, j + 9, k + 8, Blocks.air);
		world.setBlock(i + 5, j + 9, k + 9, Blocks.air);
		world.setBlock(i + 5, j + 9, k + 10, Blocks.air);
		world.setBlock(i + 5, j + 9, k + 11, Blocks.air);
		world.setBlock(i + 5, j + 9, k + 12, Blocks.air);
		world.setBlock(i + 5, j + 9, k + 13, Blocks.air);
		world.setBlock(i + 5, j + 9, k + 14, Blocks.air);
		world.setBlock(i + 5, j + 9, k + 15, Blocks.air);
		world.setBlock(i + 5, j + 9, k + 16, Blocks.air);
		world.setBlock(i + 5, j + 9, k + 17, Blocks.air);
		world.setBlock(i + 5, j + 9, k + 18, Blocks.air);
		world.setBlock(i + 5, j + 9, k + 19, Blocks.air);
		world.setBlock(i + 5, j + 10, k + 0, Blocks.air);
		world.setBlock(i + 5, j + 10, k + 1, Blocks.air);
		world.setBlock(i + 5, j + 10, k + 2, Blocks.air);
		world.setBlock(i + 5, j + 10, k + 3, Blocks.air);
		world.setBlock(i + 5, j + 10, k + 4, Blocks.air);
		world.setBlock(i + 5, j + 10, k + 5, Blocks.air);
		world.setBlock(i + 5, j + 10, k + 6, Blocks.air);
		world.setBlock(i + 5, j + 10, k + 7, Blocks.air);
		world.setBlock(i + 5, j + 10, k + 8, Blocks.air);
		world.setBlock(i + 5, j + 10, k + 9, Blocks.air);
		world.setBlock(i + 5, j + 10, k + 10, Blocks.air);
		world.setBlock(i + 5, j + 10, k + 11, Blocks.air);
		world.setBlock(i + 5, j + 10, k + 12, Blocks.air);
		world.setBlock(i + 5, j + 10, k + 13, Blocks.air);
		world.setBlock(i + 5, j + 10, k + 14, Blocks.air);
		world.setBlock(i + 5, j + 10, k + 15, Blocks.air);
		world.setBlock(i + 5, j + 10, k + 16, Blocks.air);
		world.setBlock(i + 5, j + 10, k + 17, Blocks.air);
		world.setBlock(i + 5, j + 10, k + 18, Blocks.air);
		world.setBlock(i + 5, j + 10, k + 19, Blocks.air);
		world.setBlock(i + 6, j + 0, k + 0, VetheaBlocks.cryptWall);
		world.setBlock(i + 6, j + 0, k + 1, Blocks.air);
		world.setBlock(i + 6, j + 0, k + 2, VetheaBlocks.cryptWall);
		world.setBlock(i + 6, j + 0, k + 3, VetheaBlocks.cryptWall);
		world.setBlock(i + 6, j + 0, k + 4, VetheaBlocks.cryptWall);
		world.setBlock(i + 6, j + 0, k + 5, VetheaBlocks.dreamDirt);
		world.setBlock(i + 6, j + 0, k + 6, VetheaBlocks.dreamDirt);
		world.setBlock(i + 6, j + 0, k + 7, VetheaBlocks.dreamDirt);
		world.setBlock(i + 6, j + 0, k + 8, VetheaBlocks.dreamDirt);
		world.setBlock(i + 6, j + 0, k + 9, VetheaBlocks.dreamDirt);
		world.setBlock(i + 6, j + 0, k + 10, VetheaBlocks.cryptFloor);
		world.setBlock(i + 6, j + 0, k + 11, VetheaBlocks.cryptFloor);
		world.setBlock(i + 6, j + 0, k + 12, VetheaBlocks.cryptFloor);
		world.setBlock(i + 6, j + 0, k + 13, VetheaBlocks.cryptFloor);
		world.setBlock(i + 6, j + 0, k + 14, VetheaBlocks.cryptFloor);
		world.setBlock(i + 6, j + 0, k + 15, VetheaBlocks.cryptFloor);
		world.setBlock(i + 6, j + 0, k + 16, VetheaBlocks.dreamDirt);
		world.setBlock(i + 6, j + 0, k + 17, VetheaBlocks.dreamDirt);
		world.setBlock(i + 6, j + 0, k + 18, VetheaBlocks.dreamDirt);
		world.setBlock(i + 6, j + 0, k + 19, VetheaBlocks.dreamDirt);
		world.setBlock(i + 6, j + 1, k + 0, VetheaBlocks.cryptWall);
		world.setBlock(i + 6, j + 1, k + 1, Blocks.air);
		world.setBlock(i + 6, j + 1, k + 2, VetheaBlocks.fireCrystal);
		world.setBlock(i + 6, j + 1, k + 3, VetheaBlocks.cryptWall);
		world.setBlock(i + 6, j + 1, k + 4, VetheaBlocks.cryptWall);
		world.setBlock(i + 6, j + 1, k + 5, VetheaBlocks.dreamDirt);
		world.setBlock(i + 6, j + 1, k + 6, VetheaBlocks.dreamDirt);
		world.setBlock(i + 6, j + 1, k + 7, VetheaBlocks.dreamDirt);
		world.setBlock(i + 6, j + 1, k + 8, VetheaBlocks.dreamDirt);
		world.setBlock(i + 6, j + 1, k + 9, VetheaBlocks.cryptWall);
		world.setBlock(i + 6, j + 1, k + 10, Blocks.air);
		world.setBlock(i + 6, j + 1, k + 11, Blocks.air);
		world.setBlock(i + 6, j + 1, k + 12, Blocks.air);
		world.setBlock(i + 6, j + 1, k + 13, Blocks.air);
		world.setBlock(i + 6, j + 1, k + 14, Blocks.air);
		world.setBlock(i + 6, j + 1, k + 15, Blocks.air);
		world.setBlock(i + 6, j + 1, k + 16, VetheaBlocks.cryptWall);
		world.setBlock(i + 6, j + 1, k + 17, VetheaBlocks.dreamDirt);
		world.setBlock(i + 6, j + 1, k + 18, VetheaBlocks.dreamDirt);
		world.setBlock(i + 6, j + 1, k + 19, VetheaBlocks.dreamDirt);
		world.setBlock(i + 6, j + 2, k + 0, VetheaBlocks.cryptWall);
		world.setBlock(i + 6, j + 2, k + 1, Blocks.air);
		world.setBlock(i + 6, j + 2, k + 2, VetheaBlocks.cryptWall);
		world.setBlock(i + 6, j + 2, k + 3, VetheaBlocks.cryptWall);
		world.setBlock(i + 6, j + 2, k + 4, VetheaBlocks.cryptWall);
		world.setBlock(i + 6, j + 2, k + 5, VetheaBlocks.dreamDirt);
		world.setBlock(i + 6, j + 2, k + 6, VetheaBlocks.dreamDirt);
		world.setBlock(i + 6, j + 2, k + 7, VetheaBlocks.dreamDirt);
		world.setBlock(i + 6, j + 2, k + 8, VetheaBlocks.dreamDirt);
		world.setBlock(i + 6, j + 2, k + 9, VetheaBlocks.cryptWall);
		world.setBlock(i + 6, j + 2, k + 10, Blocks.air);
		world.setBlock(i + 6, j + 2, k + 11, Blocks.air);
		world.setBlock(i + 6, j + 2, k + 12, Blocks.air);
		world.setBlock(i + 6, j + 2, k + 13, Blocks.air);
		world.setBlock(i + 6, j + 2, k + 14, Blocks.air);
		world.setBlock(i + 6, j + 2, k + 15, Blocks.air);
		world.setBlock(i + 6, j + 2, k + 16, VetheaBlocks.cryptWall);
		world.setBlock(i + 6, j + 2, k + 17, VetheaBlocks.dreamDirt);
		world.setBlock(i + 6, j + 2, k + 18, VetheaBlocks.dreamDirt);
		world.setBlock(i + 6, j + 2, k + 19, VetheaBlocks.dreamDirt);
		world.setBlock(i + 6, j + 3, k + 0, VetheaBlocks.dreamDirt);
		world.setBlock(i + 6, j + 3, k + 1, VetheaBlocks.cryptWall);
		world.setBlock(i + 6, j + 3, k + 2, VetheaBlocks.cryptWall);
		world.setBlock(i + 6, j + 3, k + 3, VetheaBlocks.cryptWall);
		world.setBlock(i + 6, j + 3, k + 4, VetheaBlocks.cryptWall);
		world.setBlock(i + 6, j + 3, k + 5, VetheaBlocks.dreamDirt);
		world.setBlock(i + 6, j + 3, k + 6, VetheaBlocks.dreamDirt);
		world.setBlock(i + 6, j + 3, k + 7, VetheaBlocks.dreamDirt);
		world.setBlock(i + 6, j + 3, k + 8, VetheaBlocks.dreamDirt);
		world.setBlock(i + 6, j + 3, k + 9, VetheaBlocks.cryptWall);
		world.setBlock(i + 6, j + 3, k + 10, Blocks.air);
		world.setBlock(i + 6, j + 3, k + 11, Blocks.air);
		world.setBlock(i + 6, j + 3, k + 12, Blocks.air);
		world.setBlock(i + 6, j + 3, k + 13, Blocks.air);
		world.setBlock(i + 6, j + 3, k + 14, Blocks.air);
		world.setBlock(i + 6, j + 3, k + 15, Blocks.air);
		world.setBlock(i + 6, j + 3, k + 16, VetheaBlocks.cryptWall);
		world.setBlock(i + 6, j + 3, k + 17, VetheaBlocks.dreamDirt);
		world.setBlock(i + 6, j + 3, k + 18, VetheaBlocks.dreamDirt);
		world.setBlock(i + 6, j + 3, k + 19, VetheaBlocks.dreamDirt);
		world.setBlock(i + 6, j + 4, k + 0, VetheaBlocks.dreamDirt);
		world.setBlock(i + 6, j + 4, k + 1, VetheaBlocks.dreamDirt);
		world.setBlock(i + 6, j + 4, k + 2, VetheaBlocks.dreamDirt);
		world.setBlock(i + 6, j + 4, k + 3, VetheaBlocks.dreamDirt);
		world.setBlock(i + 6, j + 4, k + 4, VetheaBlocks.dreamDirt);
		world.setBlock(i + 6, j + 4, k + 5, VetheaBlocks.dreamDirt);
		world.setBlock(i + 6, j + 4, k + 6, VetheaBlocks.dreamDirt);
		world.setBlock(i + 6, j + 4, k + 7, VetheaBlocks.dreamDirt);
		world.setBlock(i + 6, j + 4, k + 8, VetheaBlocks.dreamDirt);
		world.setBlock(i + 6, j + 4, k + 9, VetheaBlocks.dreamDirt);
		world.setBlock(i + 6, j + 4, k + 10, VetheaBlocks.hungerstone2);
		world.setBlock(i + 6, j + 4, k + 11, VetheaBlocks.hungerstone2);
		world.setBlock(i + 6, j + 4, k + 12, VetheaBlocks.hungerstone2);
		world.setBlock(i + 6, j + 4, k + 13, VetheaBlocks.hungerstone2);
		world.setBlock(i + 6, j + 4, k + 14, VetheaBlocks.hungerstone2);
		world.setBlock(i + 6, j + 4, k + 15, VetheaBlocks.hungerstone2);
		world.setBlock(i + 6, j + 4, k + 16, VetheaBlocks.dreamDirt);
		world.setBlock(i + 6, j + 4, k + 17, VetheaBlocks.dreamDirt);
		world.setBlock(i + 6, j + 4, k + 18, VetheaBlocks.dreamDirt);
		world.setBlock(i + 6, j + 4, k + 19, VetheaBlocks.dreamDirt);
		world.setBlock(i + 6, j + 5, k + 0, VetheaBlocks.cryptWall);
		world.setBlock(i + 6, j + 5, k + 1, VetheaBlocks.cryptWall);
		world.setBlock(i + 6, j + 5, k + 2, VetheaBlocks.cryptWall);
		world.setBlock(i + 6, j + 5, k + 3, VetheaBlocks.cryptWall);
		world.setBlock(i + 6, j + 5, k + 4, VetheaBlocks.cryptWall);
		world.setBlock(i + 6, j + 5, k + 5, VetheaBlocks.cryptWall);
		world.setBlock(i + 6, j + 5, k + 6, VetheaBlocks.cryptWall);
		world.setBlock(i + 6, j + 5, k + 7, VetheaBlocks.cryptWall);
		world.setBlock(i + 6, j + 5, k + 8, VetheaBlocks.cryptWall);
		world.setBlock(i + 6, j + 5, k + 9, VetheaBlocks.cryptWall);
		world.setBlock(i + 6, j + 5, k + 10, VetheaBlocks.cryptWall);
		world.setBlock(i + 6, j + 5, k + 11, VetheaBlocks.cryptWall);
		world.setBlock(i + 6, j + 5, k + 12, VetheaBlocks.cryptWall);
		world.setBlock(i + 6, j + 5, k + 13, VetheaBlocks.cryptWall);
		world.setBlock(i + 6, j + 5, k + 14, VetheaBlocks.cryptWall);
		world.setBlock(i + 6, j + 5, k + 15, VetheaBlocks.cryptWall);
		world.setBlock(i + 6, j + 5, k + 16, VetheaBlocks.cryptWall);
		world.setBlock(i + 6, j + 5, k + 17, VetheaBlocks.cryptWall);
		world.setBlock(i + 6, j + 5, k + 18, VetheaBlocks.cryptWall);
		world.setBlock(i + 6, j + 5, k + 19, VetheaBlocks.cryptWall);
		world.setBlock(i + 6, j + 6, k + 0, Blocks.air);
		world.setBlock(i + 6, j + 6, k + 1, Blocks.air);
		world.setBlock(i + 6, j + 6, k + 2, Blocks.air);
		world.setBlock(i + 6, j + 6, k + 3, Blocks.air);
		world.setBlock(i + 6, j + 6, k + 4, Blocks.air);
		world.setBlock(i + 6, j + 6, k + 5, Blocks.air);
		world.setBlock(i + 6, j + 6, k + 6, Blocks.air);
		world.setBlock(i + 6, j + 6, k + 7, Blocks.air);
		world.setBlock(i + 6, j + 6, k + 8, Blocks.air);
		world.setBlock(i + 6, j + 6, k + 9, Blocks.air);
		world.setBlock(i + 6, j + 6, k + 10, Blocks.air);
		world.setBlock(i + 6, j + 6, k + 11, Blocks.air);
		world.setBlock(i + 6, j + 6, k + 12, Blocks.air);
		world.setBlock(i + 6, j + 6, k + 13, Blocks.air);
		world.setBlock(i + 6, j + 6, k + 14, Blocks.air);
		world.setBlock(i + 6, j + 6, k + 15, Blocks.air);
		world.setBlock(i + 6, j + 6, k + 16, Blocks.air);
		world.setBlock(i + 6, j + 6, k + 17, Blocks.air);
		world.setBlock(i + 6, j + 6, k + 18, Blocks.air);
		world.setBlock(i + 6, j + 6, k + 19, Blocks.air);
		world.setBlock(i + 6, j + 7, k + 0, Blocks.air);
		world.setBlock(i + 6, j + 7, k + 1, Blocks.air);
		world.setBlock(i + 6, j + 7, k + 2, Blocks.air);
		world.setBlock(i + 6, j + 7, k + 3, Blocks.air);
		world.setBlock(i + 6, j + 7, k + 4, Blocks.air);
		world.setBlock(i + 6, j + 7, k + 5, Blocks.air);
		world.setBlock(i + 6, j + 7, k + 6, Blocks.air);
		world.setBlock(i + 6, j + 7, k + 7, Blocks.air);
		world.setBlock(i + 6, j + 7, k + 8, Blocks.air);
		world.setBlock(i + 6, j + 7, k + 9, Blocks.air);
		world.setBlock(i + 6, j + 7, k + 10, Blocks.air);
		world.setBlock(i + 6, j + 7, k + 11, Blocks.air);
		world.setBlock(i + 6, j + 7, k + 12, Blocks.air);
		world.setBlock(i + 6, j + 7, k + 13, Blocks.air);
		world.setBlock(i + 6, j + 7, k + 14, Blocks.air);
		world.setBlock(i + 6, j + 7, k + 15, Blocks.air);
		world.setBlock(i + 6, j + 7, k + 16, Blocks.air);
		world.setBlock(i + 6, j + 7, k + 17, Blocks.air);
		world.setBlock(i + 6, j + 7, k + 18, Blocks.air);
		world.setBlock(i + 6, j + 7, k + 19, Blocks.air);
		world.setBlock(i + 6, j + 8, k + 0, VetheaBlocks.hungerstone1);
		world.setBlock(i + 6, j + 8, k + 1, Blocks.air);
		world.setBlock(i + 6, j + 8, k + 2, Blocks.air);
		world.setBlock(i + 6, j + 8, k + 3, Blocks.air);
		world.setBlock(i + 6, j + 8, k + 4, Blocks.air);
		world.setBlock(i + 6, j + 8, k + 5, Blocks.air);
		world.setBlock(i + 6, j + 8, k + 6, Blocks.air);
		world.setBlock(i + 6, j + 8, k + 7, Blocks.air);
		world.setBlock(i + 6, j + 8, k + 8, Blocks.air);
		world.setBlock(i + 6, j + 8, k + 9, Blocks.air);
		world.setBlock(i + 6, j + 8, k + 10, Blocks.air);
		world.setBlock(i + 6, j + 8, k + 11, Blocks.air);
		world.setBlock(i + 6, j + 8, k + 12, Blocks.air);
		world.setBlock(i + 6, j + 8, k + 13, Blocks.air);
		world.setBlock(i + 6, j + 8, k + 14, Blocks.air);
		world.setBlock(i + 6, j + 8, k + 15, Blocks.air);
		world.setBlock(i + 6, j + 8, k + 16, Blocks.air);
		world.setBlock(i + 6, j + 8, k + 17, Blocks.air);
		world.setBlock(i + 6, j + 8, k + 18, Blocks.air);
		world.setBlock(i + 6, j + 8, k + 19, VetheaBlocks.hungerstone1);

		generate2(world, rand, i, j, k);
		return true;
	}

	public boolean generate2(World world, Random rand, int i, int j, int k) {
		world.setBlock(i + 6, j + 9, k + 0, Blocks.air);
		world.setBlock(i + 6, j + 9, k + 1, Blocks.air);
		world.setBlock(i + 6, j + 9, k + 2, Blocks.air);
		world.setBlock(i + 6, j + 9, k + 3, Blocks.air);
		world.setBlock(i + 6, j + 9, k + 4, Blocks.air);
		world.setBlock(i + 6, j + 9, k + 5, Blocks.air);
		world.setBlock(i + 6, j + 9, k + 6, Blocks.air);
		world.setBlock(i + 6, j + 9, k + 7, Blocks.air);
		world.setBlock(i + 6, j + 9, k + 8, Blocks.air);
		world.setBlock(i + 6, j + 9, k + 9, Blocks.air);
		world.setBlock(i + 6, j + 9, k + 10, Blocks.air);
		world.setBlock(i + 6, j + 9, k + 11, Blocks.air);
		world.setBlock(i + 6, j + 9, k + 12, Blocks.air);
		world.setBlock(i + 6, j + 9, k + 13, Blocks.air);
		world.setBlock(i + 6, j + 9, k + 14, Blocks.air);
		world.setBlock(i + 6, j + 9, k + 15, Blocks.air);
		world.setBlock(i + 6, j + 9, k + 16, Blocks.air);
		world.setBlock(i + 6, j + 9, k + 17, Blocks.air);
		world.setBlock(i + 6, j + 9, k + 18, Blocks.air);
		world.setBlock(i + 6, j + 9, k + 19, Blocks.air);
		world.setBlock(i + 6, j + 10, k + 0, Blocks.air);
		world.setBlock(i + 6, j + 10, k + 1, Blocks.air);
		world.setBlock(i + 6, j + 10, k + 2, Blocks.air);
		world.setBlock(i + 6, j + 10, k + 3, Blocks.air);
		world.setBlock(i + 6, j + 10, k + 4, Blocks.air);
		world.setBlock(i + 6, j + 10, k + 5, Blocks.air);
		world.setBlock(i + 6, j + 10, k + 6, Blocks.air);
		world.setBlock(i + 6, j + 10, k + 7, Blocks.air);
		world.setBlock(i + 6, j + 10, k + 8, Blocks.air);
		world.setBlock(i + 6, j + 10, k + 9, Blocks.air);
		world.setBlock(i + 6, j + 10, k + 10, Blocks.air);
		world.setBlock(i + 6, j + 10, k + 11, Blocks.air);
		world.setBlock(i + 6, j + 10, k + 12, Blocks.air);
		world.setBlock(i + 6, j + 10, k + 13, Blocks.air);
		world.setBlock(i + 6, j + 10, k + 14, Blocks.air);
		world.setBlock(i + 6, j + 10, k + 15, Blocks.air);
		world.setBlock(i + 6, j + 10, k + 16, Blocks.air);
		world.setBlock(i + 6, j + 10, k + 17, Blocks.air);
		world.setBlock(i + 6, j + 10, k + 18, Blocks.air);
		world.setBlock(i + 6, j + 10, k + 19, Blocks.air);
		world.setBlock(i + 7, j + 0, k + 0, VetheaBlocks.cryptWall);
		world.setBlock(i + 7, j + 0, k + 1, Blocks.air);
		world.setBlock(i + 7, j + 0, k + 2, Blocks.air);
		world.setBlock(i + 7, j + 0, k + 3, Blocks.air);
		world.setBlock(i + 7, j + 0, k + 4, Blocks.air);
		world.setBlock(i + 7, j + 0, k + 5, VetheaBlocks.cryptWall);
		world.setBlock(i + 7, j + 0, k + 6, VetheaBlocks.dreamDirt);
		world.setBlock(i + 7, j + 0, k + 7, VetheaBlocks.dreamDirt);
		world.setBlock(i + 7, j + 0, k + 8, VetheaBlocks.dreamDirt);
		world.setBlock(i + 7, j + 0, k + 9, VetheaBlocks.dreamDirt);
		world.setBlock(i + 7, j + 0, k + 10, VetheaBlocks.cryptFloor);
		world.setBlock(i + 7, j + 0, k + 11, VetheaBlocks.cryptFloor);
		world.setBlock(i + 7, j + 0, k + 12, VetheaBlocks.cryptFloor);
		world.setBlock(i + 7, j + 0, k + 13, VetheaBlocks.cryptFloor);
		world.setBlock(i + 7, j + 0, k + 14, VetheaBlocks.cryptFloor);
		world.setBlock(i + 7, j + 0, k + 15, VetheaBlocks.cryptFloor);
		world.setBlock(i + 7, j + 0, k + 16, VetheaBlocks.dreamDirt);
		world.setBlock(i + 7, j + 0, k + 17, VetheaBlocks.dreamDirt);
		world.setBlock(i + 7, j + 0, k + 18, VetheaBlocks.dreamDirt);
		world.setBlock(i + 7, j + 0, k + 19, VetheaBlocks.dreamDirt);
		world.setBlock(i + 7, j + 1, k + 0, VetheaBlocks.cryptWall);
		world.setBlock(i + 7, j + 1, k + 1, Blocks.air);
		world.setBlock(i + 7, j + 1, k + 2, Blocks.air);
		world.setBlock(i + 7, j + 1, k + 3, Blocks.air);
		world.setBlock(i + 7, j + 1, k + 4, Blocks.air);
		world.setBlock(i + 7, j + 1, k + 5, VetheaBlocks.cryptWall);
		world.setBlock(i + 7, j + 1, k + 6, VetheaBlocks.dreamDirt);
		world.setBlock(i + 7, j + 1, k + 7, VetheaBlocks.dreamDirt);
		world.setBlock(i + 7, j + 1, k + 8, VetheaBlocks.dreamDirt);
		world.setBlock(i + 7, j + 1, k + 9, VetheaBlocks.cryptWall);
		world.setBlock(i + 7, j + 1, k + 10, Blocks.air);
		world.setBlock(i + 7, j + 1, k + 11, Blocks.air);
		world.setBlock(i + 7, j + 1, k + 12, Blocks.air);
		world.setBlock(i + 7, j + 1, k + 13, Blocks.air);
		world.setBlock(i + 7, j + 1, k + 14, Blocks.air);
		world.setBlock(i + 7, j + 1, k + 15, Blocks.air);
		world.setBlock(i + 7, j + 1, k + 16, VetheaBlocks.cryptWall);
		world.setBlock(i + 7, j + 1, k + 17, VetheaBlocks.dreamDirt);
		world.setBlock(i + 7, j + 1, k + 18, VetheaBlocks.dreamDirt);
		world.setBlock(i + 7, j + 1, k + 19, VetheaBlocks.dreamDirt);
		world.setBlock(i + 7, j + 2, k + 0, VetheaBlocks.cryptWall);
		world.setBlock(i + 7, j + 2, k + 1, Blocks.air);
		world.setBlock(i + 7, j + 2, k + 2, Blocks.air);
		world.setBlock(i + 7, j + 2, k + 3, Blocks.air);
		world.setBlock(i + 7, j + 2, k + 4, Blocks.air);
		world.setBlock(i + 7, j + 2, k + 5, VetheaBlocks.cryptWall);
		world.setBlock(i + 7, j + 2, k + 6, VetheaBlocks.dreamDirt);
		world.setBlock(i + 7, j + 2, k + 7, VetheaBlocks.dreamDirt);
		world.setBlock(i + 7, j + 2, k + 8, VetheaBlocks.dreamDirt);
		world.setBlock(i + 7, j + 2, k + 9, VetheaBlocks.cryptWall);
		world.setBlock(i + 7, j + 2, k + 10, Blocks.air);
		world.setBlock(i + 7, j + 2, k + 11, Blocks.air);
		world.setBlock(i + 7, j + 2, k + 12, Blocks.air);
		world.setBlock(i + 7, j + 2, k + 13, Blocks.air);
		world.setBlock(i + 7, j + 2, k + 14, Blocks.air);
		world.setBlock(i + 7, j + 2, k + 15, Blocks.air);
		world.setBlock(i + 7, j + 2, k + 16, VetheaBlocks.cryptWall);
		world.setBlock(i + 7, j + 2, k + 17, VetheaBlocks.dreamDirt);
		world.setBlock(i + 7, j + 2, k + 18, VetheaBlocks.dreamDirt);
		world.setBlock(i + 7, j + 2, k + 19, VetheaBlocks.dreamDirt);
		world.setBlock(i + 7, j + 3, k + 0, VetheaBlocks.cryptWall);
		world.setBlock(i + 7, j + 3, k + 1, Blocks.air);
		world.setBlock(i + 7, j + 3, k + 2, Blocks.air);
		world.setBlock(i + 7, j + 3, k + 3, Blocks.air);
		world.setBlock(i + 7, j + 3, k + 4, Blocks.air);
		world.setBlock(i + 7, j + 3, k + 5, VetheaBlocks.cryptWall);
		world.setBlock(i + 7, j + 3, k + 6, VetheaBlocks.dreamDirt);
		world.setBlock(i + 7, j + 3, k + 7, VetheaBlocks.dreamDirt);
		world.setBlock(i + 7, j + 3, k + 8, VetheaBlocks.dreamDirt);
		world.setBlock(i + 7, j + 3, k + 9, VetheaBlocks.cryptWall);
		world.setBlock(i + 7, j + 3, k + 10, Blocks.air);
		world.setBlock(i + 7, j + 3, k + 11, Blocks.air);
		world.setBlock(i + 7, j + 3, k + 12, Blocks.air);
		world.setBlock(i + 7, j + 3, k + 13, Blocks.air);
		world.setBlock(i + 7, j + 3, k + 14, Blocks.air);
		world.setBlock(i + 7, j + 3, k + 15, Blocks.air);
		world.setBlock(i + 7, j + 3, k + 16, VetheaBlocks.cryptWall);
		world.setBlock(i + 7, j + 3, k + 17, VetheaBlocks.dreamDirt);
		world.setBlock(i + 7, j + 3, k + 18, VetheaBlocks.dreamDirt);
		world.setBlock(i + 7, j + 3, k + 19, VetheaBlocks.dreamDirt);
		world.setBlock(i + 7, j + 4, k + 0, VetheaBlocks.dreamDirt);
		world.setBlock(i + 7, j + 4, k + 1, VetheaBlocks.hungerstone2);
		world.setBlock(i + 7, j + 4, k + 2, VetheaBlocks.hungerstone2);
		world.setBlock(i + 7, j + 4, k + 3, VetheaBlocks.hungerstone2);
		world.setBlock(i + 7, j + 4, k + 4, VetheaBlocks.hungerstone2);
		world.setBlock(i + 7, j + 4, k + 5, VetheaBlocks.dreamDirt);
		world.setBlock(i + 7, j + 4, k + 6, VetheaBlocks.dreamDirt);
		world.setBlock(i + 7, j + 4, k + 7, VetheaBlocks.dreamDirt);
		world.setBlock(i + 7, j + 4, k + 8, VetheaBlocks.dreamDirt);
		world.setBlock(i + 7, j + 4, k + 9, VetheaBlocks.dreamDirt);
		world.setBlock(i + 7, j + 4, k + 10, VetheaBlocks.hungerstone2);
		world.setBlock(i + 7, j + 4, k + 11, VetheaBlocks.hungerstone2);
		world.setBlock(i + 7, j + 4, k + 12, VetheaBlocks.hungerstone2);
		world.setBlock(i + 7, j + 4, k + 13, VetheaBlocks.hungerstone2);
		world.setBlock(i + 7, j + 4, k + 14, VetheaBlocks.hungerstone2);
		world.setBlock(i + 7, j + 4, k + 15, VetheaBlocks.hungerstone2);
		world.setBlock(i + 7, j + 4, k + 16, VetheaBlocks.dreamDirt);
		world.setBlock(i + 7, j + 4, k + 17, VetheaBlocks.dreamDirt);
		world.setBlock(i + 7, j + 4, k + 18, VetheaBlocks.dreamDirt);
		world.setBlock(i + 7, j + 4, k + 19, VetheaBlocks.dreamDirt);
		world.setBlock(i + 7, j + 5, k + 0, VetheaBlocks.cryptWall);
		world.setBlock(i + 7, j + 5, k + 1, VetheaBlocks.cryptWall);
		world.setBlock(i + 7, j + 5, k + 2, VetheaBlocks.cryptWall);
		world.setBlock(i + 7, j + 5, k + 3, VetheaBlocks.cryptWall);
		world.setBlock(i + 7, j + 5, k + 4, VetheaBlocks.cryptWall);
		world.setBlock(i + 7, j + 5, k + 5, VetheaBlocks.cryptWall);
		world.setBlock(i + 7, j + 5, k + 6, VetheaBlocks.cryptWall);
		world.setBlock(i + 7, j + 5, k + 7, VetheaBlocks.cryptWall);
		world.setBlock(i + 7, j + 5, k + 8, VetheaBlocks.cryptWall);
		world.setBlock(i + 7, j + 5, k + 9, VetheaBlocks.cryptWall);
		world.setBlock(i + 7, j + 5, k + 10, VetheaBlocks.cryptWall);
		world.setBlock(i + 7, j + 5, k + 11, VetheaBlocks.cryptWall);
		world.setBlock(i + 7, j + 5, k + 12, VetheaBlocks.cryptWall);
		world.setBlock(i + 7, j + 5, k + 13, VetheaBlocks.cryptWall);
		world.setBlock(i + 7, j + 5, k + 14, VetheaBlocks.cryptWall);
		world.setBlock(i + 7, j + 5, k + 15, VetheaBlocks.cryptWall);
		world.setBlock(i + 7, j + 5, k + 16, VetheaBlocks.cryptWall);
		world.setBlock(i + 7, j + 5, k + 17, VetheaBlocks.cryptWall);
		world.setBlock(i + 7, j + 5, k + 18, VetheaBlocks.cryptWall);
		world.setBlock(i + 7, j + 5, k + 19, VetheaBlocks.cryptWall);
		world.setBlock(i + 7, j + 6, k + 0, Blocks.air);
		world.setBlock(i + 7, j + 6, k + 1, Blocks.air);
		world.setBlock(i + 7, j + 6, k + 2, Blocks.air);
		world.setBlock(i + 7, j + 6, k + 3, Blocks.air);
		world.setBlock(i + 7, j + 6, k + 4, Blocks.air);
		world.setBlock(i + 7, j + 6, k + 5, Blocks.air);
		world.setBlock(i + 7, j + 6, k + 6, Blocks.air);
		world.setBlock(i + 7, j + 6, k + 7, Blocks.air);
		world.setBlock(i + 7, j + 6, k + 8, Blocks.air);
		world.setBlock(i + 7, j + 6, k + 9, Blocks.air);
		world.setBlock(i + 7, j + 6, k + 10, Blocks.air);
		world.setBlock(i + 7, j + 6, k + 11, Blocks.air);
		world.setBlock(i + 7, j + 6, k + 12, Blocks.air);
		world.setBlock(i + 7, j + 6, k + 13, Blocks.air);
		world.setBlock(i + 7, j + 6, k + 14, Blocks.air);
		world.setBlock(i + 7, j + 6, k + 15, Blocks.air);
		world.setBlock(i + 7, j + 6, k + 16, Blocks.air);
		world.setBlock(i + 7, j + 6, k + 17, Blocks.air);
		world.setBlock(i + 7, j + 6, k + 18, Blocks.air);
		world.setBlock(i + 7, j + 6, k + 19, Blocks.air);
		world.setBlock(i + 7, j + 7, k + 0, Blocks.air);
		world.setBlock(i + 7, j + 7, k + 1, Blocks.air);
		world.setBlock(i + 7, j + 7, k + 2, Blocks.air);
